Workbook
Name _04._HID_CEA_01_GENERIC_NO_INIT_CAL___Output_1_1: HID_CEA_01!$A$1:$H$310
Name _04._JIN_CEA_01_GENERIC_NO_INIT_CAL___Output_1_1: JIN_CEA_01!$A$1:$F$310
Name _04._JIN_CEA_01_GENERIC_NO_INIT_CAL_2016_MAN___Output_1: JIN_CEA_01!$A$9:$H$310
Name _04._LIS_CEA_01_GENERIC_NO_INIT_CAL___Output_1: LIS_CEA_01!$A$1:$H$310
Name _04._LIS_CEA_01_GENERIC_NO_INIT_CAL___Output_1_1: LIS_CEA_01!$A$1:$H$310
Name _04._STE_CEA_01_GENERIC_NO_INIT_CAL___Output_1: STE_CEA_01!$A$1:$F$310
Name _04._STE_CEA_02_GENERIC_NO_INIT_CAL___Output_1: STE_CEA_02!$A$1:$H$310
Name _04._STE_CEA_03_GENERIC_NO_INIT_CAL___Output_1: STE_CEA_03!$A$1:$H$310

Sheet Cover
A11: Emissions Reduction Fund Offsets Report
A12: Dogwood Carbon Project
A14: Item | B14: Project details
A15: Project Name | B15: Dogwood Carbon Project
A16: Registration number | B16: ERF Project ID 101808
A17: Participant | B17: Corporate Carbon Solutions Pty Ltd
A18: Commencement date | B18: 40725
A19: Reporting period | B19: 1 Jan 2023 to 01 January 2024 (1 year)
A20: Report number | B20: Report 8
A23: Code | B23: Section
B24: Cover
B25: Net Abatement
B26: CEA Attributes
B27: Abatement
B28: Project Emissions
B29: Global Warming Potential
B30: Fuel Emissions
B31: CEA-01 Stewartdale

Sheet Net Abatement
A3: Equation 18; Section 5.8(a)
A4: Symbol | B4: Element | C4: CO2-e (t) | D4: Section
A5: CP | B5: Carbon stock for the project (in tonnes CO2-e) - Equation 11b. | C5: ='Abatement - Report 8'!AD13 -> 26959.689 | D5: 5.8(g)
A6: EB | B6: Total project emissions from biomass burning for the project (in tonnes of CO2-2) - Equation 15 | C6: ='Project Emissions'!G17 -> 1.5931607 | D6: 5.8(c )
A7: EF | B7: Total project fuel emissions for the project (in tonnes CO2-e) - Equation 17 | C7: ='Fuel Emissions'!E32 -> 30.353698 | D7: 5.8(d)
A8: CN | B8: Initial carbon stock for the project area (in tonnes CO2-e) Equation 11a | C8: ='Abatement - Report 3'!F13 -> 3.891384 | D8: 5.8(e/f)
A9: CV | B9: Final carbon stock for the project from the previous offsets report (in tonnes CO2-e) | C9: ='Abatement - Report 8'!AA13 -> 24934.473 | D9: na
A11: A | B11: Project net abatement for the reporting period (in tonnes CO2-e) | C11: =C5-C6-C7-C8-C9 -> 1989.3777 | D11: 5.8(a) | E11: =C11/(44/12) -> 542.55756
B14: Carbon stock change | C14: =C5-C9 -> 2025.216 | D14: 5.8(b) | E14: =C14/(44/12) -> 552.33162
A16: Af | B16: 25 years Permance Proj _Buffers (risk of reversal =5%; permanence period = 20%, total = 25% ) | C16: =(1-0.25)*C11 -> 1492.0333

Sheet CEA Attributes
A1: Method Ref | B1: CEA identification number | C1: STE_CEA_01 | D1: STE_CEA_02 | E1: STE_CEA_03 | F1: JIN_CEA_01 | G1: OLD_CEA_01 | H1: LIS_CEA_01
B2: Landholder / Property | C2: Stewartdale | D2: Stewartdale | E2: Stewartdale | F2: Jingeri | G2: Old Hidden Vale | H2: Liscombe Pools
B3: Date finished planting | C3: 42095 | D3: 42095 | E3: 42095 | F3: 42090 | G3: 40909 | H3: 40391
B4: Modelling Start Date | C4: 42125 | D4: 42125 | E4: 42125 | F4: 42095 | G4: 40940 | H4: 40422
B5: CEA area (ha) | C5: 13.77 | D5: 24.62 | E5: 66.16 | F5: 8.76 | G5: 2.7 | H5: 3.24 | I5: =SUM(C5:H5) -> 119.25
B6: Exclusion area (ha) | C6: 575.01 | F6: 366.55 | G6: 276.45 | H6: 456.08 | I6: =SUM(C6:H6) -> 1674.09
B7: Principal evidence of planting history | C7: Mgt Records | D7: Mgt Records | E7: Mgt Records | F7: Mgt Records | G7: Mgt Records | H7: Mgt Records | I7: =SUM(I5:I6) -> 1793.34
B8: Permanent planting type | C8: MSEP-Temp | D8: MSEP-Temp | E8: MSEP-Temp | F8: MSEP-Temp | G8: MSEP-Temp | H8: MSEP-Temp
A9: 1.4 | B9: Permanent planting established on or after 1 July 2007? | C9: Yes - see plant date | D9: Yes - see plant date | E9: Yes - see plant date | F9: Yes - see plant date | G9: Yes - see plant date | H9: Yes - see plant date
A10: 2.3 (3) | B10: Did not contain woody biomass that needed to be cleared prior to the planting going ahead (other than known weed species required by law to be cleared) | C10: No - refer mgt records | D10: No - refer mgt records | E10: No - refer mgt records | F10: No - refer mgt records | G10: No - refer mgt records | H10: No - refer mgt records
B11: Land clear at 1989? | C11: Yes | D11: Yes | E11: Yes | F11: Yes | G11: Yes | H11: Yes
B12: Planting required by law? | C12: No | D12: No | E12: No | F12: No | G12: No | H12: No
A13: 2.3 (4) | B13: Clear of forest cover for 5 years before planting | C13: Yes | D13: Yes | E13: Yes | F13: Yes | G13: Yes | H13: Yes
A14: 2.3 (5) | B14: Project trees have the potential to attain forest cover? | C14: Yes | D14: Yes | E14: Yes | F14: Yes | G14: Yes | H14: Yes
B15: Species planted | C15: E.tereticornis, E.moluccana, E.melanophloia, L.suaveolens, E.crebra, E.siderophloia, L.confertus, C.tessellaris, C.intermedia, C.clarksoniana, A.leiocarpa | D15: E.tereticornis, E.moluccana, E.melanophloia, L.suaveolens, E.crebra, E.siderophloia, L.confertus, C.tessellaris, C.intermedia, C.clarksoniana, A.leiocarpa | E15: E.tereticornis, E.moluccana, E.melanophloia, L.suaveolens, E.crebra, E.siderophloia, L.confertus, C.tessellaris, C.intermedia, C.clarksoniana, A.leiocarpa | F15: E.tereticornis, E.crebra, E.siderophloia, E.melliodora, E.albens, C.citridora, C.intermedia, C.trachyploia, L.confertus, E.Longirostrata | G15: E.tereticornis, C.citriodora, E.moluccana, E.propinqua, E.melanophloia, E.major, E.biturbinata, E.microcorys, E.longirostrata, L.confertus, A.leiocarpa, A.woodsiana, E.crebra, E.carnea, E.fibrosa, E.portuensis, E.acmenoides, M.viminalis, E.siderophloia, C.intermedia, C.trachyphloia | H15: Eucalyptus melliodora, Angophora floribund, Eucalyptus polyanthemos, Eucalyptus albens, Eucalyptus blakelyi, Allocasuarina verticillata, Grevillea robusta, Melia azedarach, Brachychition populneus, Acacia decurrens, Acacia baileyana
B16: RE Class | C16: 12.3.3 | D16: 12.9-10.2/12.9-10.7/12.9-10.19 | E16: 12.9-10.7 | F16: 12.8.16/12.8.14/12.8.9/12.8.4 | G16: 12.9-10.2/12.9-10.7/12.9-10.17a | H16: NSW PCTID 266, 277, 796 (White Box grassy woodland, Blakelys Red Gum - Yellow Box grassy tall woodland, Derived grassland of the NSW South Western Slopes)
B17: Soil type | C17: Kurosol | D17: Kurosol | E17: Kurosol | F17: Ferrosol - Red | G17: Sodosol | H17: Kandosol
B18: Aspect | C18: Varied | D18: Varied | E18: Varied | F18: Eastern & Northern | G18: Northern | H18: Varied - Creek edge
B19: Slope position | C19: Mid-lower | D19: Mid-lower | E19: Mid-lower | F19: Mid-lower | G19: Mid | H19: Lower
B20: Land management regime | C20: Biodiversity | D20: Biodiversity | E20: Biodiversity | F20: Biodiversity | G20: Biodiversity | H20: Biodiversity
B21: What are some key aspects which makes this a separate CEA to others? | C21: RE Class | D21: RE Class | E21: RE Class | F21: RE 12.8.16: Open forest on sedimentary rocks, dry hillsides | G21: RE Class | H21: Soil Type
B22: Planting type | C22: Mixed spp. | D22: Mixed spp. | E22: Mixed spp. | F22: Mixed spp. | G22: Mixed spp. | H22: Mixed spp.
B23: Planting geometry | C23: Block | D23: Block | E23: Block | F23: Block | G23: Block | H23: Block
B24: Planting spacing (rows, m) | C24: 4 | D24: 4 | E24: 4 | F24: 3 | G24: 4 | H24: 4
B25: Tree spacing (m) | C25: 4 | D25: 4 | E25: 4 | F25: 4.1 | G25: 4 | H25: 6
B26: Stocking density (assumed for modelling) | C26: <500 | D26: <500 | E26: <500 | F26: <500 | G26: <500 | H26: <500
B27: Tree proportion (assumed for modelling) | C27: <75% | D27: <75% | E27: <75% | F27: <75% | G27: <75% | H27: <75%
B28: Subject to competition from adjacent trees? | C28: Yes | D28: Yes | E28: Yes | F28: Yes | G28: Yes | H28: Yes
B29: CEA boundary distance from stems of outermost plants | C29: 0m | D29: 0m | E29: 0m | F29: 0m | G29: 0m | H29: 0m
B30: Planting Start Date | C30: 42064 | D30: 42064 | E30: 42064 | F30: 42064 | G30: 40939 | H30: 40299
B31: Planting Finish Date | C31: 42095 | D31: 42095 | E31: 42095 | F31: 42090 | G31: 40939 | H31: 40391
A32: 3.18 | B32: Average number of propagated seedling stock per ha | C32: 880 | D32: 880 | E32: 880 | F32: =(100/F24)*(100/F25) -> 813.00813 | G32: 625 | H32: 420
A33: 3.18 | B33: Tree proportion of trees to shrubs at planting | C33: 1 | D33: 1 | E33: 1 | F33: 1 | G33: 1 | H33: 0.85
A34: 3.3 (2) (c) | B34: Operations history | C34: Yes | D34: Yes | E34: Yes | F34: Yes | G34: Yes | H34: Yes
A35: 3.45, 3.48 | B35: Has harvesting or thinning occurred? | C35: No | D35: No | E35: No | F35: No | G35: No | H35: No
A36: 3.47 | B36: Has grazing affected forest cover? | C36: No | D36: No | E36: No | F36: No | G36: No | H36: No
A37: 3.49 | B37: Use of lime or fertilizer | C37: No | D37: No | E37: No | F37: No | G37: No | H37: No
B38: Disturbance events including fire | C38: Nil | D38: Nil | E38: Nil | F38: Nil | G38: Nil | H38: Nil
B39: Survival | C39: 0.95 | D39: 0.95 | E39: 0.95 | F39: 1.07 | G39: 0.9 | H39: 0.55
B40: Simple calculation of future crown cover assuming radius of 2m and 30% mortality since establishment | C40: =(PI()*2^2*C32*C39)/10000 -> 1.0505486 | D40: =(PI()*2^2*D32*D39)/10000 -> 1.0505486 | E40: =(PI()*2^2*E32*E39)/10000 -> 1.0505486 | F40: =(PI()*2^2*F32*F39)/10000 -> 1.0931721 | G40: =(PI()*2^2*G32*G39)/10000 -> 0.70685835 | H40: =(PI()*2^2*H32*H39)/10000 -> 0.29028316
...

Sheet Abatement - Report 8
A2: Division 5.4; Section 5.8(b)
F3: Equation 12a | G3: 2016 - Report 1 | I3: Equation 12b | J3: 2017 - Report 2 | L3: Equation 12b | M3: 2018 - Report 3 | O3: Equation 12b | P3: 2020 - Report 4 | R3: Equation 12b | S3: 2021 - Report 5 | U3: Equation 12b | V3: 2022 - Report 6 | X3: Equation 12b | Y3: 2023 - Report 7 | AA3: Equation 12b | AB3: 2024 - Report 8 | AD3: Equation 12b | AL3: Area | AM3: Net abatement
A4: CEA Name | B4: FullCAM calibration used | C4: CEA area (ha) | D4: Initial carbon mass trees - CDt (t C /ha) | E4: Initial carbon mass debris - CDd (t C /ha) | F4: Initial carbon mass - CD (t C) | G4: End carbon mass trees - Ct (t C /ha) | H4: End carbon mass debris - Cd (t C /ha) | I4: End carbon mass - C (t C) | J4: End carbon mass trees - Ct (t C /ha) | K4: End carbon mass debris - Cd (t C /ha) | L4: End carbon mass - C (t C) | M4: End carbon mass trees - Ct (t C /ha) | N4: End carbon mass debris - Cd (t C /ha) | O4: End carbon mass - C (t C) | P4: End carbon mass trees - Ct (t C /ha) | Q4: End carbon mass debris - Cd (t C /ha) | R4: End carbon mass - C (t C) | S4: End carbon mass trees - Ct (t C /ha) | T4: End carbon mass debris - Cd (t C /ha) | U4: End carbon mass - C (t C) | V4: End carbon mass trees - Ct (t C /ha) | W4: End carbon mass debris - Cd (t C /ha) | X4: End carbon mass - C (t C) | Y4: End carbon mass trees - Ct (t C /ha) | Z4: End carbon mass debris - Cd (t C /ha) | AA4: End carbon mass - C (t C) | AB4: End carbon mass trees - Ct (t C /ha) | AC4: End carbon mass debris - Cd (t C /ha) | AD4: End carbon mass - C (t C) | AI4: Carbon stock change | AM4: ='Net Abatement'!C11 -> 1989.3777 | AN4: Splits
A5: JIN_CEA_01 | B5: Mixed species environmental planting - temperate | C5: ='CEA Attributes'!F5 -> 8.76 | D5: 0 | E5: 0 | F5: =(D5+E5)*C5 -> 0 | G5: ='Abatement - Report 1'!G4 -> 1.2359209 | H5: ='Abatement - Report 1'!H4 -> 0.071879623 | I5: ='Abatement - Report 1'!I4 -> 11.456333 | J5: 18.665416 | K5: 1.8858156 | L5: 180.02879 | M5: 36.533445 | N5: 4.3853774 | O5: 358.44889 | P5: 49.303557 | Q5: 8.5171658 | R5: 506.50953 | S5: =JIN_CEA_01!E91 -> 56.138794 | T5: =JIN_CEA_01!F91 -> 10.672327 | U5: =(T5+S5)*C5 -> 585.26542 | V5: =JIN_CEA_01!E103 -> 60.67404 | W5: =JIN_CEA_01!F103 -> 12.497611 | X5: =(W5+V5)*C5 -> 640.98366 | Y5: =JIN_CEA_01!E115 -> 64.975261 | Z5: =JIN_CEA_01!F115 -> 14.058257 | AA5: =(Z5+Y5)*C5 -> 692.33362 | AB5: =JIN_CEA_01!E127 -> 72.922873 | AC5: =JIN_CEA_01!F127 -> 15.493313 | AD5: =(AC5+AB5)*C5 -> 774.52579 | AI5: =AD5-AA5 -> 82.192174 | AJ5: =AI5*(44/12) -> 301.3713 | AL5: =AI5/$AK$8 -> 0.14880947 | AN5: =$AM$4*AL5 -> 296.03823
A6: HID_CEA_01 | B6: Mixed species environmental planting - temperate | C6: ='CEA Attributes'!G5 -> 2.7 | D6: 0 | E6: 0 | F6: =(D6+E6)*C6 -> 0 | G6: ='Abatement - Report 1'!G5 -> 8.6244366 | H6: ='Abatement - Report 1'!H5 -> 1.1639746 | I6: ='Abatement - Report 1'!I5 -> 26.42871 | J6: 11.392651 | K6: 2.1026674 | L6: 36.43736 | M6: 15.008508 | N6: 2.815663 | O6: 48.12526 | P6: 20.333943 | Q6: 4.1384045 | R6: 66.075338 | S6: =HID_CEA_01!E129 -> 22.545254 | T6: =HID_CEA_01!F129 -> 2.1788461 | U6: =(T6+S6)*C6 -> 66.755071 | V6: =HID_CEA_01!E141 -> 24.404294 | W6: =HID_CEA_01!F141 -> 3.2140433 | X6: =(W6+V6)*C6 -> 74.569511 | Y6: =HID_CEA_01!E153 -> 26.342407 | Z6: =HID_CEA_01!F153 -> 4.0858451 | AA6: =(Z6+Y6)*C6 -> 82.15628 | AB6: =HID_CEA_01!E165 -> 27.281937 | AC6: =HID_CEA_01!F165 -> 4.815221 | AD6: =(AC6+AB6)*C6 -> 86.662325 | AI6: =AD6-AA6 -> 4.5060454 | AJ6: =AI6*(44/12) -> 16.522167 | AL6: =AI6/$AK$8 -> 0.0081582246 | AN6: =$AM$4*AL6 -> 16.22979
A7: LIS_CEA_01 | B7: Mixed species environmental planting - temperate | C7: ='CEA Attributes'!H5 -> 3.24 | D7: =LIS_CEA_01!E20 -> 0.29377931 | E7: =LIS_CEA_01!F20 -> 0.033778268 | F7: =(D7+E7)*C7 -> 1.0612866 | G7: ='Abatement - Report 1'!G6 -> 3.6519413 | H7: ='Abatement - Report 1'!H6 -> 0.64600861 | I7: ='Abatement - Report 1'!I6 -> 13.925358 | J7: 6.0646123 | K7: 1.1987738 | L7: 23.533371 | M7: 7.8642871 | N7: 1.6702547 | O7: 30.891915 | P7: 13.213963 | Q7: 3.1108819 | R7: 52.892496 | S7: =LIS_CEA_01!E146 -> 16.4708 | T7: =LIS_CEA_01!F146 -> 3.7039664 | U7: =(T7+S7)*C7 -> 65.366242 | V7: =LIS_CEA_01!E158 -> 19.424544 | W7: =LIS_CEA_01!F158 -> 4.2933919 | X7: =(W7+V7)*C7 -> 76.846112 | Y7: =LIS_CEA_01!E170 -> 20.78958 | Z7: =LIS_CEA_01!F170 -> 4.8296846 | AA7: =(Z7+Y7)*C7 -> 83.006417 | AB7: =LIS_CEA_01!E182 -> 22.086285 | AC7: =LIS_CEA_01!F182 -> 5.2983251 | AD7: =(AC7+AB7)*C7 -> 88.726137 | AI7: =AD7-AA7 -> 5.7197207 | AJ7: =AI7*(44/12) -> 20.972309 | AL7: =AI7/$AK$8 -> 0.010355592 | AN7: =$AM$4*AL7 -> 20.601183
A8: STE_CEA_01 | B8: Mixed species environmental planting - temperate | C8: ='CEA Attributes'!C5 -> 13.77 | D8: 0 | E8: 0 | F8: =(D8+E8)*C8 -> 0 | G8: ='Abatement - Report 1'!G7 -> 4.492529 | H8: ='Abatement - Report 1'!H7 -> 0.17131219 | I8: ='Abatement - Report 1'!I7 -> 64.221093 | J8: 15.2929 | K8: 1.8717138 | L8: 236.35674 | M8: 23.247 | N8: 3.3669807 | O8: 366.47451 | P8: 34.431617 | Q8: 6.2363016 | R8: 559.99723 | S8: =STE_CEA_01!E90 -> 38.837186 | T8: =STE_CEA_01!F90 -> 7.4784789 | U8: =(T8+S8)*C8 -> 637.76671 | V8: =STE_CEA_01!E102 -> 43.347083 | W8: =STE_CEA_01!F102 -> 8.5966302 | X8: =(W8+V8)*C8 -> 715.26493 | Y8: =STE_CEA_01!E114 -> 47.219661 | Z8: =STE_CEA_01!F114 -> 9.6093875 | AA8: =(Z8+Y8)*C8 -> 782.53599 | AB8: =STE_CEA_01!E126 -> 50.703374 | AC8: =STE_CEA_01!F126 -> 10.522407 | AD8: =(AC8+AB8)*C8 -> 843.07901 | AI8: =SUM(AD8:AD10)-SUM(AA8:AA10) -> 459.91368 | AJ8: =AI8*(44/12) -> 1686.3502 | AK8: =SUM(AD5:AD10)-SUM(AA5:AA10) -> 552.33162 | AL8: =AI8/$AK$8 -> 0.83267672 | AN8: =$AM$4*AL8 -> 1656.5085
A9: STE_CEA_02 | B9: Mixed species environmental planting - temperate | C9: ='CEA Attributes'!D5 -> 24.62 | D9: 0 | E9: 0 | F9: =(D9+E9)*C9 -> 0 | G9: ='Abatement - Report 1'!G8 -> 4.5082506 | H9: ='Abatement - Report 1'!H8 -> 0.17253132 | I9: ='Abatement - Report 1'!I8 -> 115.24085 | J9: 15.337401 | K9: 1.8790375 | L9: 423.86873 | M9: 23.310063 | N9: 3.3806721 | O9: 657.1259 | P9: 34.520037 | Q9: 6.2648943 | R9: 1004.125 | S9: =STE_CEA_02!E90 -> 38.935505 | T9: =STE_CEA_02!F90 -> 7.5147016 | U9: =(T9+S9)*C9 -> 1143.6041 | V9: =STE_CEA_02!E102 -> 43.455543 | W9: =STE_CEA_02!F102 -> 8.6402691 | X9: =(W9+V9)*C9 -> 1282.5989 | Y9: =STE_CEA_02!E114 -> 47.336821 | Z9: =STE_CEA_02!F114 -> 9.6601315 | AA9: =(Z9+Y9)*C9 -> 1403.265 | AB9: =STE_CEA_02!E126 -> 50.828374 | AC9: =STE_CEA_02!F126 -> 10.579838 | AD9: =(AC9+AB9)*C9 -> 1511.8702 | AN9: =SUM(AN5:AN8) -> 1989.3777
A10: STE_CEA_03 | B10: Mixed species environmental planting - temperate | C10: ='CEA Attributes'!E5 -> 66.16 | D10: 0 | E10: 0 | F10: =(D10+E10)*C10 -> 0 | G10: ='Abatement - Report 1'!G9 -> 4.4925867 | H10: ='Abatement - Report 1'!H9 -> 0.17205496 | I10: ='Abatement - Report 1'!I9 -> 308.61269 | J10: 15.28149 | K10: 1.8723688 | L10: 1134.8993 | M10: 23.224519 | N10: 3.3684945 | O10: 1759.3938 | P10: 34.39283 | Q10: 6.2420985 | R10: 2688.4069 | S10: =STE_CEA_03!E90 -> 38.791888 | T10: =STE_CEA_03!F90 -> 7.4872964 | U10: =(T10+S10)*C10 -> 3061.8308 | V10: =STE_CEA_03!E102 -> 43.295126 | W10: =STE_CEA_03!F102 -> 8.6087093 | X10: =(W10+V10)*C10 -> 3433.9577 | Y10: =STE_CEA_03!E114 -> 47.161979 | Z10: =STE_CEA_03!F114 -> 9.6248044 | AA10: =(Z10+Y10)*C10 -> 3757.0136 | AB10: =STE_CEA_03!E126 -> 50.640555 | AC10: =STE_CEA_03!F126 -> 10.541112 | AD10: =(AC10+AB10)*C10 -> 4047.7791
E13: Initial carbon stock CN (tCO2e) | F13: =SUM(F5:F10)*44/12 -> 3.891384 | H13: End carbon stock CP (tCO2e) | I13: =SUM(I5:I10)*44/12 -> 1979.5785 | K13: End carbon stock CP (tCO2e) | L13: 7462.1223 | N13: End carbon stock CP (tCO2e) | O13: 11808.354 | Q13: End carbon stock CP (tCO2e) | R13: =SUM(R5:R10)*44/12 -> 17886.024 | T13: End carbon stock CP (tCO2e) | U13: =SUM(U5:U10)*44/12 -> 20388.824 | W13: End carbon stock CP (tCO2e) | X13: =SUM(X5:X10)*44/12 -> 22822.143 | Z13: End carbon stock CP (tCO2e) | AA13: =SUM(AA5:AA10)*44/12 -> 24934.473 | AC13: End carbon stock CP (tCO2e) | AD13: =SUM(AD5:AD10)*44/12 -> 26959.689
E14: (Equation 11a) | H14: Equation 11b | K14: Equation 11b | N14: Equation 11b | Q14: Equation 11b | T14: Equation 11b | W14: Equation 11b | Z14: Equation 11b | AC14: Equation 11b
E16: Carbon stock change for project (tCO2-e) (5.8 (b)) | AA16: =AA13-$F13 -> 24930.582 | AC16: Total CO2 reduction to end of 2024: | AD16: =AD13-$F13 -> 26955.798
AA21: =AA13-X13 -> 2112.3301 | AC21: t CO2 sequestered in 2024: | AD21: =AD13-AA13 -> 2025.216

Sheet Abatement - Report 7
A2: Division 5.4; Section 5.8(b)
F3: Equation 12a | G3: 2016 - Report 1 | I3: Equation 12b | J3: 2017 - Report 2 | L3: Equation 12b | M3: 2018 - Report 3 | O3: Equation 12b | P3: 2020 - Report 4 | R3: Equation 12b | S3: 2021 - Report 5 | U3: Equation 12b | V3: 2022 - Report 6 | X3: Equation 12b | Y3: 2023 - Report 7 | AA3: Equation 12b | AG3: Area | AH3: Net abatement
A4: CEA Name | B4: FullCAM calibration used | C4: CEA area (ha) | D4: Initial carbon mass trees - CDt (t C /ha) | E4: Initial carbon mass debris - CDd (t C /ha) | F4: Initial carbon mass - CD (t C) | G4: End carbon mass trees - Ct (t C /ha) | H4: End carbon mass debris - Cd (t C /ha) | I4: End carbon mass - C (t C) | J4: End carbon mass trees - Ct (t C /ha) | K4: End carbon mass debris - Cd (t C /ha) | L4: End carbon mass - C (t C) | M4: End carbon mass trees - Ct (t C /ha) | N4: End carbon mass debris - Cd (t C /ha) | O4: End carbon mass - C (t C) | P4: End carbon mass trees - Ct (t C /ha) | Q4: End carbon mass debris - Cd (t C /ha) | R4: End carbon mass - C (t C) | S4: End carbon mass trees - Ct (t C /ha) | T4: End carbon mass debris - Cd (t C /ha) | U4: End carbon mass - C (t C) | V4: End carbon mass trees - Ct (t C /ha) | W4: End carbon mass debris - Cd (t C /ha) | X4: End carbon mass - C (t C) | Y4: End carbon mass trees - Ct (t C /ha) | Z4: End carbon mass debris - Cd (t C /ha) | AA4: End carbon mass - C (t C) | AD4: Carbon stock change | AG4: 6063.66 | AH4: ='Net Abatement'!C11 -> 1989.3777 | AI4: Splits
A5: JIN_CEA_01 | B5: Mixed species environmental planting - temperate | C5: ='CEA Attributes'!F5 -> 8.76 | D5: 0 | E5: 0 | F5: =(D5+E5)*C5 -> 0 | G5: ='Abatement - Report 1'!G4 -> 1.2359209 | H5: ='Abatement - Report 1'!H4 -> 0.071879623 | I5: ='Abatement - Report 1'!I4 -> 11.456333 | J5: 18.665416 | K5: 1.8858156 | L5: 180.02879 | M5: 36.533445 | N5: 4.3853774 | O5: 358.44889 | P5: 49.303557 | Q5: 8.5171658 | R5: 506.50953 | S5: =JIN_CEA_01!E91 -> 56.138794 | T5: =JIN_CEA_01!F91 -> 10.672327 | U5: =(T5+S5)*C5 -> 585.26542 | V5: =JIN_CEA_01!E103 -> 60.67404 | W5: =JIN_CEA_01!F103 -> 12.497611 | X5: =(W5+V5)*C5 -> 640.98366 | Y5: =JIN_CEA_01!E115 -> 64.975261 | Z5: =JIN_CEA_01!F115 -> 14.058257 | AA5: =(Z5+Y5)*C5 -> 692.33362 | AD5: =AA5-X5 -> 51.349958 | AE5: =AD5*(44/12) -> 188.28318 | AG5: =AD5/$AF$8 -> 0.089135301 | AH5: =AG5*$AG$4 -> 540.48616 | AI5: =$AH$4*AG5 -> 177.32378
A6: HID_CEA_01 | B6: Mixed species environmental planting - temperate | C6: ='CEA Attributes'!G5 -> 2.7 | D6: 0 | E6: 0 | F6: =(D6+E6)*C6 -> 0 | G6: ='Abatement - Report 1'!G5 -> 8.6244366 | H6: ='Abatement - Report 1'!H5 -> 1.1639746 | I6: ='Abatement - Report 1'!I5 -> 26.42871 | J6: 11.392651 | K6: 2.1026674 | L6: 36.43736 | M6: 15.008508 | N6: 2.815663 | O6: 48.12526 | P6: 20.333943 | Q6: 4.1384045 | R6: 66.075338 | S6: =HID_CEA_01!E129 -> 22.545254 | T6: =HID_CEA_01!F129 -> 2.1788461 | U6: =(T6+S6)*C6 -> 66.755071 | V6: =HID_CEA_01!E141 -> 24.404294 | W6: =HID_CEA_01!F141 -> 3.2140433 | X6: =(W6+V6)*C6 -> 74.569511 | Y6: =HID_CEA_01!E153 -> 26.342407 | Z6: =HID_CEA_01!F153 -> 4.0858451 | AA6: =(Z6+Y6)*C6 -> 82.15628 | AD6: =AA6-X6 -> 7.5867693 | AE6: =AD6*(44/12) -> 27.818154 | AG6: =AD6/$AF$8 -> 0.013169416 | AH6: =AG6*$AG$4 -> 79.854862 | AI6: =$AH$4*AG6 -> 26.198943
A7: LIS_CEA_01 | B7: Mixed species environmental planting - temperate | C7: ='CEA Attributes'!H5 -> 3.24 | D7: =LIS_CEA_01!E20 -> 0.29377931 | E7: =LIS_CEA_01!F20 -> 0.033778268 | F7: =(D7+E7)*C7 -> 1.0612866 | G7: ='Abatement - Report 1'!G6 -> 3.6519413 | H7: ='Abatement - Report 1'!H6 -> 0.64600861 | I7: ='Abatement - Report 1'!I6 -> 13.925358 | J7: 6.0646123 | K7: 1.1987738 | L7: 23.533371 | M7: 7.8642871 | N7: 1.6702547 | O7: 30.891915 | P7: 13.213963 | Q7: 3.1108819 | R7: 52.892496 | S7: =LIS_CEA_01!E146 -> 16.4708 | T7: =LIS_CEA_01!F146 -> 3.7039664 | U7: =(T7+S7)*C7 -> 65.366242 | V7: =LIS_CEA_01!E158 -> 19.424544 | W7: =LIS_CEA_01!F158 -> 4.2933919 | X7: =(W7+V7)*C7 -> 76.846112 | Y7: =LIS_CEA_01!E170 -> 20.78958 | Z7: =LIS_CEA_01!F170 -> 4.8296846 | AA7: =(Z7+Y7)*C7 -> 83.006417 | AD7: =AA7-X7 -> 6.1603042 | AE7: =AD7*(44/12) -> 22.587782 | AG7: =AD7/$AF$8 -> 0.010693301 | AH7: =AG7*$AG$4 -> 64.840542 | AI7: =$AH$4*AG7 -> 21.273015
A8: STE_CEA_01 | B8: Mixed species environmental planting - temperate | C8: ='CEA Attributes'!C5 -> 13.77 | D8: 0 | E8: 0 | F8: =(D8+E8)*C8 -> 0 | G8: ='Abatement - Report 1'!G7 -> 4.492529 | H8: ='Abatement - Report 1'!H7 -> 0.17131219 | I8: ='Abatement - Report 1'!I7 -> 64.221093 | J8: 15.2929 | K8: 1.8717138 | L8: 236.35674 | M8: 23.247 | N8: 3.3669807 | O8: 366.47451 | P8: 34.431617 | Q8: 6.2363016 | R8: 559.99723 | S8: =STE_CEA_01!E90 -> 38.837186 | T8: =STE_CEA_01!F90 -> 7.4784789 | U8: =(T8+S8)*C8 -> 637.76671 | V8: =STE_CEA_01!E102 -> 43.347083 | W8: =STE_CEA_01!F102 -> 8.5966302 | X8: =(W8+V8)*C8 -> 715.26493 | Y8: =STE_CEA_01!E114 -> 47.219661 | Z8: =STE_CEA_01!F114 -> 9.6093875 | AA8: =(Z8+Y8)*C8 -> 782.53599 | AD8: =SUM(AA8:AA10)-SUM(X8:X10) -> 510.993 | AE8: =AD8*(44/12) -> 1873.641 | AF8: =SUM(AA5:AA10)-SUM(X5:X10) -> 576.09003 | AG8: =AD8/$AF$8 -> 0.88700198 | AH8: =AG8*$AG$4 -> 5378.4784 | AI8: =$AH$4*AG8 -> 1764.582
A9: STE_CEA_02 | B9: Mixed species environmental planting - temperate | C9: ='CEA Attributes'!D5 -> 24.62 | D9: 0 | E9: 0 | F9: =(D9+E9)*C9 -> 0 | G9: ='Abatement - Report 1'!G8 -> 4.5082506 | H9: ='Abatement - Report 1'!H8 -> 0.17253132 | I9: ='Abatement - Report 1'!I8 -> 115.24085 | J9: 15.337401 | K9: 1.8790375 | L9: 423.86873 | M9: 23.310063 | N9: 3.3806721 | O9: 657.1259 | P9: 34.520037 | Q9: 6.2648943 | R9: 1004.125 | S9: =STE_CEA_02!E90 -> 38.935505 | T9: =STE_CEA_02!F90 -> 7.5147016 | U9: =(T9+S9)*C9 -> 1143.6041 | V9: =STE_CEA_02!E102 -> 43.455543 | W9: =STE_CEA_02!F102 -> 8.6402691 | X9: =(W9+V9)*C9 -> 1282.5989 | Y9: =STE_CEA_02!E114 -> 47.336821 | Z9: =STE_CEA_02!F114 -> 9.6601315 | AA9: =(Z9+Y9)*C9 -> 1403.265 | AI9: =SUM(AI5:AI8) -> 1989.3777
A10: STE_CEA_03 | B10: Mixed species environmental planting - temperate | C10: ='CEA Attributes'!E5 -> 66.16 | D10: 0 | E10: 0 | F10: =(D10+E10)*C10 -> 0 | G10: ='Abatement - Report 1'!G9 -> 4.4925867 | H10: ='Abatement - Report 1'!H9 -> 0.17205496 | I10: ='Abatement - Report 1'!I9 -> 308.61269 | J10: 15.28149 | K10: 1.8723688 | L10: 1134.8993 | M10: 23.224519 | N10: 3.3684945 | O10: 1759.3938 | P10: 34.39283 | Q10: 6.2420985 | R10: 2688.4069 | S10: =STE_CEA_03!E90 -> 38.791888 | T10: =STE_CEA_03!F90 -> 7.4872964 | U10: =(T10+S10)*C10 -> 3061.8308 | V10: =STE_CEA_03!E102 -> 43.295126 | W10: =STE_CEA_03!F102 -> 8.6087093 | X10: =(W10+V10)*C10 -> 3433.9577 | Y10: =STE_CEA_03!E114 -> 47.161979 | Z10: =STE_CEA_03!F114 -> 9.6248044 | AA10: =(Z10+Y10)*C10 -> 3757.0136
E13: Initial carbon stock CN (tCO2e) | F13: =SUM(F5:F10)*44/12 -> 3.891384 | H13: End carbon stock CP (tCO2e) | I13: =SUM(I5:I10)*44/12 -> 1979.5785 | K13: End carbon stock CP (tCO2e) | L13: 7462.1223 | N13: End carbon stock CP (tCO2e) | O13: 11808.354 | Q13: End carbon stock CP (tCO2e) | R13: =SUM(R5:R10)*44/12 -> 17886.024 | T13: End carbon stock CP (tCO2e) | U13: =SUM(U5:U10)*44/12 -> 20388.824 | W13: End carbon stock CP (tCO2e) | X13: =SUM(X5:X10)*44/12 -> 22822.143 | Z13: End carbon stock CP (tCO2e) | AA13: =SUM(AA5:AA10)*44/12 -> 24934.473
E14: (Equation 11a) | H14: Equation 11b | K14: Equation 11b | N14: Equation 11b | Q14: Equation 11b | T14: Equation 11b | W14: Equation 11b | Z14: Equation 11b
E16: Carbon stock change for project (tCO2-e) (5.8 (b)) | AA16: =AA13-F13 -> 24930.582
AA21: =AA13-X13 -> 2112.3301
Q32: =576*44/12 -> 2112

Sheet Abatement - Report 6
A2: Division 5.4; Section 5.8(b)
F3: Equation 12a | G3: 2016 - Report 1 | I3: Equation 12b | J3: 2017 - Report 2 | L3: Equation 12b | M3: 2018 - Report 3 | O3: Equation 12b | P3: 2020 - Report 4 | R3: Equation 12b | S3: 2021 - Report 5 | U3: Equation 12b | V3: 2022 - Report 6 | X3: Equation 12b | AD3: Area | AE3: Net abatement
A4: CEA Name | B4: FullCAM calibration used | C4: CEA area (ha) | D4: Initial carbon mass trees - CDt (t C /ha) | E4: Initial carbon mass debris - CDd (t C /ha) | F4: Initial carbon mass - CD (t C) | G4: End carbon mass trees - Ct (t C /ha) | H4: End carbon mass debris - Cd (t C /ha) | I4: End carbon mass - C (t C) | J4: End carbon mass trees - Ct (t C /ha) | K4: End carbon mass debris - Cd (t C /ha) | L4: End carbon mass - C (t C) | M4: End carbon mass trees - Ct (t C /ha) | N4: End carbon mass debris - Cd (t C /ha) | O4: End carbon mass - C (t C) | P4: End carbon mass trees - Ct (t C /ha) | Q4: End carbon mass debris - Cd (t C /ha) | R4: End carbon mass - C (t C) | S4: End carbon mass trees - Ct (t C /ha) | T4: End carbon mass debris - Cd (t C /ha) | U4: End carbon mass - C (t C) | V4: End carbon mass trees - Ct (t C /ha) | W4: End carbon mass debris - Cd (t C /ha) | X4: End carbon mass - C (t C) | AA4: Carbon stock change | AD4: 6063.66 | AE4: ='Net Abatement'!C11 -> 1989.3777 | AF4: Splits
A5: JIN_CEA_01 | B5: Mixed species environmental planting - temperate | C5: ='CEA Attributes'!F5 -> 8.76 | D5: 0 | E5: 0 | F5: =(D5+E5)*C5 -> 0 | G5: ='Abatement - Report 1'!G4 -> 1.2359209 | H5: ='Abatement - Report 1'!H4 -> 0.071879623 | I5: ='Abatement - Report 1'!I4 -> 11.456333 | J5: 18.665416 | K5: 1.8858156 | L5: 180.02879 | M5: 36.533445 | N5: 4.3853774 | O5: 358.44889 | P5: 49.303557 | Q5: 8.5171658 | R5: 506.50953 | S5: =JIN_CEA_01!E91 -> 56.138794 | T5: =JIN_CEA_01!F91 -> 10.672327 | U5: =(T5+S5)*C5 -> 585.26542 | V5: =JIN_CEA_01!E103 -> 60.67404 | W5: =JIN_CEA_01!F103 -> 12.497611 | X5: =(W5+V5)*C5 -> 640.98366 | AA5: =X5-U5 -> 55.71824 | AB5: =AA5*(44/12) -> 204.30021 | AD5: =AA5/$AC$8 -> 0.083959487 | AE5: =AD5*$AD$4 -> 509.10178 | AF5: =$AE$4*AD5 -> 167.02713
A6: HID_CEA_01 | B6: Mixed species environmental planting - temperate | C6: ='CEA Attributes'!G5 -> 2.7 | D6: 0 | E6: 0 | F6: =(D6+E6)*C6 -> 0 | G6: ='Abatement - Report 1'!G5 -> 8.6244366 | H6: ='Abatement - Report 1'!H5 -> 1.1639746 | I6: ='Abatement - Report 1'!I5 -> 26.42871 | J6: 11.392651 | K6: 2.1026674 | L6: 36.43736 | M6: 15.008508 | N6: 2.815663 | O6: 48.12526 | P6: 20.333943 | Q6: 4.1384045 | R6: 66.075338 | S6: =HID_CEA_01!E129 -> 22.545254 | T6: =HID_CEA_01!F129 -> 2.1788461 | U6: =(T6+S6)*C6 -> 66.755071 | V6: =HID_CEA_01!E141 -> 24.404294 | W6: =HID_CEA_01!F141 -> 3.2140433 | X6: =(W6+V6)*C6 -> 74.569511 | AA6: =X6-U6 -> 7.8144391 | AB6: =AA6*(44/12) -> 28.652943 | AD6: =AA6/$AC$8 -> 0.011775252 | AE6: =AD6*$AD$4 -> 71.401122 | AF6: =$AE$4*AD6 -> 23.425423
A7: LIS_CEA_01 | B7: Mixed species environmental planting - temperate | C7: ='CEA Attributes'!H5 -> 3.24 | D7: =LIS_CEA_01!E20 -> 0.29377931 | E7: =LIS_CEA_01!F20 -> 0.033778268 | F7: =(D7+E7)*C7 -> 1.0612866 | G7: ='Abatement - Report 1'!G6 -> 3.6519413 | H7: ='Abatement - Report 1'!H6 -> 0.64600861 | I7: ='Abatement - Report 1'!I6 -> 13.925358 | J7: 6.0646123 | K7: 1.1987738 | L7: 23.533371 | M7: 7.8642871 | N7: 1.6702547 | O7: 30.891915 | P7: 13.213963 | Q7: 3.1108819 | R7: 52.892496 | S7: =LIS_CEA_01!E146 -> 16.4708 | T7: =LIS_CEA_01!F146 -> 3.7039664 | U7: =(T7+S7)*C7 -> 65.366242 | V7: =LIS_CEA_01!E158 -> 19.424544 | W7: =LIS_CEA_01!F158 -> 4.2933919 | X7: =(W7+V7)*C7 -> 76.846112 | AA7: =X7-U7 -> 11.47987 | AB7: =AA7*(44/12) -> 42.092857 | AD7: =AA7/$AC$8 -> 0.017298536 | AE7: =AD7*$AD$4 -> 104.89244 | AF7: =$AE$4*AD7 -> 34.413322
A8: STE_CEA_01 | B8: Mixed species environmental planting - temperate | C8: ='CEA Attributes'!C5 -> 13.77 | D8: 0 | E8: 0 | F8: =(D8+E8)*C8 -> 0 | G8: ='Abatement - Report 1'!G7 -> 4.492529 | H8: ='Abatement - Report 1'!H7 -> 0.17131219 | I8: ='Abatement - Report 1'!I7 -> 64.221093 | J8: 15.2929 | K8: 1.8717138 | L8: 236.35674 | M8: 23.247 | N8: 3.3669807 | O8: 366.47451 | P8: 34.431617 | Q8: 6.2363016 | R8: 559.99723 | S8: =STE_CEA_01!E90 -> 38.837186 | T8: =STE_CEA_01!F90 -> 7.4784789 | U8: =(T8+S8)*C8 -> 637.76671 | V8: =STE_CEA_01!E102 -> 43.347083 | W8: =STE_CEA_01!F102 -> 8.5966302 | X8: =(W8+V8)*C8 -> 715.26493 | AA8: =SUM(X8:X10)-SUM(U8:U10) -> 588.61991 | AB8: =AA8*(44/12) -> 2158.273 | AC8: =SUM(X5:X10)-SUM(U5:U10) -> 663.63245 | AD8: =AA8/$AC$8 -> 0.88696673 | AE8: =AD8*$AD$4 -> 5378.2647 | AF8: =$AE$4*AD8 -> 1764.5118
A9: STE_CEA_02 | B9: Mixed species environmental planting - temperate | C9: ='CEA Attributes'!D5 -> 24.62 | D9: 0 | E9: 0 | F9: =(D9+E9)*C9 -> 0 | G9: ='Abatement - Report 1'!G8 -> 4.5082506 | H9: ='Abatement - Report 1'!H8 -> 0.17253132 | I9: ='Abatement - Report 1'!I8 -> 115.24085 | J9: 15.337401 | K9: 1.8790375 | L9: 423.86873 | M9: 23.310063 | N9: 3.3806721 | O9: 657.1259 | P9: 34.520037 | Q9: 6.2648943 | R9: 1004.125 | S9: =STE_CEA_02!E90 -> 38.935505 | T9: =STE_CEA_02!F90 -> 7.5147016 | U9: =(T9+S9)*C9 -> 1143.6041 | V9: =STE_CEA_02!E102 -> 43.455543 | W9: =STE_CEA_02!F102 -> 8.6402691 | X9: =(W9+V9)*C9 -> 1282.5989 | AF9: =SUM(AF5:AF8) -> 1989.3777
A10: STE_CEA_03 | B10: Mixed species environmental planting - temperate | C10: ='CEA Attributes'!E5 -> 66.16 | D10: 0 | E10: 0 | F10: =(D10+E10)*C10 -> 0 | G10: ='Abatement - Report 1'!G9 -> 4.4925867 | H10: ='Abatement - Report 1'!H9 -> 0.17205496 | I10: ='Abatement - Report 1'!I9 -> 308.61269 | J10: 15.28149 | K10: 1.8723688 | L10: 1134.8993 | M10: 23.224519 | N10: 3.3684945 | O10: 1759.3938 | P10: 34.39283 | Q10: 6.2420985 | R10: 2688.4069 | S10: =STE_CEA_03!E90 -> 38.791888 | T10: =STE_CEA_03!F90 -> 7.4872964 | U10: =(T10+S10)*C10 -> 3061.8308 | V10: =STE_CEA_03!E102 -> 43.295126 | W10: =STE_CEA_03!F102 -> 8.6087093 | X10: =(W10+V10)*C10 -> 3433.9577
E13: Initial carbon stock CN (tCO2e) | F13: =SUM(F5:F10)*44/12 -> 3.891384 | H13: End carbon stock CP (tCO2e) | I13: =SUM(I5:I10)*44/12 -> 1979.5785 | K13: End carbon stock CP (tCO2e) | L13: 7462.1223 | N13: End carbon stock CP (tCO2e) | O13: 11808.354 | Q13: End carbon stock CP (tCO2e) | R13: =SUM(R5:R10)*44/12 -> 17886.024 | T13: End carbon stock CP (tCO2e) | U13: =SUM(U5:U10)*44/12 -> 20388.824 | W13: End carbon stock CP (tCO2e) | X13: =SUM(X5:X10)*44/12 -> 22822.143
E14: (Equation 11a) | H14: Equation 11b | K14: Equation 11b | N14: Equation 11b | Q14: Equation 11b | T14: Equation 11b | W14: Equation 11b
E16: Carbon stock change for project (tCO2-e) (5.8 (b)) | X16: =X13-F13 -> 22818.252
X21: =X13-U13 -> 2433.319

Sheet Abatement - Report 5
A2: Division 5.4; Section 5.8(b)
F3: Equation 12a | G3: 2016 - Report 1 | I3: Equation 12b | J3: 2017 - Report 2 | L3: Equation 12b | M3: 2018 - Report 3 | O3: Equation 12b | P3: 2020 - Report 4 | R3: Equation 12b | S3: 2021 - Report 5 | U3: Equation 12b | Z3: Area | AA3: Net abatement
A4: CEA Name | B4: FullCAM calibration used | C4: CEA area (ha) | D4: Initial carbon mass trees - CDt (t C /ha) | E4: Initial carbon mass debris - CDd (t C /ha) | F4: Initial carbon mass - CD (t C) | G4: End carbon mass trees - Ct (t C /ha) | H4: End carbon mass debris - Cd (t C /ha) | I4: End carbon mass - C (t C) | J4: End carbon mass trees - Ct (t C /ha) | K4: End carbon mass debris - Cd (t C /ha) | L4: End carbon mass - C (t C) | M4: End carbon mass trees - Ct (t C /ha) | N4: End carbon mass debris - Cd (t C /ha) | O4: End carbon mass - C (t C) | P4: End carbon mass trees - Ct (t C /ha) | Q4: End carbon mass debris - Cd (t C /ha) | R4: End carbon mass - C (t C) | S4: End carbon mass trees - Ct (t C /ha) | T4: End carbon mass debris - Cd (t C /ha) | U4: End carbon mass - C (t C) | W4: Carbon stock change | Z4: 6063.66 | AA4: ='Net Abatement'!C11 -> 1989.3777 | AB4: Splits
A5: JIN_CEA_01 | B5: Mixed species environmental planting - temperate | C5: ='CEA Attributes'!F5 -> 8.76 | D5: 0 | E5: 0 | F5: =(D5+E5)*C5 -> 0 | G5: ='Abatement - Report 1'!G4 -> 1.2359209 | H5: ='Abatement - Report 1'!H4 -> 0.071879623 | I5: ='Abatement - Report 1'!I4 -> 11.456333 | J5: 18.665416 | K5: 1.8858156 | L5: 180.02879 | M5: 36.533445 | N5: 4.3853774 | O5: 358.44889 | P5: 49.303557 | Q5: 8.5171658 | R5: 506.50953 | S5: =JIN_CEA_01!E91 -> 56.138794 | T5: =JIN_CEA_01!F91 -> 10.672327 | U5: =(T5+S5)*C5 -> 585.26542 | W5: =U5-R5 -> 78.755889 | X5: =W5*(44/12) -> 288.77159 | Z5: =W5/$Y$8 -> 0.1153794 | AA5: =Z5*$Z$4 -> 699.62144 | AB5: =$AA$4*Z5 -> 229.5332
A6: HID_CEA_01 | B6: Mixed species environmental planting - temperate | C6: ='CEA Attributes'!G5 -> 2.7 | D6: 0 | E6: 0 | F6: =(D6+E6)*C6 -> 0 | G6: ='Abatement - Report 1'!G5 -> 8.6244366 | H6: ='Abatement - Report 1'!H5 -> 1.1639746 | I6: ='Abatement - Report 1'!I5 -> 26.42871 | J6: 11.392651 | K6: 2.1026674 | L6: 36.43736 | M6: 15.008508 | N6: 2.815663 | O6: 48.12526 | P6: 20.333943 | Q6: 4.1384045 | R6: 66.075338 | S6: =HID_CEA_01!E129 -> 22.545254 | T6: =HID_CEA_01!F129 -> 2.1788461 | U6: =(T6+S6)*C6 -> 66.755071 | W6: =U6-R6 -> 0.67973297 | X6: =W6*(44/12) -> 2.4923542 | Z6: =W6/$Y$8 -> 0.00099582624 | AA6: =Z6*$Z$4 -> 6.0383518 | AB6: =$AA$4*Z6 -> 1.9810745
A7: LIS_CEA_01 | B7: Mixed species environmental planting - temperate | C7: ='CEA Attributes'!H5 -> 3.24 | D7: =LIS_CEA_01!E20 -> 0.29377931 | E7: =LIS_CEA_01!F20 -> 0.033778268 | F7: =(D7+E7)*C7 -> 1.0612866 | G7: ='Abatement - Report 1'!G6 -> 3.6519413 | H7: ='Abatement - Report 1'!H6 -> 0.64600861 | I7: ='Abatement - Report 1'!I6 -> 13.925358 | J7: 6.0646123 | K7: 1.1987738 | L7: 23.533371 | M7: 7.8642871 | N7: 1.6702547 | O7: 30.891915 | P7: 13.213963 | Q7: 3.1108819 | R7: 52.892496 | S7: =LIS_CEA_01!E146 -> 16.4708 | T7: =LIS_CEA_01!F146 -> 3.7039664 | U7: =(T7+S7)*C7 -> 65.366242 | W7: =U7-R7 -> 12.473746 | X7: =W7*(44/12) -> 45.737069 | Z7: =W7/$Y$8 -> 0.018274358 | AA7: =Z7*$Z$4 -> 110.80949 | AB7: =$AA$4*Z7 -> 36.354601
A8: STE_CEA_01 | B8: Mixed species environmental planting - temperate | C8: ='CEA Attributes'!C5 -> 13.77 | D8: 0 | E8: 0 | F8: =(D8+E8)*C8 -> 0 | G8: ='Abatement - Report 1'!G7 -> 4.492529 | H8: ='Abatement - Report 1'!H7 -> 0.17131219 | I8: ='Abatement - Report 1'!I7 -> 64.221093 | J8: 15.2929 | K8: 1.8717138 | L8: 236.35674 | M8: 23.247 | N8: 3.3669807 | O8: 366.47451 | P8: 34.431617 | Q8: 6.2363016 | R8: 559.99723 | S8: =STE_CEA_01!E90 -> 38.837186 | T8: =STE_CEA_01!F90 -> 7.4784789 | U8: =(T8+S8)*C8 -> 637.76671 | W8: =SUM(U8:U10)-SUM(R8:R10) -> 590.67254 | X8: =W8*(44/12) -> 2165.7993 | Y8: =SUM(U5:U10)-SUM(R5:R10) -> 682.5819 | Z8: =W8/$Y$8 -> 0.86535042 | AA8: =Z8*$Z$4 -> 5247.1907 | AB8: =$AA$4*Z8 -> 1721.5088
A9: STE_CEA_02 | B9: Mixed species environmental planting - temperate | C9: ='CEA Attributes'!D5 -> 24.62 | D9: 0 | E9: 0 | F9: =(D9+E9)*C9 -> 0 | G9: ='Abatement - Report 1'!G8 -> 4.5082506 | H9: ='Abatement - Report 1'!H8 -> 0.17253132 | I9: ='Abatement - Report 1'!I8 -> 115.24085 | J9: 15.337401 | K9: 1.8790375 | L9: 423.86873 | M9: 23.310063 | N9: 3.3806721 | O9: 657.1259 | P9: 34.520037 | Q9: 6.2648943 | R9: 1004.125 | S9: =STE_CEA_02!E90 -> 38.935505 | T9: =STE_CEA_02!F90 -> 7.5147016 | U9: =(T9+S9)*C9 -> 1143.6041 | AB9: =SUM(AB5:AB8) -> 1989.3777
A10: STE_CEA_03 | B10: Mixed species environmental planting - temperate | C10: ='CEA Attributes'!E5 -> 66.16 | D10: 0 | E10: 0 | F10: =(D10+E10)*C10 -> 0 | G10: ='Abatement - Report 1'!G9 -> 4.4925867 | H10: ='Abatement - Report 1'!H9 -> 0.17205496 | I10: ='Abatement - Report 1'!I9 -> 308.61269 | J10: 15.28149 | K10: 1.8723688 | L10: 1134.8993 | M10: 23.224519 | N10: 3.3684945 | O10: 1759.3938 | P10: 34.39283 | Q10: 6.2420985 | R10: 2688.4069 | S10: =STE_CEA_03!E90 -> 38.791888 | T10: =STE_CEA_03!F90 -> 7.4872964 | U10: =(T10+S10)*C10 -> 3061.8308
E13: Initial carbon stock CN (tCO2e) | F13: =SUM(F5:F10)*44/12 -> 3.891384 | H13: End carbon stock CP (tCO2e) | I13: =SUM(I5:I10)*44/12 -> 1979.5785 | K13: End carbon stock CP (tCO2e) | L13: 7462.1223 | N13: End carbon stock CP (tCO2e) | O13: 11808.354 | Q13: End carbon stock CP (tCO2e) | R13: =SUM(R5:R10)*44/12 -> 17886.024 | T13: End carbon stock CP (tCO2e) | U13: =SUM(U5:U10)*44/12 -> 20388.824
E14: (Equation 11a) | H14: Equation 11b | K14: Equation 11b | N14: Equation 11b | Q14: Equation 11b | T14: Equation 11b
E16: Carbon stock change for project (tCO2-e) (5.8 (b)) | U16: =U13-F13 -> 20384.933
U21: =U13-R13 -> 2502.8003

Sheet Abatement - Report 4
A2: Division 5.4; Section 5.8(b)
F3: Equation 12a | G3: 2016 - Report 1 | I3: Equation 12b | J3: 2017 - Report 2 | L3: Equation 12b | M3: 2018 - Report 3 | O3: Equation 12b | P3: 2020 - Report 4 | R3: Equation 12b
A4: CEA Name | B4: FullCAM calibration used | C4: CEA area (ha) | D4: Initial carbon mass trees - CDt (t C /ha) | E4: Initial carbon mass debris - CDd (t C /ha) | F4: Initial carbon mass - CD (t C) | G4: End carbon mass trees - Ct (t C /ha) | H4: End carbon mass debris - Cd (t C /ha) | I4: End carbon mass - C (t C) | J4: End carbon mass trees - Ct (t C /ha) | K4: End carbon mass debris - Cd (t C /ha) | L4: End carbon mass - C (t C) | M4: End carbon mass trees - Ct (t C /ha) | N4: End carbon mass debris - Cd (t C /ha) | O4: End carbon mass - C (t C) | P4: End carbon mass trees - Ct (t C /ha) | Q4: End carbon mass debris - Cd (t C /ha) | R4: End carbon mass - C (t C) | W4: 6063.66 | X4: 4547
A5: JIN_CEA_01 | B5: Mixed species environmental planting - temperate | C5: ='CEA Attributes'!F5 -> 8.76 | D5: 0 | E5: 0 | F5: =(D5+E5)*C5 -> 0 | G5: ='Abatement - Report 1'!G4 -> 1.2359209 | H5: ='Abatement - Report 1'!H4 -> 0.071879623 | I5: ='Abatement - Report 1'!I4 -> 11.456333 | J5: 18.665416 | K5: 1.8858156 | L5: 180.02879 | M5: 36.533445 | N5: 4.3853774 | O5: 358.44889 | P5: =JIN_CEA_01!E79 -> 49.303557 | Q5: =JIN_CEA_01!F79 -> 8.5171658 | R5: =(Q5+P5)*C5 -> 506.50953 | T5: =R5-O5 -> 148.06064 | U5: =T5*(44/12) -> 542.88901 | W5: =T5/$V$8 -> 0.089325196 | X5: =W5*$W$4 -> 541.63762 | Y5: =$X$4*W5 -> 406.16167
A6: HID_CEA_01 | B6: Mixed species environmental planting - temperate | C6: ='CEA Attributes'!G5 -> 2.7 | D6: 0 | E6: 0 | F6: =(D6+E6)*C6 -> 0 | G6: ='Abatement - Report 1'!G5 -> 8.6244366 | H6: ='Abatement - Report 1'!H5 -> 1.1639746 | I6: ='Abatement - Report 1'!I5 -> 26.42871 | J6: 11.392651 | K6: 2.1026674 | L6: 36.43736 | M6: 15.008508 | N6: 2.815663 | O6: 48.12526 | P6: =HID_CEA_01!E117 -> 20.333943 | Q6: =HID_CEA_01!F117 -> 4.1384045 | R6: =(Q6+P6)*C6 -> 66.075338 | T6: =R6-O6 -> 17.950078 | U6: =T6*(44/12) -> 65.816953 | W6: =T6/$V$8 -> 0.010829308 | X6: =W6*$W$4 -> 65.665241 | Y6: =$X$4*W6 -> 49.240863
A7: LIS_CEA_01 | B7: Mixed species environmental planting - temperate | C7: ='CEA Attributes'!H5 -> 3.24 | D7: =LIS_CEA_01!E20 -> 0.29377931 | E7: =LIS_CEA_01!F20 -> 0.033778268 | F7: =(D7+E7)*C7 -> 1.0612866 | G7: ='Abatement - Report 1'!G6 -> 3.6519413 | H7: ='Abatement - Report 1'!H6 -> 0.64600861 | I7: ='Abatement - Report 1'!I6 -> 13.925358 | J7: 6.0646123 | K7: 1.1987738 | L7: 23.533371 | M7: 7.8642871 | N7: 1.6702547 | O7: 30.891915 | P7: =LIS_CEA_01!E134 -> 13.213963 | Q7: =LIS_CEA_01!F134 -> 3.1108819 | R7: =(Q7+P7)*C7 -> 52.892496 | T7: =R7-O7 -> 22.000581 | U7: =T7*(44/12) -> 80.668796 | W7: =T7/$V$8 -> 0.013272982 | X7: =W7*$W$4 -> 80.48285 | Y7: =$X$4*W7 -> 60.352249
A8: STE_CEA_01 | B8: Mixed species environmental planting - temperate | C8: ='CEA Attributes'!C5 -> 13.77 | D8: 0 | E8: 0 | F8: =(D8+E8)*C8 -> 0 | G8: ='Abatement - Report 1'!G7 -> 4.492529 | H8: ='Abatement - Report 1'!H7 -> 0.17131219 | I8: ='Abatement - Report 1'!I7 -> 64.221093 | J8: 15.2929 | K8: 1.8717138 | L8: 236.35674 | M8: 23.247 | N8: 3.3669807 | O8: 366.47451 | P8: =STE_CEA_01!E78 -> 34.431617 | Q8: =STE_CEA_01!F78 -> 6.2363016 | R8: =(Q8+P8)*C8 -> 559.99723 | T8: =SUM(R8:R10)-SUM(O8:O10) -> 1469.5349 | U8: =T8*(44/12) -> 5388.2946 | V8: =SUM(R5:R10)-SUM(O5:O10) -> 1657.5462 | W8: =T8/$V$8 -> 0.88657251 | X8: =W8*$W$4 -> 5375.8743 | Y8: =$X$4*W8 -> 4031.2452
A9: STE_CEA_02 | B9: Mixed species environmental planting - temperate | C9: ='CEA Attributes'!D5 -> 24.62 | D9: 0 | E9: 0 | F9: =(D9+E9)*C9 -> 0 | G9: ='Abatement - Report 1'!G8 -> 4.5082506 | H9: ='Abatement - Report 1'!H8 -> 0.17253132 | I9: ='Abatement - Report 1'!I8 -> 115.24085 | J9: 15.337401 | K9: 1.8790375 | L9: 423.86873 | M9: 23.310063 | N9: 3.3806721 | O9: 657.1259 | P9: =STE_CEA_02!E78 -> 34.520037 | Q9: =STE_CEA_02!F78 -> 6.2648943 | R9: =(Q9+P9)*C9 -> 1004.125
A10: STE_CEA_03 | B10: Mixed species environmental planting - temperate | C10: ='CEA Attributes'!E5 -> 66.16 | D10: 0 | E10: 0 | F10: =(D10+E10)*C10 -> 0 | G10: ='Abatement - Report 1'!G9 -> 4.4925867 | H10: ='Abatement - Report 1'!H9 -> 0.17205496 | I10: ='Abatement - Report 1'!I9 -> 308.61269 | J10: 15.28149 | K10: 1.8723688 | L10: 1134.8993 | M10: 23.224519 | N10: 3.3684945 | O10: 1759.3938 | P10: =STE_CEA_03!E78 -> 34.39283 | Q10: =STE_CEA_03!F78 -> 6.2420985 | R10: =(Q10+P10)*C10 -> 2688.4069
E13: Initial carbon stock CN (tCO2e) | F13: =SUM(F5:F10)*44/12 -> 3.891384 | H13: End carbon stock CP (tCO2e) | I13: =SUM(I5:I10)*44/12 -> 1979.5785 | K13: End carbon stock CP (tCO2e) | L13: 7462.1223 | N13: End carbon stock CP (tCO2e) | O13: 11808.354 | Q13: End carbon stock CP (tCO2e) | R13: =SUM(R5:R10)*44/12 -> 17886.024
E14: (Equation 11a) | H14: Equation 11b | K14: Equation 11b | N14: Equation 11b | Q14: Equation 11b
E16: Carbon stock change for project (tCO2-e) (5.8 (b)) | R16: =R13-F13 -> 17882.132

Sheet Abatement - Report 3
A2: Division 5.4; Section 5.8(b)
F3: Equation 12a | G3: 2016 - Report 1 | I3: Equation 12b | J3: 2017 - Report 2 | L3: Equation 12b | M3: 2018 - Report 3 | O3: Equation 12b
A4: CEA Name | B4: FullCAM calibration used | C4: CEA area (ha) | D4: Initial carbon mass trees - CDt (t C /ha) | E4: Initial carbon mass debris - CDd (t C /ha) | F4: Initial carbon mass - CD (t C) | G4: End carbon mass trees - Ct (t C /ha) | H4: End carbon mass debris - Cd (t C /ha) | I4: End carbon mass - C (t C) | J4: End carbon mass trees - Ct (t C /ha) | K4: End carbon mass debris - Cd (t C /ha) | L4: End carbon mass - C (t C) | M4: End carbon mass trees - Ct (t C /ha) | N4: End carbon mass debris - Cd (t C /ha) | O4: End carbon mass - C (t C)
A5: JIN_CEA_01 | B5: Mixed species environmental planting - temperate | C5: 8.76 | D5: 0 | E5: 0 | F5: 0 | G5: 1.2359209 | H5: 0.071879623 | I5: 11.456333 | J5: 18.665416 | K5: 1.8858156 | L5: 180.02879 | M5: 36.533445 | N5: 4.3853774 | O5: 358.44889
A6: HID_CEA_01 | B6: Mixed species environmental planting - temperate | C6: 2.7 | D6: 0 | E6: 0 | F6: 0 | G6: 8.6244366 | H6: 1.1639746 | I6: 26.42871 | J6: 11.392651 | K6: 2.1026674 | L6: 36.43736 | M6: 15.008508 | N6: 2.815663 | O6: 48.12526
A7: LIS_CEA_01 | B7: Mixed species environmental planting - temperate | C7: 3.24 | D7: 0.29377931 | E7: 0.033778268 | F7: 1.0612866 | G7: 3.6519413 | H7: 0.64600861 | I7: 13.925358 | J7: 6.0646123 | K7: 1.1987738 | L7: 23.533371 | M7: 7.8642871 | N7: 1.6702547 | O7: 30.891915
A8: STE_CEA_01 | B8: Mixed species environmental planting - temperate | C8: 13.77 | D8: 0 | E8: 0 | F8: 0 | G8: 4.492529 | H8: 0.17131219 | I8: 64.221093 | J8: 15.2929 | K8: 1.8717138 | L8: 236.35674 | M8: 23.247 | N8: 3.3669807 | O8: 366.47451
A9: STE_CEA_02 | B9: Mixed species environmental planting - temperate | C9: 24.62 | D9: 0 | E9: 0 | F9: 0 | G9: 4.5082506 | H9: 0.17253132 | I9: 115.24085 | J9: 15.337401 | K9: 1.8790375 | L9: 423.86873 | M9: 23.310063 | N9: 3.3806721 | O9: 657.1259
A10: STE_CEA_03 | B10: Mixed species environmental planting - temperate | C10: 66.16 | D10: 0 | E10: 0 | F10: 0 | G10: 4.4925867 | H10: 0.17205496 | I10: 308.61269 | J10: 15.28149 | K10: 1.8723688 | L10: 1134.8993 | M10: 23.224519 | N10: 3.3684945 | O10: 1759.3938
E13: Initial carbon stock CN (tCO2e) | F13: 3.891384 | H13: End carbon stock CP (tCO2e) | I13: 1979.5785 | K13: End carbon stock CP (tCO2e) | L13: 7462.1223 | N13: End carbon stock CP (tCO2e) | O13: 11808.354
E14: (Equation 11a) | H14: Equation 11b | K14: Equation 11b | N14: Equation 11b
E16: Carbon stock change for project (tCO2-e) (5.8 (b)) | O16: 11804.463

Sheet Abatement - Report 2
A1: Division 5.4; Section 5.8(b)
F2: Equation 12a | G2: 2016 - Report 1 | I2: Equation 12b | J2: 2017 - Report 2 | L2: Equation 12b
A3: CEA Name | B3: FullCAM calibration used | C3: CEA area (ha) | D3: Initial carbon mass trees - CDt (t C /ha) | E3: Initial carbon mass debris - CDd (t C /ha) | F3: Initial carbon mass - CD (t C) | G3: End carbon mass trees - Ct (t C /ha) | H3: End carbon mass debris - Cd (t C /ha) | I3: End carbon mass - C (t C) | J3: End carbon mass trees - Ct (t C /ha) | K3: End carbon mass debris - Cd (t C /ha) | L3: End carbon mass - C (t C)
A4: JIN_CEA_01 | B4: Mixed species environmental planting - temperate | C4: 8.76 | D4: 0 | E4: 0 | F4: 0 | G4: 1.2359209 | H4: 0.071879623 | I4: 11.456333 | J4: 18.665416 | K4: 1.8858156 | L4: 180.02879
A5: HID_CEA_01 | B5: Mixed species environmental planting - temperate | C5: 2.7 | D5: 0 | E5: 0 | F5: 0 | G5: 8.6244366 | H5: 1.1639746 | I5: 26.42871 | J5: 11.392651 | K5: 2.1026674 | L5: 36.43736
A6: LIS_CEA_01 | B6: Mixed species environmental planting - temperate | C6: 3.24 | D6: 0.29377931 | E6: 0.033778268 | F6: 1.0612866 | G6: 3.6519413 | H6: 0.64600861 | I6: 13.925358 | J6: 6.0646123 | K6: 1.1987738 | L6: 23.533371
A7: STE_CEA_01 | B7: Mixed species environmental planting - temperate | C7: 13.77 | D7: 0 | E7: 0 | F7: 0 | G7: 4.492529 | H7: 0.17131219 | I7: 64.221093 | J7: 15.2929 | K7: 1.8717138 | L7: 236.35674
A8: STE_CEA_02 | B8: Mixed species environmental planting - temperate | C8: 24.62 | D8: 0 | E8: 0 | F8: 0 | G8: 4.5082506 | H8: 0.17253132 | I8: 115.24085 | J8: 15.337401 | K8: 1.8790375 | L8: 423.86873
A9: STE_CEA_03 | B9: Mixed species environmental planting - temperate | C9: 66.16 | D9: 0 | E9: 0 | F9: 0 | G9: 4.4925867 | H9: 0.17205496 | I9: 308.61269 | J9: 15.28149 | K9: 1.8723688 | L9: 1134.8993
E12: Initial carbon stock CN (tCO2e) | F12: 3.891384 | H12: End carbon stock CP (tCO2e) | I12: 1979.5785 | K12: End carbon stock CP (tCO2e) | L12: 7462.1223
E13: (Equation 11a) | H13: Equation 11b | K13: Equation 11b
E15: Carbon stock change for project (tCO2-e) (5.8 (b)) | L15: 7458.2309

Sheet Abatement - Report 1
A1: Division 5.4; Section 5.8(b)
F2: Equation 12a | I2: Equation 12b
A3: CEA Name | B3: FullCAM calibration used | C3: CEA area (ha) | D3: Initial carbon mass trees - CDt (t C /ha) | E3: Initial carbon mass debris - CDd (t C /ha) | F3: Initial carbon mass - CD (t C) | G3: End carbon mass trees - Ct (t C /ha) | H3: End carbon mass debris - Cd (t C /ha) | I3: End carbon mass - C (t C)
A4: JIN_CEA_01 | B4: Mixed species environmental planting - temperate | C4: 8.76 | D4: 0 | E4: 0 | F4: 0 | G4: 1.2359209 | H4: 0.071879623 | I4: 11.456333
A5: HID_CEA_01 | B5: Mixed species environmental planting - temperate | C5: 2.7 | D5: 0 | E5: 0 | F5: 0 | G5: 8.6244366 | H5: 1.1639746 | I5: 26.42871 | J5: 1.0612866
A6: LIS_CEA_01 | B6: Mixed species environmental planting - temperate | C6: 3.24 | D6: 0.29377931 | E6: 0.033778268 | F6: 1.0612866 | G6: 3.6519413 | H6: 0.64600861 | I6: 13.925358 | J6: 539.88504
A7: STE_CEA_01 | B7: Mixed species environmental planting - temperate | C7: 13.77 | D7: 0 | E7: 0 | F7: 0 | G7: 4.492529 | H7: 0.17131219 | I7: 64.221093 | J7: 538.82375
A8: STE_CEA_02 | B8: Mixed species environmental planting - temperate | C8: 24.62 | D8: 0 | E8: 0 | F8: 0 | G8: 4.5082506 | H8: 0.17253132 | I8: 115.24085
A9: STE_CEA_03 | B9: Mixed species environmental planting - temperate | C9: 66.16 | D9: 0 | E9: 0 | F9: 0 | G9: 4.4925867 | H9: 0.17205496 | I9: 308.61269
E12: Initial carbon stock CN (tCO2e) | F12: 3.891384 | H12: End carbon stock CP (tCO2e) | I12: 1979.5785
E13: (Equation 11a) | H13: Equation 11b
E15: Carbon stock change for project (tCO2-e) (5.8 (b)) | I15: 1975.6871

Sheet Project Emissions
A2: Division 5.4; Section 5.8(c)
A4: CEA Name | B4: FullCAM calibration used | C4: CEA area (ha) | D4: CH4 Emissions - ECH4 (t CH4/ha) | E4: CH4 Emissions - EBCH4 (t CH4) | F4: N2O Emissions - EN2O (t N2O/ha) | G4: N2O Emissions - EBN2O (t N2O)
A5: JIN_CEA_01 | B5: Mixed species environmental planting - temperate | C5: ='CEA Attributes'!F5 -> 8.76 | D5: =JIN_CEA_01!G25 -> 0 | E5: =D5*C5 -> 0 | F5: =JIN_CEA_01!H25 -> 0 | G5: =F5*C5 -> 0
A6: HID_CEA_01 | B6: Mixed species environmental planting - temperate | C6: ='CEA Attributes'!G5 -> 2.7 | D6: =HID_CEA_01!G124 -> 0.021069868 | E6: =D6*C6 -> 0.056888643 | F6: =HID_CEA_01!H124 -> 0.00038949992 | G6: =F6*C6 -> 0.0010516498
A7: LIS_CEA_01 | B7: Mixed species environmental planting - temperate | C7: ='CEA Attributes'!H5 -> 3.24 | D7: =LIS_CEA_01!G80 -> 0 | E7: =D7*C7 -> 0 | F7: =LIS_CEA_01!H80 -> 0 | G7: =F7*C7 -> 0
A8: STE_CEA_01 | B8: Mixed species environmental planting - temperate | C8: ='CEA Attributes'!C5 -> 13.77 | D8: =STE_CEA_01!G21 -> 0 | E8: =D8*C8 -> 0 | F8: =STE_CEA_01!H21 -> 0 | G8: =F8*C8 -> 0
A9: STE_CEA_02 | B9: Mixed species environmental planting - temperate | C9: ='CEA Attributes'!D5 -> 24.62 | D9: =STE_CEA_02!G24 -> 0 | E9: =D9*C9 -> 0 | F9: =STE_CEA_02!H24 -> 0 | G9: =F9*C9 -> 0
A10: STE_CEA_03 | B10: Mixed species environmental planting - temperate | C10: ='CEA Attributes'!E5 -> 66.16 | D10: =STE_CEA_03!G24 -> 0 | E10: =D10*C10 -> 0 | F10: =STE_CEA_03!H24 -> 0 | G10: =F10*C10 -> 0
D13: Gl Warm Pot CH4 | E13: 28 | F13: Gl Warm Pot NO2 | G13: 265 | I13: AR5 GPW 2020-21 onwards
D15: Equation 13 | E15: =SUM(E5:E11)*E13 -> 1.592882 | F15: Equation 14 | G15: =SUM(G5:G11)*G13/1000 -> 0.00027868719
F17: Equation 15 | G17: =G15+E15 -> 1.5931607

Sheet Global Warm Pot

Sheet Fuel Emissions
A2: Division 5.4; Section 5.8(d)
B4: Diesel use - for each hectare assume:
B5: Slashing frequency (events/year) | D5: 2
B6: Power rating of t (hp/kW) | D6: 90 / 67
B7: Fuel consumption (l/hr) | D7: 15
B8: Productivity (hrs/ha) | D8: 0.5
B9: Project area (ha) | D9: =SUM('CEA Attributes'!C5:H5) -> 119.25
B10: Reporting period (years) | D10: 1
B12: Petrol use - For each property, assume:
B13: Site visit frequency (visits/yr) | D13: 4
B14: Travel distance/site visit (km) | D14: 200
B15: Fuel consumption of (l/km) | D15: 10
B16: Fuel consumption/site visit (litres) | D16: =D14/D15 -> 20
B17: Reporting period (years) | D17: 1
B19: Qf - Total diesel (kL) | D19: =D9*D8*D7*D5*D10/1000 -> 1.78875
B20: Qf - Total gasoline (kL) | D20: =(D16*D13*D17)/1000 -> 0.08
B22: Fuel emission for each fuel type and greenhouse gas for the project - Equation 16
C24: Fuel emissions (t CO2e)
C25: CO2 | D25: CH4 | E25: N2O | F25: Total CO2e
B26: Ef,diesel | C26: =$D$19*$C$40*D40/1000 -> 4.8262979 | D26: =$D$19*$C$40*E40/1000 -> 0.006904575 | E26: =$D$19*$C$40*F40/1000 -> 0.034522875 | F26: =SUM(C26:E26) -> 4.8677254
B27: Ef,gasoline | C27: =$D$20*$C$39*D39/1000 -> 0.1844064 | D27: =$D$20*$C$39*E39/1000 -> 0.001368 | E27: =$D$20*$C$39*F39/1000 -> 0.0049248 | F27: =SUM(C27:E27) -> 0.1906992
B29: Total project fuel emissions for the reporting period - Equation 17
B30: Ef - Total project fuel emssions for the reporting period= | E30: =F26+F27 -> 5.0584246 | F30: tonnes of CO2e
B31: Previous report | E31: 25.295274 | F31: tonnes of CO2e
B32: Total project fuel emssions= | E32: =E31+E30 -> 30.353698 | F32: tonnes of CO2e
A34: Fuel combustion—fuels for transport energy purposes
A35: Item | B35: Fuel combusted | C35: Energy content factor | D35: Emission factor
C36: (GJ/kL unless otherwise indicated) | D36: kg CO2‑e/GJ
D37: (relevant oxidation factors incorporated)
D38: CO2 | E38: CH4 | F38: N2O
A39: 35 | B39: Gasoline (other than for use as fuel in an aircraft) | C39: 34.2 | D39: 67.4 | E39: 0.5 | F39: 1.8
A40: 40 | B40: Diesel oil | C40: 38.6 | D40: 69.9 | E40: 0.1 | F40: 0.5
A43: Proportion of fuel emmissions by CEA
A44: CEA Name | B44: FullCAM calibration used | C44: CEA area (ha) | D44: Proportion of Fuel emissions
A45: ='Abatement - Report 3'!A5 -> JIN_CEA_01 | B45: ='Abatement - Report 3'!B5 -> Mixed species environmental planting - temperate | C45: ='Abatement - Report 3'!C5 -> 8.76 | D45: =C45/$C$51*$E$30 -> 0.37158742
A46: ='Abatement - Report 3'!A6 -> HID_CEA_01 | B46: ='Abatement - Report 3'!B6 -> Mixed species environmental planting - temperate | C46: ='Abatement - Report 3'!C6 -> 2.7 | D46: =C46/$C$51*$E$30 -> 0.11453037
A47: ='Abatement - Report 3'!A7 -> LIS_CEA_01 | B47: ='Abatement - Report 3'!B7 -> Mixed species environmental planting - temperate | C47: ='Abatement - Report 3'!C7 -> 3.24 | D47: =C47/$C$51*$E$30 -> 0.13743644
A48: ='Abatement - Report 3'!A8 -> STE_CEA_01 | B48: ='Abatement - Report 3'!B8 -> Mixed species environmental planting - temperate | C48: ='Abatement - Report 3'!C8 -> 13.77 | D48: =C48/$C$51*$E$30 -> 0.58410488
A49: ='Abatement - Report 3'!A9 -> STE_CEA_02 | B49: ='Abatement - Report 3'!B9 -> Mixed species environmental planting - temperate | C49: ='Abatement - Report 3'!C9 -> 24.62 | D49: =C49/$C$51*$E$30 -> 1.0443473
A50: ='Abatement - Report 3'!A10 -> STE_CEA_03 | B50: ='Abatement - Report 3'!B10 -> Mixed species environmental planting - temperate | C50: ='Abatement - Report 3'!C10 -> 66.16 | D50: =C50/$C$51*$E$30 -> 2.8064182
...

Sheet JIN_CEA_01
A8: Year | B8: Month | C8: Day | D8: Dec. Year | E8: C mass of trees | F8: C mass of forest debris | G8: CH4 emitted due to fire | H8: N2O emitted due to fire | I8: C mass of trees+debris
E9: tC/ha | F9: tC/ha | G9: tCH4/ha | H9: tN2O/ha | I9: tC/ha
A10: 2015 | B10: 3 | C10: 31 | D10: 2015.247 | E10: 0 | F10: 0 | I10: =E10+F10 -> 0
A11: 2015 | B11: 4 | C11: 30 | D11: 2015.329 | E11: 0.2937 | F11: 0.0036657659 | G11: 0 | H11: 0 | I11: =E11+F11 -> 0.29736577
A12: 2015 | B12: 5 | C12: 31 | D12: 2015.414 | E12: 0.2937 | F12: 0.007304537 | G12: 0 | H12: 0 | I12: =E12+F12 -> 0.30100454
A13: 2015 | B13: 6 | C13: 30 | D13: 2015.496 | E13: 0.2937 | F13: 0.010782673 | G13: 0 | H13: 0 | I13: =E13+F13 -> 0.30448267
A14: 2015 | B14: 7 | C14: 31 | D14: 2015.581 | E14: 0.29370136 | F14: 0.014289593 | G14: 0 | H14: 0 | I14: =E14+F14 -> 0.30799096
A15: 2015 | B15: 8 | C15: 31 | D15: 2015.666 | E15: 0.29371508 | F15: 0.017777164 | G15: 0 | H15: 0 | I15: =E15+F15 -> 0.31149224
A16: 2015 | B16: 9 | C16: 30 | D16: 2015.748 | E16: 0.29378091 | F16: 0.021049401 | G16: 0 | H16: 0 | I16: =E16+F16 -> 0.31483031
A17: 2015 | B17: 10 | C17: 31 | D17: 2015.833 | E17: 0.29402844 | F17: 0.02418459 | G17: 0 | H17: 0 | I17: =E17+F17 -> 0.31821303
A18: 2015 | B18: 11 | C18: 30 | D18: 2015.915 | E18: 0.29562508 | F18: 0.027181298 | G18: 0 | H18: 0 | I18: =E18+F18 -> 0.32280638
A19: 2015 | B19: 12 | C19: 31 | D19: 2016 | E19: 0.30159133 | F19: 0.030246214 | G19: 0 | H19: 0 | I19: =E19+F19 -> 0.33183754
A20: 2016 | B20: 1 | C20: 31 | D20: 2016.085 | E20: 0.32685638 | F20: 0.033460151 | G20: 0 | H20: 0 | I20: =E20+F20 -> 0.36031653
A21: 2016 | B21: 2 | C21: 29 | D21: 2016.164 | E21: 0.38228506 | F21: 0.036944396 | G21: 0 | H21: 0 | I21: =E21+F21 -> 0.41922945
A22: 2016 | B22: 3 | C22: 31 | D22: 2016.249 | E22: 0.5034081 | F22: 0.041875087 | G22: 0 | H22: 0 | I22: =E22+F22 -> 0.54528319
... A25: 2016 | B25: 6 | C25: 30 | D25: 2016.497 | E25: 1.2288266 | F25: 0.0716869 | G25: 0 | H25: 0 | I25: =E25+F25 -> 1.3005135
A26: 2016 | B26: 7 | C26: 31 | D26: 2016.582 | E26: 1.6472107 | F26: 0.089921673 | G26: 0 | H26: 0 | I26: =E26+F26 -> 1.7371324 | K26: Year | L26: Month | M26: Trees+Debris | N26: Area | O26: Abatement (t C) | P26: Aabtement (tCO2) | Q26: Fuel Emissions tCO2e | R26: Net Abatement (tCO2e)
A27: 2016 | B27: 8 | C27: 31 | D27: 2016.667 | E27: 2.1669269 | F27: 0.11440377 | G27: 0 | H27: 0 | I27: =E27+F27 -> 2.2813307 | K27: 2016 | L27: 6 | M27: =I25 -> 1.3005135 | N27: ='Abatement - Report 3'!$C$5 -> 8.76 | O27: =M27*N27 -> 11.392498 | P27: =O27*44/12 -> 41.772492 | Q27: ='Fuel Emissions'!$D$45 -> 0.37158742 | R27: =P27-Q27 -> 41.400905
A28: 2016 | B28: 9 | C28: 30 | D28: 2016.749 | E28: 2.7514866 | F28: 0.14434746 | G28: 0 | H28: 0 | I28: =E28+F28 -> 2.8958341 | K28: 2017 | L28: 6 | M28: =I37 -> 10.660079 | N28: ='Abatement - Report 3'!$C$5 -> 8.76 | O28: =M28*N28 -> 93.382288 | P28: =O28*44/12 -> 342.40172 | Q28: ='Fuel Emissions'!$D$45 -> 0.37158742 | R28: =P28-Q28 -> 342.03013
A29: 2016 | B29: 10 | C29: 31 | D29: 2016.833 | E29: 3.686439 | F29: 0.18260337 | G29: 0 | H29: 0 | I29: =E29+F29 -> 3.8690424 | K29: 2018 | L29: 6 | M29: =I49 -> 26.171159 | N29: ='Abatement - Report 3'!$C$5 -> 8.76 | O29: =M29*N29 -> 229.25936 | P29: =O29*44/12 -> 840.61764 | Q29: ='Fuel Emissions'!$D$45 -> 0.37158742 | R29: =P29-Q29 -> 840.24606
A30: 2016 | B30: 11 | C30: 30 | D30: 2016.915 | E30: 4.4770455 | F30: 0.22873004 | G30: 0 | H30: 0 | I30: =E30+F30 -> 4.7057756 | K30: 2019 | L30: 6 | M30: =I61 -> 41.759178 | N30: ='Abatement - Report 3'!$C$5 -> 8.76 | O30: =M30*N30 -> 365.8104 | P30: =O30*44/12 -> 1341.3048 | Q30: ='Fuel Emissions'!$D$45 -> 0.37158742 | R30: =P30-Q30 -> 1340.9332
A31: 2016 | B31: 12 | C31: 31 | D31: 2017 | E31: 5.3800081 | F31: 0.28510708 | G31: 0 | H31: 0 | I31: =E31+F31 -> 5.6651152 | K31: 2020 | L31: 6 | M31: =I73 -> 51.45661 | N31: ='Abatement - Report 3'!$C$5 -> 8.76 | O31: =M31*N31 -> 450.75991 | P31: =O31*44/12 -> 1652.7863 | Q31: ='Fuel Emissions'!$D$45 -> 0.37158742 | R31: =P31-Q31 -> 1652.4147
A32: 2017 | B32: 1 | C32: 31 | D32: 2017.085 | E32: 6.0147486 | F32: 0.34862028 | G32: 0 | H32: 0 | I32: =E32+F32 -> 6.3633689 | K32: 2021 | L32: 6 | M32: =I85 -> 63.330381 | N32: ='Abatement - Report 3'!$C$5 -> 8.76 | O32: =M32*N32 -> 554.77414 | P32: =O32*44/12 -> 2034.1718 | Q32: ='Fuel Emissions'!$D$45 -> 0.37158742 | R32: =P32-Q32 -> 2033.8002
A33: 2017 | B33: 2 | C33: 28 | D33: 2017.162 | E33: 6.6180653 | F33: 0.41044248 | G33: 0 | H33: 0 | I33: =E33+F33 -> 7.0285077 | K33: 2022 | L33: 6 | M33: =I97 -> 69.962008 | N33: ='Abatement - Report 3'!$C$5 -> 8.76 | O33: =M33*N33 -> 612.86719 | P33: =O33*44/12 -> 2247.1797 | Q33: ='Fuel Emissions'!$D$45 -> 0.37158742 | R33: =P33-Q33 -> 2246.8081
A34: 2017 | B34: 3 | C34: 31 | D34: 2017.247 | E34: 7.3175237 | F34: 0.48414448 | G34: 0 | H34: 0 | I34: =E34+F34 -> 7.8016682 | K34: 2023 | L34: 6 | M34: =I109 -> 76.054761 | N34: ='Abatement - Report 3'!$C$5 -> 8.76 | O34: =M34*N34 -> 666.2397 | P34: =O34*44/12 -> 2442.8789 | Q34: ='Fuel Emissions'!$D$45 -> 0.37158742 | R34: =P34-Q34 -> 2442.5073
A35: 2017 | B35: 4 | C35: 30 | D35: 2017.329 | E35: 8.0241923 | F35: 0.56124096 | G35: 0 | H35: 0 | I35: =E35+F35 -> 8.5854333 | K35: 2024 | L35: 6 | M35: =I121 -> 83.723213 | N35: ='Abatement - Report 3'!$C$5 -> 8.76 | O35: =M35*N35 -> 733.41534 | P35: =O35*44/12 -> 2689.1896 | Q35: ='Fuel Emissions'!$D$45 -> 0.37158742 | R35: =P35-Q35 -> 2688.818
