Workbook

Sheet Cover
A11: Emissions Reduction Fund Offsets Report
A12: Blackwood Biodiversity and Carbon Project
A14: Item | B14: Project details
A15: Project Name | B15: Devon Park Biodiversity and Carbon Project
A16: Registration number | B16: ERF Project ID 173013
A17: Participant | B17: Dunkeld Pastoral Pty Ltd
A18: Agent | B18: Corporate Carbon Advisory Pty Ltd
A19: Commencement date | B19: 44685
A20: Reporting period Start | B20: 45688
A21: Reporting period End | B21: 45961
A22: Report number | B22: Report 3
A25: Code | B25: Section
B26: Cover
B27: CEA Attributes
B28: Net Abatement
B29: EORP Carbon Stock
B30: Project Emmissions
B31: Global Warming Potential
B32: Fuel Emmissions
B33: DP_CEA01
B34: DP_CEA02
B35: DP_CEA03
B36: DP_CEA04

Sheet CEA Attributes
A1: Method Ref | B1: CEA identification number | C1: DP_CEA_01 | D1: DP_CEA_02 | E1: DP_CEA_03 | F1: DP_CEA_04
B2: Landholder / Property | C2: Dunkeld / Devon Park | D2: Dunkeld / Devon Park | E2: Dunkeld / Devon Park | F2: Dunkeld / Devon Park
B3: Date finished planting | C3: 45155 | D3: 44772 | E3: 44772 | F3: 45884
B4: Modelling Start Date | C4: 45155 | D4: 44772 | E4: 44772 | F4: 45884
B5: CEA area (ha) | C5: 11.085 | D5: 2.507 | E5: 3.688 | F5: 14.068
B6: Exclusion area (ha)
B7: Principal evidence of planting history | C7: Mgt Records | D7: Mgt Records | E7: Mgt Records | F7: Mgt Records
B8: Permanent planting type | C8: MSEP-Generic | D8: MSEP-Generic | E8: MSEP-Generic | F8: MSEP-Generic
A9: 1.4 | B9: Permanent planting established on or after 1 July 2007? | C9: Yes - see plant date | D9: Yes - see plant date | E9: Yes - see plant date | F9: Yes - see plant date
A10: 2.3 (3) | B10: Did not contain woody biomass that needed to be cleared prior to the planting going ahead (other than known weed species required by law to be cleared) | C10: No - refer mgt records | D10: No - refer mgt records | E10: No - refer mgt records | F10: No - refer mgt records
B11: Land clear at 1989? | C11: Yes | D11: Yes | E11: Yes | F11: Yes
B12: Planting required by law? | C12: No | D12: No | E12: No | F12: No
A13: 2.3 (4) | B13: Clear of forest cover for 5 years before planting | C13: Yes | D13: Yes | E13: Yes | F13: Yes
A14: 2.3 (5) | B14: Project trees have the potential to attain forest cover? | C14: Yes | D14: Yes | E14: Yes | F14: Yes
B15: Species planted | C15: Acacia acinacea, Acacia implexa, Acacia mearnsii, Acacia melanoxylon, Acacia paradoxa, Acacia pycnantha, Acacia verticillata, Allocasuarina verticillata, Banksia marginata, Bursaria spinosa, Callistemon rugulosus, Dodonaea sp., Eucalyptus camaldulensis, Eucalyptus ovata, Leptospermum continentale, Leptospermum lanigerum, Melaleuca ericifolia, Melaleuca squarrosa, and Ozothamnus ferrugineus. | D15: Acacia exudens, Acacia implexa, Acacia mearnsii, Acacia melanoxylon, Acacia retinodes, Acacia paradoxa, Acacia pycnantha, Acacia verticillata, Allocasuarina verticillata, Bursaria spinosa, Callistemon citrinus, Callistemon rugulosus, Dodonaea viscosa cuneata, Eucalyptus camaldulensis, Eucalyptus ovata, Leptospermum continentale, Leptospermum lanigerum, Melaleuca ericifolia, Melaleuca squarrosa, and Ozothamnus ferrugineus. | E15: Acacia exudens, Acacia implexa, Acacia mearnsii, Acacia melanoxylon, Acacia retinodes, Acacia paradoxa, Acacia pycnantha, Acacia verticillata, Allocasuarina verticillata, Bursaria spinosa, Callistemon citrinus, Callistemon rugulosus, Dodonaea viscosa cuneata, Eucalyptus camaldulensis, Eucalyptus ovata, Leptospermum continentale, Leptospermum lanigerum, Melaleuca ericifolia, Melaleuca squarrosa, and Ozothamnus ferrugineus. | F15: Eucalyptus camaldulensis, Eucalyptus ovata, Acacia melanoxylon, Acacia mearnsii, Acacia implexa, Acacia pycnantha, Acacia paradoxa, Acacia acinacea, Allocasuarina verticillata, Banksia marginata, Melaleuca ericifolia, Melaleuca squarrosa, Leptospermum lanigerum, Leptospermum continentale, Callistemon rugulosus, Dodonaea viscosa cuneata, Bursaria spinosa, and Ozothamnus ferrugineu
B16: NVIS Major Vegetation Subgroups Pre-Clear - (MVS) | C16: MVS 36 and 48 | D16: MVS 48 | E16: MVS 48 | F16: MVS 9, 36 and 48
B17: Soil type (Australia Soil Atlas) | C17: Rudosols - Ra1 | D17: Rudosols - Ra1 | E17: Rudosols - Ra1 | F17: Rudosols - Ra2
B18: Aspect | C18: Grazing - Varied | D18: Grazing - Varied | E18: Grazing - Varied | F18: Grazing - Varied
B19: Slope position | C19: Mid-lower | D19: Mid-lower | E19: Mid-lower | F19: Mid-lower
B20: Land management regime | C20: Biodiversity | D20: Biodiversity | E20: Biodiversity | F20: Biodiversity
B21: What are some key aspects which makes this a separate CEA to others? | C21: Planting dates | D21: Planting dates | E21: Planting dates | F21: Planting dates
B22: Planting type | C22: Mixed spp. | D22: Mixed spp. | E22: Mixed spp. | F22: Mixed spp.
B23: Planting geometry | C23: Block | D23: Block | E23: Block | F23: Block
B24: Planting spacing (rows, m) | C24: 4 | D24: 4 | E24: 4 | F24: 3
B25: Tree spacing (m) | C25: 2.5 | D25: 4 | E25: 4 | F25: 4
B26: Stocking density (assumed for modelling) | C26: <500 | D26: <500 | E26: <500 | F26: <500
B27: Tree proportion (assumed for modelling) | C27: <75% | D27: <75% | E27: <75% | F27: <75%
B28: Subject to competition from adjacent trees? | C28: Yes | D28: Yes | E28: Yes | F28: Yes
B29: CEA boundary distance from stems of outermost plants | C29: 0m | D29: 0m | E29: 0m | F29: 0m
B30: Planting Start Date | C30: 45139 | D30: 45108 | E30: 45108 | F30: 45880
B31: Planting Finish Date | C31: 45155 | D31: 45137 | E31: 45137 | F31: 45884
A32: 3.18 | B32: Average number of propagated seedling stock per ha | C32: 1043 | D32: 641 | E32: 641 | F32: 833
A33: 3.18 | B33: Tree proportion of trees to shrubs at planting | C33: 0.75 | D33: 0.75 | E33: 0.75 | F33: 0.75
A34: 3.3 (2) (c) | B34: Operations history | C34: Yes | D34: Yes | E34: Yes | F34: Yes
A35: 3.45, 3.48 | B35: Has harvesting or thinning occurred? | C35: No | D35: No | E35: No | F35: No
A36: 3.47 | B36: Has grazing affected forest cover? | C36: No | D36: No | E36: No | F36: No
A37: 3.49 | B37: Use of lime or fertilizer | C37: No | D37: No | E37: No | F37: No
B38: Disturbance events including fire | C38: No | D38: No | E38: No | F38: No
B39: Survival | C39: 0.714 | D39: 0.856 | E39: 0.856 | F39: Plantings still in establisment phase
B40: Simple calculation of future crown cover assuming radius of 2m and 30% mortality since establishment | C40: =(PI()*2^2*C32*C39)/10000 -> 0.93582013 | D40: =(PI()*2^2*D32*D39)/10000 -> 0.68951173 | E40: =(PI()*2^2*E32*E39)/10000 -> 0.68951173 | F40: Plantings still in establisment phase
...

Sheet Net Abatement
A2: Division 4.5, Section 4.15
A3: Symbol | B3: Element | C3: CO2-e (t)
A4: Carbon Stock (End-of-Period) | B4: Carbon stock for the project (in tonnes CO2-e) +C12B4:B12B4:B10B4:B11B4:B12B5BB4:C13 | C4: ='EORP Carbon Stock'!I11 -> 299.89398
A5: Burning Emissions | B5: Total project emissions from biomass burning for the project (in tonnes of CO2-2) | C5: ='Project Emissions'!G15 -> 0
A6: Fuel Emissions | B6: Total project fuel emissions for the project (in tonnes CO2-e) | C6: ='Fuel Emissions'!K26 -> 0.37297382
A7: Carbon Stock (Start-of-Period) | B7: Initial carbon stock for the project area (in tonnes CO2-e) | C7: ='EORP Carbon Stock'!F11 -> 0
A8: Carbon Stock (Previous Reporting Period) | B8: Carbon stock for the project area at the end of the previous reporting period (in tonnes CO2-e) | C8: 8.996087
A10: Net Abatement | B10: Project net abatement for the reporting period (in tonnes CO2-e) | C10: =C4-C5-C6-C7-C8 -> 290.52492
A13: Issued ACCUs (after CER buffer) | B13: Calculated ACCU after buffers (risk of reversal =5%; permanence period = 20%, total = 25% ) | C13: =(1-0.25)*C10 -> 217.89369

Sheet Property Summary
B2: Abatement to 30 June 2023
B3: Property | C3: CEA | D3: Area (ha) | E3: Abatement (tC) | F3: Abatement (tCO2e) | G3: Project CH4 emissions (tCO2e) | H3: Project N2O emissions (tCO2e) | I3: Fuel Emissions tCO2e | J3: Net abatement (tCO2e) | K3: Age (yrs)
B4: Blackwood | C4: CEA-01 | D4: ='CEA Attributes'!C5 -> 11.085 | E4: ='EORP Carbon Stock'!I5 -> 33.608771 | F4: =E4*44/12 -> 123.23216 | G4: 0 | H4: 0 | I4: ='Fuel Emissions'!D41 -> 1.1622614 | J4: =F4-G4-H4-I4 -> 122.0699 | K4: =#REF!-#REF! -> #REF!
B5: Blackwood | C5: CEA-02 | D5: ='CEA Attributes'!#REF! -> #REF! | E5: ='EORP Carbon Stock'!#REF! -> #REF! | F5: =E5*44/12 -> #REF! | G5: ='Project Emissions'!#REF!*'Project Emissions'!$E$11 -> #REF! | H5: ='Project Emissions'!#REF!*'Project Emissions'!$G$11 -> #REF! | I5: ='Fuel Emissions'!#REF! -> #REF! | J5: =F5-G5-H5-I5 -> #REF! | K5: =#REF!-#REF! -> #REF!
B6: Blackwood | C6: CEA-03 | D6: ='CEA Attributes'!E5 -> 3.688 | E6: ='EORP Carbon Stock'!#REF! -> #REF! | F6: =E6*44/12 -> #REF! | G6: ='Project Emissions'!#REF!*'Project Emissions'!$E$11 -> #REF! | H6: ='Project Emissions'!#REF!*'Project Emissions'!$G$11 -> #REF! | I6: ='Fuel Emissions'!#REF! -> #REF! | J6: =F6-G6-H6-I6 -> #REF! | K6: =#REF!-#REF! -> #REF!
B7: Total | D7: =SUM('EORP Carbon Stock'!C5:C9) -> 31.348 | E7: =SUM('EORP Carbon Stock'!I5:I9) -> 81.789268 | F7: =SUM(F4:F6) -> #REF! | G7: ='Project Emissions'!E13 -> 0 | H7: ='Project Emissions'!G13 -> 0 | I7: ='Fuel Emissions'!D43 -> 1.5489479 | J7: ='Net Abatement'!C10 -> 290.52492
B9: Abatement to 30 June 2025
B10: Property | D10: Area (ha) | E10: Abatement (tC) | F10: Abatement (tCO2e) | G10: Project CH4 emissions (tCO2e) | H10: Project N2O emissions (tCO2e) | I10: Fuel Emissions tCO2e | J10: Net abatement (tCO2e) | K10: Age (yrs)
B11: Blackwood | C11: CEA-01 | D11: =D4 -> 11.085 | E11: =SUM(#REF!)*D11 -> #REF! | F11: =E11*44/12 -> #REF! | G11: =G4 -> 0 | H11: =H4 -> 0 | I11: =I4 -> 1.1622614 | J11: =F11-G11-H11-I11 -> #REF! | K11: =#REF!-#REF! -> #REF!
B12: Blackwood | C12: CEA-02 | D12: =D5 -> #REF! | E12: =SUM(#REF!)*D12 -> #REF! | F12: =E12*44/12 -> #REF! | G12: =G5 -> #REF! | H12: =H5 -> #REF! | I12: =I5 -> #REF! | J12: =F12-G12-H12-I12 -> #REF! | K12: =#REF!-#REF! -> #REF!
B13: Blackwood | C13: CEA-03 | D13: =D6 -> 3.688 | E13: =SUM(#REF!)*D13 -> #REF! | F13: =E13*44/12 -> #REF! | G13: =G6 -> #REF! | H13: =H6 -> #REF! | I13: =I6 -> #REF! | J13: =F13-G13-H13-I13 -> #REF! | K13: =#REF!-#REF! -> #REF!
B14: Total | D14: =D7 -> 31.348 | E14: =SUM('EORP Carbon Stock'!I11:I17) -> 299.89398 | F14: =SUM(F11:F13) -> #REF! | G14: =G7 -> 0 | H14: =H7 -> 0 | I14: =I7 -> 1.5489479 | J14: =F14-G14-H14-I14 -> #REF!
B17: Cumulative total
B18: Year | C18: Month | D18: CEA1 | E18: CEA2 | F18: CEA3 | J18: Total | L18: SD Total
B19: 2022 | C19: 6 | D19: =#REF! -> #REF! | E19: =#REF! -> #REF! | F19: =#REF! -> #REF! | J19: =SUM(D19:I19) -> #REF! | L19: =SUM(G19:I19) -> 0
B20: 2023 | C20: 6 | D20: =#REF! -> #REF! | E20: =#REF! -> #REF! | F20: =#REF! -> #REF! | J20: =SUM(D20:I20) -> #REF! | L20: =SUM(G20:I20) -> 0
B21: 2024 | C21: 6 | D21: =#REF! -> #REF! | E21: =#REF! -> #REF! | F21: =#REF! -> #REF! | J21: =SUM(D21:I21) -> #REF! | L21: =SUM(G21:I21) -> 0
B22: 2025 | C22: 6 | D22: =#REF! -> #REF! | E22: =#REF! -> #REF! | F22: =#REF! -> #REF! | J22: =SUM(D22:I22) -> #REF! | L22: =SUM(G22:I22) -> 0
B23: 2026 | C23: 6 | D23: =#REF! -> #REF! | E23: =#REF! -> #REF! | F23: =#REF! -> #REF! | J23: =SUM(D23:I23) -> #REF! | L23: =SUM(G23:I23) -> 0
B24: 2027 | C24: 6 | D24: =#REF! -> #REF! | E24: =#REF! -> #REF! | F24: =#REF! -> #REF! | J24: =SUM(D24:I24) -> #REF! | L24: =SUM(G24:I24) -> 0
B25: 2028 | C25: 6 | D25: =#REF! -> #REF! | E25: =#REF! -> #REF! | F25: =#REF! -> #REF! | J25: =SUM(D25:I25) -> #REF! | L25: =SUM(G25:I25) -> 0
B26: 2029 | C26: 6 | D26: =#REF! -> #REF! | E26: =#REF! -> #REF! | F26: =#REF! -> #REF! | J26: =SUM(D26:I26) -> #REF! | L26: =SUM(G26:I26) -> 0
B27: 2030 | C27: 6 | D27: =#REF! -> #REF! | E27: =#REF! -> #REF! | F27: =#REF! -> #REF! | J27: =SUM(D27:I27) -> #REF! | L27: =SUM(G27:I27) -> 0
B28: 2031 | C28: 6 | D28: =#REF! -> #REF! | E28: =#REF! -> #REF! | F28: =#REF! -> #REF! | J28: =SUM(D28:I28) -> #REF! | L28: =SUM(G28:I28) -> 0
B31: Annual abatement
B32: Year | C32: Month | D32: Jingeri | E32: Hidden Vale | F32: Liscombe | G32: Stewartdale 1 | H32: Stewartdale 2 | I32: Stewartdale 3 | J32: Total | L32: SD Total
B33: 2022 | C33: 6 | D33: =D19 -> #REF! | E33: =E19 -> #REF! | F33: =F19 -> #REF! | G33: =G19 -> 0 | H33: =H19 -> 0 | I33: =I19 -> 0 | J33: =SUM(D33:I33) -> #REF! | L33: =SUM(G33:I33) -> 0
B34: 2023 | C34: 6 | D34: =D20-D19 -> #REF! | E34: =E20-E19 -> #REF! | F34: =F20-F19 -> #REF! | G34: =G20-G19 -> 0 | H34: =H20-H19 -> 0 | I34: =I20-I19 -> 0 | J34: =SUM(D34:I34) -> #REF! | L34: =SUM(G34:I34) -> 0
B35: 2024 | C35: 6 | D35: =D21-D20 -> #REF! | E35: =E21-E20 -> #REF! | F35: =F21-F20 -> #REF! | G35: =G21-G20 -> 0 | H35: =H21-H20 -> 0 | I35: =I21-I20 -> 0 | J35: =SUM(D35:I35) -> #REF! | L35: =SUM(G35:I35) -> 0
B36: 2025 | C36: 6 | D36: =D22-D21 -> #REF! | E36: =E22-E21 -> #REF! | F36: =F22-F21 -> #REF! | G36: =G22-G21 -> 0 | H36: =H22-H21 -> 0 | I36: =I22-I21 -> 0 | J36: =SUM(D36:I36) -> #REF! | L36: =SUM(G36:I36) -> 0
B37: 2026 | C37: 6 | D37: =D23-D22 -> #REF! | E37: =E23-E22 -> #REF! | F37: =F23-F22 -> #REF! | G37: =G23-G22 -> 0 | H37: =H23-H22 -> 0 | I37: =I23-I22 -> 0 | J37: =SUM(D37:I37) -> #REF! | L37: =SUM(G37:I37) -> 0
B38: 2027 | C38: 6 | D38: =D24-D23 -> #REF! | E38: =E24-E23 -> #REF! | F38: =F24-F23 -> #REF! | G38: =G24-G23 -> 0 | H38: =H24-H23 -> 0 | I38: =I24-I23 -> 0 | J38: =SUM(D38:I38) -> #REF! | L38: =SUM(G38:I38) -> 0
B39: 2028 | C39: 6 | D39: =D25-D24 -> #REF! | E39: =E25-E24 -> #REF! | F39: =F25-F24 -> #REF! | G39: =G25-G24 -> 0 | H39: =H25-H24 -> 0 | I39: =I25-I24 -> 0 | J39: =SUM(D39:I39) -> #REF! | L39: =SUM(G39:I39) -> 0
B40: 2029 | C40: 6 | D40: =D26-D25 -> #REF! | E40: =E26-E25 -> #REF! | F40: =F26-F25 -> #REF! | G40: =G26-G25 -> 0 | H40: =H26-H25 -> 0 | I40: =I26-I25 -> 0 | J40: =SUM(D40:I40) -> #REF! | L40: =SUM(G40:I40) -> 0
B41: 2030 | C41: 6 | D41: =D27-D26 -> #REF! | E41: =E27-E26 -> #REF! | F41: =F27-F26 -> #REF! | G41: =G27-G26 -> 0 | H41: =H27-H26 -> 0 | I41: =I27-I26 -> 0 | J41: =SUM(D41:I41) -> #REF! | L41: =SUM(G41:I41) -> 0
B42: 2031 | C42: 6 | D42: =D28-D27 -> #REF! | E42: =E28-E27 -> #REF! | F42: =F28-F27 -> #REF! | G42: =G28-G27 -> 0 | H42: =H28-H27 -> 0 | I42: =I28-I27 -> 0 | J42: =SUM(D42:I42) -> #REF! | L42: =SUM(G42:I42) -> 0
B43: Total | D43: =SUM(D33:D42) -> #REF! | E43: =SUM(E33:E42) -> #REF! | F43: =SUM(F33:F42) -> #REF! | G43: =SUM(G33:G42) -> 0 | H43: =SUM(H33:H42) -> 0 | I43: =SUM(I33:I42) -> 0 | J43: =SUM(J33:J42) -> #REF! | L43: =SUM(G43:I43) -> 0
B46: Abatement Scheudle
B47: Year | C47: Month | D47: Jingeri | E47: Hidden Vale | F47: Liscombe | G47: Stewartdale 1 | H47: Stewartdale 2 | I47: Stewartdale 3 | J47: Total | L47: SD Total
B48: 2017 | C48: 6 | D48: =D33+D34 -> #REF! | E48: =E33+E34 -> #REF! | F48: =F33+F34 -> #REF! | G48: =G33+G34 -> 0 | H48: =H33+H34 -> 0 | I48: =I33+I34 -> 0 | J48: =SUM(D48:I48) -> #REF! | L48: =SUM(G48:I48) -> 0
...

Sheet EORP Carbon Stock
A4: CEA Name | B4: FullCAM calibration used | C4: CEA area (ha) | D4: Initial carbon mass trees - CDt (t C /ha) | E4: Initial carbon mass debris - CDd (t C /ha) | F4: Initial carbon mass - CD (t C) | G4: End carbon mass trees - Ct (t C /ha) | H4: End carbon mass debris - Cd (t C /ha) | I4: End carbon mass - C (t C)
A5: DP_CEA01 | B5: Mixed species environmental planting - Generic | C5: ='CEA Attributes'!C5 -> 11.085 | D5: 0 | E5: 0 | F5: =(D5+E5)*C5 -> 0 | G5: {=INDEX('DP_CEA01 - Output'!E:E, MATCH(Cover!B20, DATE('DP_CEA01 - Output'!A:A, 'DP_CEA01 - Output'!B:B, 'DP_CEA01 - Output'!C:C), 0))} -> 2.920373 | H5: {=INDEX('DP_CEA01 - Output'!F:F, MATCH(Cover!B20, DATE('DP_CEA01 - Output'!A:A, 'DP_CEA01 - Output'!B:B, 'DP_CEA01 - Output'!C:C), 0))} -> 0.11154143 | I5: =(H5+G5)*C5 -> 33.608771
A6: DP_CEA02 | B6: Mixed species environmental planting - Generic | C6: ='CEA Attributes'!D5 -> 2.507 | D6: 0 | E6: 0 | F6: =(D6+E6)*C6 -> 0 | G6: {=INDEX('DP_CEA02 - Output'!E:E, MATCH(Cover!B20, DATE('DP_CEA02 - Output'!A:A, 'DP_CEA02 - Output'!B:B, 'DP_CEA02 - Output'!C:C), 0))} -> 7.3929822 | H6: {=INDEX('DP_CEA02 - Output'!F:F, MATCH(Cover!B20, DATE('DP_CEA02 - Output'!A:A, 'DP_CEA02 - Output'!B:B, 'DP_CEA02 - Output'!C:C), 0))} -> 0.4245847 | I6: =(H6+G6)*C6 -> 19.59864
A7: DP_CEA03 | B7: Mixed species environmental planting - Generic | C7: ='CEA Attributes'!E5 -> 3.688 | D7: 0 | E7: 0 | F7: =(D7+E7)*C7 -> 0 | G7: {=INDEX('DP_CEA03 - Output'!E:E, MATCH(Cover!B20, DATE('DP_CEA02 - Output'!A:A, 'DP_CEA02 - Output'!B:B, 'DP_CEA02 - Output'!C:C), 0))} -> 6.2368634 | H7: {=INDEX('DP_CEA03 - Output'!F:F, MATCH(Cover!B20, DATE('DP_CEA03 - Output'!A:A, 'DP_CEA03 - Output'!B:B, 'DP_CEA03 - Output'!C:C), 0))} -> 0.36149967 | I7: =(H7+G7)*C7 -> 24.334763
A8: DP_CEA04 | B8: Mixed species environmental planting - Generic | C8: ='CEA Attributes'!F5 -> 14.068 | D8: 0 | E8: 0 | F8: =(D8+E8)*C8 -> 0 | G8: {=INDEX('DP_CEA04 - Output'!E:E, MATCH(Cover!B21, DATE('DP_CEA04 - Output'!A:A, 'DP_CEA04 - Output'!B:B, 'DP_CEA04 - Output'!C:C), 0))} -> 0.29371304 | H8: {=INDEX('DP_CEA04 - Output'!F:F, MATCH(Cover!B21, DATE('DP_CEA04 - Output'!A:A, 'DP_CEA04 - Output'!B:B, 'DP_CEA04 - Output'!C:C), 0))} -> 0.0081844188 | I8: =(H8+G8)*C8 -> 4.2470935
H11: Carbon stock for the project area at the end of this reporting period CP (tCO2e) | I11: =SUM(I5:I8)*44/12 -> 299.89398

Sheet Project Emissions
A2: Division 4.4, Section 4.13
A4: CEA Name | B4: FullCAM calibration used | C4: CEA area (ha) | D4: CH4 Emissions - ECH4 (t CH4/ha) | E4: CH4 Emissions - EBCH4 (t CH4) | F4: N2O Emmissions - EN2O (t N2O/ha) | G4: N2O Emmissions - EBN2O (t N2O)
A5: DP_CEA01 | B5: Mixed species environmental planting - Generic | C5: ='CEA Attributes'!C5 -> 11.085 | D5: ='DP_CEA01 - Output'!G20 -> 0 | E5: =D5*C5 -> 0 | F5: ='DP_CEA01 - Output'!H20 -> 0 | G5: =F5*C5 -> 0
A6: DP_CEA02 | B6: Mixed species environmental planting - Generic | C6: ='CEA Attributes'!D5 -> 2.507 | D6: ='DP_CEA02 - Output'!G33 -> 0 | E6: =D6*C6 -> 0 | F6: ='DP_CEA02 - Output'!H33 -> 0 | G6: =F6*C6 -> 0
A7: DP_CEA03 | B7: Mixed species environmental planting - Generic | C7: ='CEA Attributes'!E5 -> 3.688 | D7: ='DP_CEA03 - Output'!G33 -> 0 | E7: =D7*C7 -> 0 | F7: ='DP_CEA03 - Output'!H33 -> 0 | G7: =F7*C7 -> 0
A8: DP_CEA04 | B8: Mixed species environmental planting - Generic | C8: ='CEA Attributes'!F5 -> 14.068 | D8: 0 | E8: 0 | F8: 0 | G8: 0
D11: Gl Warm Pot CH4 | E11: 28 | F11: Gl Warm Pot NO2 | G11: 265
D13: Equation 13 | E13: =SUM(E5:E9)*E11 -> 0 | F13: Equation 14 | G13: =SUM(G5:G9)*G11/1000 -> 0
F15: Equation 15 | G15: =G13+E13 -> 0
J25: Mixed species environmental planting - Generic | K25: ='CEA Attributes'!N21 -> 0

Sheet Fuel Emissions
A2: Division 4.4; Section 4.14
B4: Diesel use - fore each hectare assume:
B5: Ripping, Mound and Direct Seeding (all events) | D5: One time per CEA
B6: Fuel consumption 2022 and 2023 (L) | D6: ='Fuel Ref. DP 22-23'!F11 -> 549.5 | E6: Time/consuption - Area proportional | H6: Fueld consumption 2024-2025 (L) | I6: =31+93 -> 124
B8: Petrol use - Fore each property, assume: | H8: Petrol use - Fore each property, assume:
B9: Site visit frequency (visits/yr) | D9: 4 | H9: Site visit frequency (visits/yr) | I9: 4
B10: Travel distance/site visit (km) | D10: 30 | H10: Travel distance/site visit (km) | I10: 30
B11: Fuel consumption of (km/L) | D11: 10 | H11: Fuel consumption of (km/L) | I11: 10
B12: Fuel consumption/site visit (Litres) | D12: =D10/D11 -> 3 | H12: Fuel consumption/site visit (Litres) | I12: =I10/I11 -> 3
B13: Reporting period (years) | D13: 2 | H13: Reporting period (years) | I13: 1
B15: Qf - Total diesel (kL) | D15: =(D6)/1000 -> 0.5495 | H15: Qf - Total diesel (kL) | I15: =I6/1000 -> 0.124
B16: Qf - Total gasoline (kL) | D16: =(D12*D9*D13)/1000 -> 0.024 | H16: Qf - Total gasoline (kL) | I16: =(I12*I9*I13)/1000 -> 0.012
B18: Fuel emission for each fuel type and greenhouse gas for the project - Equation 16
C20: Fuel emissions (t CO2e) | I20: Fuel emissions (t CO2e)
C21: CO2 | D21: CH4 | E21: N2O | F21: Total CO2e | I21: CO2 | J21: CH4 | K21: N2O | L21: Total CO2e
B22: Ef,diesel | C22: =$D$15*$C$36*D36/1000 -> 1.4826279 | D22: =$D$15*$C$36*E36/1000 -> 0.000212107 | E22: =$D$15*$C$36*F36/1000 -> 0.01060535 | F22: =SUM(C22:E22) -> 1.4934454 | H22: Ef,diesel | I22: =$I$15*$C$36*D36/1000 -> 0.33456936 | J22: =$I$15*$C$36*E36/1000 -> 4.7864e-05 | K22: =$D$15*$C$36*F36/1000 -> 0.01060535 | L22: =SUM(I22:K22) -> 0.34522257
B23: Ef,gasoline | C23: =$D$16*$C$35*D35/1000 -> 0.05532192 | D23: =$D$16*$C$35*E35/1000 -> 1.6416e-05 | E23: =$D$16*$C$35*F35/1000 -> 0.00016416 | F23: =SUM(C23:E23) -> 0.055502496 | H23: Ef,gasoline | I23: =$I$16*$C$35*D35/1000 -> 0.02766096 | J23: =$I$16*$C$35*E35/1000 -> 8.208e-06 | K23: =$I$16*$C$35*F35/1000 -> 8.208e-05 | L23: =SUM(I23:K23) -> 0.027751248
B25: Total project fuel emissions for the previous reporting period - Equation 17 | H25: Total project fuel emissions for the Current reporting period - Equation 17
B26: Ef - Total project fuel emssions for the previous reporting period= | E26: =F22+F23 -> 1.5489479 | F26: tonnes of CO2e | H26: Ef - Total project fuel emssions for the Current reporting period= | K26: =L22+L23 -> 0.37297382 | L26: tonnes of CO2e
A30: Fuel combustion—fuels for transport energy purposes
A31: Item | B31: Fuel combusted | C31: Energy content factor | D31: Emission factor
C32: (GJ/kL unless otherwise indicated) | D32: kg CO2‑e/GJ
D33: (relevant oxidation factors incorporated)
D34: CO2 | E34: CH4 | F34: N2O
A35: 35 | B35: Gasoline (other than for use as fuel in an aircraft) | C35: 34.2 | D35: 67.4 | E35: 0.02 | F35: 0.2
A36: 40 | B36: Diesel oil | C36: 38.6 | D36: 69.9 | E36: 0.01 | F36: 0.5
A39: Proportion of fuel emmissions by CEA
A40: CEA Name | B40: FullCAM calibration used | C40: CEA area (ha) | D40: Proportion of Fuel emissions
A41: ='EORP Carbon Stock'!A5 -> DP_CEA01 | B41: ='EORP Carbon Stock'!B5 -> Mixed species environmental planting - Generic | C41: ='EORP Carbon Stock'!C5 -> 11.085 | D41: =C41/$C$43*$E$26 -> 1.1622614
A42: ='EORP Carbon Stock'!A7 -> DP_CEA03 | B42: ='EORP Carbon Stock'!B7 -> Mixed species environmental planting - Generic | C42: ='EORP Carbon Stock'!C7 -> 3.688 | D42: =C42/$C$43*$E$26 -> 0.38668651
A43: Total | C43: =SUM(C41:C42) -> 14.773 | D43: =SUM(D41:D42) -> 1.5489479

Sheet Global Warm Pot

Sheet Fuel Ref. DP 22-23
A1: Equipment Emission Estimation (Diesel) - soil preparation + installation works (2022 and 2023 - Machinery Service Invoice ) | D1: Time (h) | E1: Eficienc. | F1: Diesel (L)
A2: Ripping Tractor: Brand: Steiger 225HP - Diesel Fuel Consumption average 20L/Hr | D2: 71 | E2: 20 | F2: =D2*E2 -> 1420
D3: 71 | E3: 15 | F3: =D3*E3 -> 1065
A4: Mounding Tractor: Brand CLAAS: 110 HP - Diesel Fuel Consumption Average 15L/Hr
A6: Direct Seeding: John Deere 32HP (Series 3 Utility Tractor) - Diesel Fuel Consumption Average: 4.5L/Hr | D6: 0 | E6: 4.5 | F6: =D6*E6 -> 0
A8: Spraying - DPC - John Deere 6125M - 120HP - Diesel Fuel Consumption Average 18L/Hr | D8: 80 | E8: 18 | F8: =D8*E8 -> 1440
D11: TOTAL (L) | F11: =SUM(F2:F8)*0.14 -> 549.5 | G11: Considering approx. 14% related to Devon Park
A12: Ripping and Mounding Invoice
F14: Planted 2022 | G14: Planted 2023 | H14: % / Project
D15: Blackwood | F15: 56.66 | G15: 28.57 | H15: =(F15+G15)/F19 -> 0.83143108
D16: Devon Park Report 1 | F16: ='CEA Attributes'!D5 -> 2.507 | H16: =F16/F19 -> 0.024456151
D17: Devon Park Report 2 | F17: ='CEA Attributes'!E5 -> 3.688 | G17: ='CEA Attributes'!C5 -> 11.085 | H17: =(G17+F17)/F19 -> 0.14411277
D18: TOTAL | F18: =SUM(F15:F17) -> 62.855 | G18: =SUM(G15:G17) -> 39.655
D19: TOTAL Planted 22/23 | F19: =F18+G18 -> 102.51
A20: Direct Seeding invoice IV0655
A29: Weeding spot-spray -Knockdown 80h estimated

Sheet DP_CEA01 - Output
A1: Year | B1: Month | C1: Day | D1: Dec. Year | E1: C mass of trees (tC/ha) | F1: C mass of forest debris (tC/ha) | G1: CH4 emitted due to fire (tCH4/ha) | H1: N2O emitted due to fire (tN2O/ha)
A2: 2023 | B2: 8 | C2: 16 | D2: 2023.625 | E2: 0 | F2: 0
A3: 2023 | B3: 8 | C3: 31 | D3: 2023.666 | E3: 0.29370033 | F3: 0.0029297956 | G3: 0 | H3: 0
A4: 2023 | B4: 9 | C4: 30 | D4: 2023.748 | E4: 0.2937261 | F4: 0.0060924614 | G4: 0 | H4: 0
A5: 2023 | B5: 10 | C5: 31 | D5: 2023.833 | E5: 0.29415749 | F5: 0.0081016552 | G5: 0 | H5: 0
A6: 2023 | B6: 11 | C6: 30 | D6: 2023.915 | E6: 0.29679043 | F6: 0.0098406631 | G6: 0 | H6: 0
A7: 2023 | B7: 12 | C7: 31 | D7: 2024 | E7: 0.30679946 | F7: 0.011654109 | G7: 0 | H7: 0
A8: 2024 | B8: 1 | C8: 31 | D8: 2024.085 | E8: 0.332959 | F8: 0.013750106 | G8: 0 | H8: 0
A9: 2024 | B9: 2 | C9: 29 | D9: 2024.164 | E9: 0.38215992 | F9: 0.016550483 | G9: 0 | H9: 0
A10: 2024 | B10: 3 | C10: 31 | D10: 2024.249 | E10: 0.47267686 | F10: 0.018515659 | G10: 0 | H10: 0
A11: 2024 | B11: 4 | C11: 30 | D11: 2024.331 | E11: 0.60782682 | F11: 0.020996222 | G11: 0 | H11: 0
A12: 2024 | B12: 5 | C12: 31 | D12: 2024.415 | E12: 0.80533254 | F12: 0.024740008 | G12: 0 | H12: 0
A13: 2024 | B13: 6 | C13: 30 | D13: 2024.497 | E13: 1.0582805 | F13: 0.029983721 | G13: 0 | H13: 0
A14: 2024 | B14: 7 | C14: 31 | D14: 2024.582 | E14: 1.3869717 | F14: 0.037170487 | G14: 0 | H14: 0
... A303: 2048 | B303: 8 | C303: 17 | D303: 2048.628 | E303: 80.235489 | F303: 22.60265 | G303: 0 | H303: 0

Sheet DP_CEA02 - Output
A1: Year | B1: Month | C1: Day | D1: Dec. Year | E1: C mass of trees (tC/ha) | F1: C mass of forest debris (tC/ha) | G1: CH4 emitted due to fire (tCH4/ha) | H1: N2O emitted due to fire (tN2O/ha)
A2: 2022 | B2: 7 | C2: 29 | D2: 2022.575 | E2: 0 | F2: 0
A3: 2022 | B3: 7 | C3: 31 | D3: 2022.581 | E3: 0.2937 | F3: 0.00038200604 | G3: 0 | H3: 0
A4: 2022 | B4: 8 | C4: 31 | D4: 2022.666 | E4: 0.29370579 | F4: 0.0050455158 | G4: 0 | H4: 0
A5: 2022 | B5: 9 | C5: 30 | D5: 2022.748 | E5: 0.29385671 | F5: 0.0072578677 | G5: 0 | H5: 0
A6: 2022 | B6: 10 | C6: 31 | D6: 2022.833 | E6: 0.29523329 | F6: 0.0090422528 | G6: 0 | H6: 0
A7: 2022 | B7: 11 | C7: 30 | D7: 2022.915 | E7: 0.30113641 | F7: 0.010740462 | G7: 0 | H7: 0
A8: 2022 | B8: 12 | C8: 31 | D8: 2023 | E8: 0.31903718 | F8: 0.012592458 | G8: 0 | H8: 0
A9: 2023 | B9: 1 | C9: 31 | D9: 2023.085 | E9: 0.3592681 | F9: 0.014826351 | G9: 0 | H9: 0
A10: 2023 | B10: 2 | C10: 28 | D10: 2023.162 | E10: 0.42472483 | F10: 0.017806714 | G10: 0 | H10: 0
A11: 2023 | B11: 3 | C11: 31 | D11: 2023.247 | E11: 0.54010939 | F11: 0.020175105 | G11: 0 | H11: 0
A12: 2023 | B12: 4 | C12: 30 | D12: 2023.329 | E12: 0.7037026 | F12: 0.023176465 | G12: 0 | H12: 0
A13: 2023 | B13: 5 | C13: 31 | D13: 2023.414 | E13: 0.93360635 | F13: 0.027615832 | G13: 0 | H13: 0
A14: 2023 | B14: 6 | C14: 30 | D14: 2023.496 | E14: 1.2193335 | F14: 0.033703624 | G14: 0 | H14: 0
... A303: 2047 | B303: 7 | C303: 30 | D303: 2047.578 | E303: 79.326313 | F303: 22.396651 | G303: 0 | H303: 0

Sheet DP_CEA03 - Output
A1: Year | B1: Month | C1: Day | D1: Dec. Year | E1: C mass of trees (tC/ha) | F1: C mass of forest debris (tC/ha) | G1: CH4 emitted due to fire (tCH4/ha) | H1: N2O emitted due to fire (tN2O/ha)
A2: 2022 | B2: 7 | C2: 29 | D2: 2022.575 | E2: 0 | F2: 0
A3: 2022 | B3: 7 | C3: 31 | D3: 2022.581 | E3: 0.2937 | F3: 0.00038194812 | G3: 0 | H3: 0
A4: 2022 | B4: 8 | C4: 31 | D4: 2022.666 | E4: 0.29370484 | F4: 0.0050329573 | G4: 0 | H4: 0
A5: 2022 | B5: 9 | C5: 30 | D5: 2022.748 | E5: 0.29383119 | F5: 0.0072365569 | G5: 0 | H5: 0
A6: 2022 | B6: 10 | C6: 31 | D6: 2022.833 | E6: 0.2949836 | F6: 0.0090077893 | G6: 0 | H6: 0
A7: 2022 | B7: 11 | C7: 30 | D7: 2022.915 | E7: 0.29992539 | F7: 0.01069075 | G7: 0 | H7: 0
A8: 2022 | B8: 12 | C8: 31 | D8: 2023 | E8: 0.31491102 | F8: 0.012518043 | G8: 0 | H8: 0
A9: 2023 | B9: 1 | C9: 31 | D9: 2023.085 | E9: 0.34859033 | F9: 0.014699876 | G9: 0 | H9: 0
A10: 2023 | B10: 2 | C10: 28 | D10: 2023.162 | E10: 0.40338742 | F10: 0.0174414 | G10: 0 | H10: 0
A11: 2023 | B11: 3 | C11: 31 | D11: 2023.247 | E11: 0.4999816 | F11: 0.019635566 | G11: 0 | H11: 0
A12: 2023 | B12: 4 | C12: 30 | D12: 2023.329 | E12: 0.63693363 | F12: 0.022259382 | G12: 0 | H12: 0
A13: 2023 | B13: 5 | C13: 31 | D13: 2023.414 | E13: 0.82939753 | F13: 0.026116924 | G13: 0 | H13: 0
A14: 2023 | B14: 6 | C14: 30 | D14: 2023.496 | E14: 1.068594 | F14: 0.031403528 | G14: 0 | H14: 0
... A29: 2024 | B29: 9 | C29: 30 | D29: 2024.749 | E29: 4.8744992 | F29: 0.24724914 | G29: 0 | H29: 0
A30: 2024 | B30: 10 | C30: 31 | D30: 2024.833 | E30: 5.2067442 | F30: 0.27241344 | G30: 0
A31: 2024 | B31: 11 | C31: 30 | D31: 2024.915 | E31: 5.5357248 | F31: 0.29883952 | G31: 0 | H31: 0
A32: 2024 | B32: 12 | C32: 31 | D32: 2025 | E32: 5.8828777 | F32: 0.32846239 | G32: 0 | H32: 0
A33: 2025 | B33: 1 | C33: 31 | D33: 2025.085 | E33: 6.2368634 | F33: 0.36149967 | G33: 0 | H33: 0
A34: 2025 | B34: 2 | C34: 28 | D34: 2025.162 | E34: 6.5620631 | F34: 0.39644501 | G34: 0 | H34: 0
A35: 2025 | B35: 3 | C35: 31 | D35: 2025.247 | E35: 6.9277303 | F35: 0.42650996 | G35: 0 | H35: 0
A36: 2025 | B36: 4 | C36: 30 | D36: 2025.329 | E36: 7.2868155 | F36: 0.45478246 | G36: 0 | H36: 0
A37: 2025 | B37: 5 | C37: 31 | D37: 2025.414 | E37: 7.6628309 | F37: 0.48571313 | G37: 0 | H37: 0
A38: 2025 | B38: 6 | C38: 30 | D38: 2025.496 | E38: 8.0311238 | F38: 0.51863578 | G38: 0 | H38: 0
A39: 2025 | B39: 7 | C39: 31 | D39: 2025.581 | E39: 8.4158519 | F39: 0.55384428 | G39: 0 | H39: 0
A40: 2025 | B40: 8 | C40: 31 | D40: 2025.666 | E40: 8.8044216 | F40: 0.5906779 | G40: 0 | H40: 0
A41: 2025 | B41: 9 | C41: 30 | D41: 2025.748 | E41: 9.1837634 | F41: 0.62958697 | G41: 0 | H41: 0
A42: 2025 | B42: 10 | C42: 31 | D42: 2025.833 | E42: 9.5788199 | F42: 0.67198373 | G42: 0 | H42: 0
... A303: 2047 | B303: 7 | C303: 30 | D303: 2047.578 | E303: 66.455844 | F303: 18.612062 | G303: 0 | H303: 0

Sheet DP_CEA04 - Output
A1: Year | B1: Month | C1: Day | D1: Dec. Year | E1: C mass of trees (tC/ha) | F1: C mass of forest debris (tC/ha) | G1: CH4 emitted due to fire (tCH4/ha) | H1: N2O emitted due to fire (tN2O/ha)
A2: 2025 | B2: 8 | C2: 14 | D2: 2025.619 | E2: 0 | F2: 0
A3: 2025 | B3: 8 | C3: 31 | D3: 2025.666 | E3: 0.2937 | F3: 0.0032230994 | G3: 0 | H3: 0
A4: 2025 | B4: 9 | C4: 30 | D4: 2025.748 | E4: 0.2937015 | F4: 0.0062227368 | G4: 0 | H4: 0
A5: 2025 | B5: 10 | C5: 31 | D5: 2025.833 | E5: 0.29371304 | F5: 0.0081844188 | G5: 0 | H5: 0
A6: 2025 | B6: 11 | C6: 30 | D6: 2025.915 | E6: 0.2937681 | F6: 0.0098939536 | G6: 0 | H6: 0
A7: 2025 | B7: 12 | C7: 31 | D7: 2026 | E7: 0.29397164 | F7: 0.011635237 | G7: 0 | H7: 0
A8: 2026 | B8: 1 | C8: 31 | D8: 2026.085 | E8: 0.29454929 | F8: 0.013524943 | G8: 0 | H8: 0
A9: 2026 | B9: 2 | C9: 28 | D9: 2026.162 | E9: 0.29572677 | F9: 0.015674198 | G9: 0 | H9: 0
A10: 2026 | B10: 3 | C10: 31 | D10: 2026.247 | E10: 0.29832391 | F10: 0.016701582 | G10: 0 | H10: 0
A11: 2026 | B11: 4 | C11: 30 | D11: 2026.329 | E11: 0.30289862 | F11: 0.017499688 | G11: 0 | H11: 0
A12: 2026 | B12: 5 | C12: 31 | D12: 2026.414 | E12: 0.31078096 | F12: 0.018474078 | G12: 0 | H12: 0
A13: 2026 | B13: 6 | C13: 30 | D13: 2026.496 | E13: 0.32260886 | F13: 0.019698042 | G13: 0 | H13: 0
A14: 2026 | B14: 7 | C14: 31 | D14: 2026.581 | E14: 0.3404895 | F14: 0.021062683 | G14: 0 | H14: 0
... A279: 2048 | B279: 8 | C279: 17 | D279: 2048.628 | E279: 70.605594 | F279: 18.980679 | G279: 0 | H279: 0
