Workbook
Name _04._HID_CEA_01_GENERIC_NO_INIT_CAL___Output_1_1: BW_CEA_01!$A$1:$H$310
Name _04._JIN_CEA_01_GENERIC_NO_INIT_CAL___Output_1_1: BW_CEA_05!$A$1:$F$310
Name _04._JIN_CEA_01_GENERIC_NO_INIT_CAL___Output_1_1: BW_CEA_06!$A$1:$F$310
Name _04._JIN_CEA_01_GENERIC_NO_INIT_CAL___Output_1_1: BW_CEA_07!$A$1:$F$310
Name _04._LIS_CEA_01_GENERIC_NO_INIT_CAL___Output_1: BW_CEA_02!$A$1:$H$310
Name _04._LIS_CEA_01_GENERIC_NO_INIT_CAL___Output_1: BW_CEA_03!$A$1:$H$310
Name _04._LIS_CEA_01_GENERIC_NO_INIT_CAL___Output_1: BW_CEA_04!$A$1:$H$310
Name _04._LIS_CEA_01_GENERIC_NO_INIT_CAL___Output_1_1: BW_CEA_02!$A$1:$H$310
Name _04._LIS_CEA_01_GENERIC_NO_INIT_CAL___Output_1_1: BW_CEA_03!$A$1:$H$310
Name _04._LIS_CEA_01_GENERIC_NO_INIT_CAL___Output_1_1: BW_CEA_04!$A$1:$H$310

Sheet Forecast_script_helper
A1: Blackwood Biodiversity and Carbon Project | B1: ERF173222
A2: Tab Used For Forecast Automation, DO NOT TOUCH | K2: Month Length Helper
K3: 1 | L3: 2 | M3: 3 | N3: 4 | O3: 5 | P3: 6 | Q3: 7 | R3: 8 | S3: 9 | T3: 10 | U3: 11 | V3: 12
A4: Current RP | B4: 2 | D4: Previouse RP | E4: =B4-1 -> 1 | K4: 31 | L4: 28 | M4: 31 | N4: 30 | O4: 31 | P4: 30 | Q4: 31 | R4: 31 | S4: 30 | T4: 31 | U4: 30 | V4: 31
A5: Current RP End Date | D5: Project Start Date | E5: =Cover!B19 -> 44682
A6: RP Length | B6: 12
A7: Current RP End Year | B7: 2025 | D7: Previouse RP Year | E7: =IF((B8-B6)<1,B7-1,B7) -> 2024
A8: Current RP End Month | B8: 10 | D8: Previouse RP Month | E8: =MOD(B8 - B6 - 1, 12) + 1 -> 10
A9: Current RP End Day | B9: 31 | D9: Previouse RP Day | E9: =_xlfn.XLOOKUP(E8,K3:V3,K4:V4) -> 31
A10: Decimal Year | B10: =B7 + (DATE(B7,B8,B9) - DATE(B7,1,0)) / (DATE(B7+1,1,0) - DATE(B7,1,0)) -> 2025.8329 | D10: Previouse RP Decimal | E10: =E7 + (DATE(E7,E8,E9) - DATE(E7,1,0)) / (DATE(E7+1,1,0) - DATE(E7,1,0)) -> 2024.8333
A12: Current RP | L12: How the Script works: If forecasting project lifecycle, reads Project Start Date, and calculates how many RPs remain from Current RP to that date, then Executes following loop (otherwise executes loop for specified number of RPs): Enters Current RP, RP length and Current RP Date info. Reads ACCUs Realised.
B13: BW_CEA_01 | C13: BW_CEA_02 | D13: BW_CEA_03 | E13: BW_CEA_04 | F13: BW_CEA_05 | G13: BW_CEA_06 | H13: BW_CEA_07
A14: C mass of trees+debris | B14: {=_xlfn.XLOOKUP($B$10, INDIRECT("'"&B$13&"'!D:D"), INDIRECT("'"&B$13&"'!I:I"), 0)} -> 6.1827856 | C14: {=_xlfn.XLOOKUP($B$10, INDIRECT("'"&C$13&"'!D:D"), INDIRECT("'"&C$13&"'!I:I"), 0)} -> 5.8076897 | D14: {=_xlfn.XLOOKUP($B$10, INDIRECT("'"&D$13&"'!D:D"), INDIRECT("'"&D$13&"'!I:I"), 0)} -> 6.3065748 | E14: {=_xlfn.XLOOKUP($B$10, INDIRECT("'"&E$13&"'!D:D"), INDIRECT("'"&E$13&"'!I:I"), 0)} -> 4.8419829 | F14: {=_xlfn.XLOOKUP($B$10, INDIRECT("'"&F$13&"'!D:D"), INDIRECT("'"&F$13&"'!I:I"), 0)} -> 10.843627 | G14: {=_xlfn.XLOOKUP($B$10, INDIRECT("'"&G$13&"'!D:D"), INDIRECT("'"&G$13&"'!I:I"), 0)} -> 10.651669 | H14: {=_xlfn.XLOOKUP($B$10, INDIRECT("'"&H$13&"'!D:D"), INDIRECT("'"&H$13&"'!I:I"), 0)} -> 9.4370301
A15: CEA Area | B15: =_xlfn.XLOOKUP(B13,Abatement!$A$5:$A$11,Abatement!$C$5:$C$11) -> 8.64 | C15: =_xlfn.XLOOKUP(C13,Abatement!$A$5:$A$11,Abatement!$C$5:$C$11) -> 3.87 | D15: =_xlfn.XLOOKUP(D13,Abatement!$A$5:$A$11,Abatement!$C$5:$C$11) -> 4.12 | E15: =_xlfn.XLOOKUP(E13,Abatement!$A$5:$A$11,Abatement!$C$5:$C$11) -> 5.58 | F15: =_xlfn.XLOOKUP(F13,Abatement!$A$5:$A$11,Abatement!$C$5:$C$11) -> 9.27 | G15: =_xlfn.XLOOKUP(G13,Abatement!$A$5:$A$11,Abatement!$C$5:$C$11) -> 21.23 | H15: =_xlfn.XLOOKUP(H13,Abatement!$A$5:$A$11,Abatement!$C$5:$C$11) -> 19.11
A16: Carbon Mass Per CEA | B16: =B15*B14 -> 53.419268 | C16: =C15*C14 -> 22.475759 | D16: =D15*D14 -> 25.983088 | E16: =E15*E14 -> 27.018264 | F16: =F15*F14 -> 100.52042 | G16: =G15*G14 -> 226.13493 | H16: =H15*H14 -> 180.34165
A17: Net Abatement | B17: =B16*44/12 -> 195.87065 | C17: =C16*44/12 -> 82.411117 | D17: =D16*44/12 -> 95.271323 | E17: =E16*44/12 -> 99.06697 | F17: =F16*44/12 -> 368.57487 | G17: =G16*44/12 -> 829.16141 | H17: =H16*44/12 -> 661.2527
A19: Carbon Stock at End of RP | B19: =SUM(B17:XFD17) -> 2331.609
A22: Previouse RP
B23: BW_CEA_01 | C23: BW_CEA_02 | D23: BW_CEA_03 | E23: BW_CEA_04 | F23: BW_CEA_05 | G23: BW_CEA_06 | H23: BW_CEA_07
A24: C mass of trees+debris | B24: {=_xlfn.XLOOKUP($E$10, INDIRECT("'"&B$23&"'!D:D"), INDIRECT("'"&B$23&"'!I:I"), 0)} -> 2.1616413 | C24: {=_xlfn.XLOOKUP($E$10, INDIRECT("'"&C$23&"'!D:D"), INDIRECT("'"&C$23&"'!I:I"), 0)} -> 1.9588068 | D24: {=_xlfn.XLOOKUP($E$10, INDIRECT("'"&D$23&"'!D:D"), INDIRECT("'"&D$23&"'!I:I"), 0)} -> 2.2006602 | E24: {=_xlfn.XLOOKUP($E$10, INDIRECT("'"&E$23&"'!D:D"), INDIRECT("'"&E$23&"'!I:I"), 0)} -> 1.7392283 | F24: {=_xlfn.XLOOKUP($E$10, INDIRECT("'"&F$23&"'!D:D"), INDIRECT("'"&F$23&"'!I:I"), 0)} -> 5.7872493 | G24: {=_xlfn.XLOOKUP($E$10, INDIRECT("'"&G$23&"'!D:D"), INDIRECT("'"&G$23&"'!I:I"), 0)} -> 5.6875302 | H24: {=_xlfn.XLOOKUP($E$10, INDIRECT("'"&H$23&"'!D:D"), INDIRECT("'"&H$23&"'!I:I"), 0)} -> 5.0565233
A25: CEA Area | B25: =_xlfn.XLOOKUP(B23,Abatement!$A$5:$A$11,Abatement!$C$5:$C$11) -> 8.64 | C25: =_xlfn.XLOOKUP(C23,Abatement!$A$5:$A$11,Abatement!$C$5:$C$11) -> 3.87 | D25: =_xlfn.XLOOKUP(D23,Abatement!$A$5:$A$11,Abatement!$C$5:$C$11) -> 4.12 | E25: =_xlfn.XLOOKUP(E23,Abatement!$A$5:$A$11,Abatement!$C$5:$C$11) -> 5.58 | F25: =_xlfn.XLOOKUP(F23,Abatement!$A$5:$A$11,Abatement!$C$5:$C$11) -> 9.27 | G25: =_xlfn.XLOOKUP(G23,Abatement!$A$5:$A$11,Abatement!$C$5:$C$11) -> 21.23 | H25: =_xlfn.XLOOKUP(H23,Abatement!$A$5:$A$11,Abatement!$C$5:$C$11) -> 19.11
A26: Carbon Mass Per CEA | B26: =B25*B24 -> 18.676581 | C26: =C25*C24 -> 7.5805824 | D26: =D25*D24 -> 9.0667202 | E26: =E25*E24 -> 9.704894 | F26: =F25*F24 -> 53.647801 | G26: =G25*G24 -> 120.74627 | H26: =H25*H24 -> 96.63016
A27: Net Abatement | B27: =B26*44/12 -> 68.480797 | C27: =C26*44/12 -> 27.795469 | D27: =D26*44/12 -> 33.244641 | E27: =E26*44/12 -> 35.584611 | F27: =F26*44/12 -> 196.7086 | G27: =G26*44/12 -> 442.73631 | H27: =H26*44/12 -> 354.31059
A29: Carbon Stock at End of Previouse RP | B29: =SUM(B27:XFD27) -> 1158.861
A31: Total Abatement | B31: =B19-B29 -> 1172.748
A33: Permenance | B33: 0.2
A34: Buffer | B34: 0.05
A36: ACCUs Realised | B36: =B31-(B33*B31+B34*B31) -> 879.56102

Sheet Cover
A11: Emissions Reduction Fund Offsets Report
A12: Blackwood Biodiversity and Carbon Project
A14: Item | B14: Project details
A15: Project Name | B15: Blackwood Biodiversity and Carbon Project
A16: Registration number | B16: ERF Project ID 173222
A17: Participant | B17: Dunkeld Pastoral Pty Ltd
A18: Agent | B18: Corporate Carbon Advisory Pty Ltd
A19: Commencement date | B19: 44682
A20: Reporting period | B20: 31 October 2024 to 31 October 2025
A21: Report number | B21: Report 2
A24: Code | B24: Section
B25: Cover
B26: Net Abatement
B27: CEA Attributes
B28: Abatement
B29: Project Emmissions
B30: Global Warming Potential
B31: Fuel Emmissions
B32: Tree Seedling Numbers
B33: CEA-01 Blackwood (Propagation 2023)
B34: CEA-02 Blackwood (Direct Seeding 2023)
B35: CEA-03 Blackwood (Propagation 2023)
B36: CEA-04 Blackwood (Propagation 2023)
... B39: CEA-07 Blackwood (Propagation 2022)

Sheet Net Abatement
A3: Equation 18; Section 5.8(a) | D3: 2025
A4: Symbol | B4: Element | C4: CO2-e (t) | D4: Section | F4: Symbol | G4: Value (t CO₂-e)
A5: CP | B5: Carbon stock for the project (in tonnes CO2-e) - Equation 11b. | C5: =Abatement!I14 -> 2331.609 | D5: 5.8(g) | F5: Carbon stock at end of reporting period | G5: =Abatement!I14 -> 2331.609
A6: EB | B6: Total project emissions from biomass burning for the project (in tonnes of CO2-2) - Equation 15 | C6: ='Project Emissions'!G18 -> 0 | D6: 5.8(c ) | F6: Total emissions from biomass burning | G6: 0
A7: EF | B7: Total project fuel emissions for the project (in tonnes CO2-e) - Equation 17 | C7: ='Fuel Emissions'!M26 -> 0 | D7: 5.8(d) | F7: Total emissions from fuel use | G7: 0
A8: CN | B8: Initial carbon stock for the project area (in tonnes CO2-e) Equation 11a | C8: =Abatement!F14 -> 0 | D8: 5.8(e/f) | F8: Carbon stock at end of previous reporting period | G8: 1158.861
A9: CV | B9: Final carbon stock for the project from the previous offsets report (in tonnes CO2-e) | C9: 1158.861 | D9: na | F9: Net abatement (2024 Method) | G9: =G5-G8 -> 1172.748
F10: Permanence period deduction (20%) | G10: =G9*0.2 -> 234.54961
A11: A | B11: Project net abatement for the reporting period (in tonnes CO2-e) | C11: =C5-C6-C7-C8-C9 -> 1172.748 | D11: 5.8(a) | F11: Risk-of-reversal buffer (5%) | G11: =G9*0.05 -> 58.637401
F12: ACCUs issued (after CFI Act Section 16 deductions) | G12: =G9-G10-G11 -> 879.56102
B14: Carbon stock change | C14: =C5-C8 -> 2331.609 | D14: 5.8(b)
A16: Af | B16: Buffers (risk of reversal =5%; premanence period = 20%, total = 25% ) | C16: =(1-0.25)*C11 -> 879.56102

Sheet Property Summary
B2: Abatement to 30 June 2023
B3: Property | C3: CEA | D3: Area (ha) | E3: Abatement (tC) | F3: Abatement (tCO2e) | G3: Project CH4 emissions (tCO2e) | H3: Project N2O emissions (tCO2e) | I3: Fuel Emissions tCO2e | J3: Net abatement (tCO2e) | K3: Age (yrs)
B4: Blackwood | C4: CEA-01 | D4: ='CEA Attributes'!#REF! -> #REF! | E4: =Abatement!#REF! -> #REF! | F4: =E4*44/12 -> #REF! | G4: 0 | H4: 0 | I4: ='Fuel Emissions'!#REF! -> #REF! | J4: =F4-G4-H4-I4 -> #REF! | K4: =#REF!-#REF! -> #REF!
B5: Blackwood | C5: CEA-02 | D5: ='CEA Attributes'!C5 -> 8.64 | E5: =Abatement!#REF! -> #REF! | F5: =E5*44/12 -> #REF! | G5: ='Project Emissions'!#REF!*'Project Emissions'!$E$14 -> #REF! | H5: ='Project Emissions'!#REF!*'Project Emissions'!$G$14 -> #REF! | I5: ='Fuel Emissions'!#REF! -> #REF! | J5: =F5-G5-H5-I5 -> #REF! | K5: =#REF!-#REF! -> #REF!
B6: Blackwood | C6: CEA-03 | D6: ='CEA Attributes'!D5 -> 3.87 | E6: =Abatement!#REF! -> #REF! | F6: =E6*44/12 -> #REF! | G6: ='Project Emissions'!#REF!*'Project Emissions'!$E$14 -> #REF! | H6: ='Project Emissions'!#REF!*'Project Emissions'!$G$14 -> #REF! | I6: ='Fuel Emissions'!#REF! -> #REF! | J6: =F6-G6-H6-I6 -> #REF! | K6: =#REF!-#REF! -> #REF!
B7: Total | D7: =SUM(Abatement!C5:C12) -> 71.82 | E7: =SUM(Abatement!I5:I12) -> 635.89337 | F7: =SUM(F4:F6) -> #REF! | G7: ='Project Emissions'!E16 -> 0 | H7: ='Project Emissions'!G16 -> 0 | I7: ='Fuel Emissions'!D48 -> 7.8460266 | J7: ='Net Abatement'!C11 -> 1172.748
B9: Abatement to 30 June 2025
B10: Property | D10: Area (ha) | E10: Abatement (tC) | F10: Abatement (tCO2e) | G10: Project CH4 emissions (tCO2e) | H10: Project N2O emissions (tCO2e) | I10: Fuel Emissions tCO2e | J10: Net abatement (tCO2e) | K10: Age (yrs)
B11: Blackwood | C11: CEA-01 | D11: =D4 -> #REF! | E11: =SUM(#REF!)*D11 -> #REF! | F11: =E11*44/12 -> #REF! | G11: =G4 -> 0 | H11: =H4 -> 0 | I11: =I4 -> #REF! | J11: =F11-G11-H11-I11 -> #REF! | K11: =#REF!-#REF! -> #REF!
B12: Blackwood | C12: CEA-02 | D12: =D5 -> 8.64 | E12: =SUM(#REF!)*D12 -> #REF! | F12: =E12*44/12 -> #REF! | G12: =G5 -> #REF! | H12: =H5 -> #REF! | I12: =I5 -> #REF! | J12: =F12-G12-H12-I12 -> #REF! | K12: =#REF!-#REF! -> #REF!
B13: Blackwood | C13: CEA-03 | D13: =D6 -> 3.87 | E13: =SUM(#REF!)*D13 -> #REF! | F13: =E13*44/12 -> #REF! | G13: =G6 -> #REF! | H13: =H6 -> #REF! | I13: =I6 -> #REF! | J13: =F13-G13-H13-I13 -> #REF! | K13: =#REF!-#REF! -> #REF!
B14: Total | D14: =D7 -> 71.82 | E14: =SUM(Abatement!I14:I20) -> 4663.2181 | F14: =SUM(F11:F13) -> #REF! | G14: =G7 -> 0 | H14: =H7 -> 0 | I14: =I7 -> 7.8460266 | J14: =F14-G14-H14-I14 -> #REF!
B17: Cumulative total
B18: Year | C18: Month | D18: CEA1 | E18: CEA2 | F18: CEA3 | J18: Total | L18: SD Total
B19: 2022 | C19: 6 | D19: =#REF! -> #REF! | E19: =BW_CEA_01!R25 -> 144.97329 | F19: =BW_CEA_02!R22 -> 15.658748 | J19: =SUM(D19:I19) -> #REF! | L19: =SUM(G19:I19) -> 0
B20: 2023 | C20: 6 | D20: =#REF! -> #REF! | E20: =BW_CEA_01!R66 -> 0 | F20: =BW_CEA_02!R83 -> 0 | J20: =SUM(D20:I20) -> #REF! | L20: =SUM(G20:I20) -> 0
B21: 2024 | C21: 6 | D21: =#REF! -> #REF! | E21: =BW_CEA_01!R67 -> 0 | F21: =BW_CEA_02!R84 -> 0 | J21: =SUM(D21:I21) -> #REF! | L21: =SUM(G21:I21) -> 0
B22: 2025 | C22: 6 | D22: =#REF! -> #REF! | E22: =BW_CEA_01!R68 -> 0 | F22: =BW_CEA_02!R85 -> 0 | J22: =SUM(D22:I22) -> #REF! | L22: =SUM(G22:I22) -> 0
B23: 2026 | C23: 6 | D23: =#REF! -> #REF! | E23: =BW_CEA_01!R69 -> 0 | F23: =BW_CEA_02!R86 -> 0 | J23: =SUM(D23:I23) -> #REF! | L23: =SUM(G23:I23) -> 0
B24: 2027 | C24: 6 | D24: =#REF! -> #REF! | E24: =BW_CEA_01!R70 -> 0 | F24: =BW_CEA_02!R87 -> 0 | J24: =SUM(D24:I24) -> #REF! | L24: =SUM(G24:I24) -> 0
B25: 2028 | C25: 6 | D25: =#REF! -> #REF! | E25: =BW_CEA_01!R71 -> 0 | F25: =BW_CEA_02!R88 -> 0 | J25: =SUM(D25:I25) -> #REF! | L25: =SUM(G25:I25) -> 0
B26: 2029 | C26: 6 | D26: =#REF! -> #REF! | E26: =BW_CEA_01!R72 -> 0 | F26: =BW_CEA_02!R89 -> 0 | J26: =SUM(D26:I26) -> #REF! | L26: =SUM(G26:I26) -> 0
B27: 2030 | C27: 6 | D27: =#REF! -> #REF! | E27: =BW_CEA_01!R73 -> 0 | F27: =BW_CEA_02!R90 -> 0 | J27: =SUM(D27:I27) -> #REF! | L27: =SUM(G27:I27) -> 0
B28: 2031 | C28: 6 | D28: =#REF! -> #REF! | E28: =BW_CEA_01!R74 -> 0 | F28: =BW_CEA_02!R91 -> 0 | J28: =SUM(D28:I28) -> #REF! | L28: =SUM(G28:I28) -> 0
B31: Annual abatement
B32: Year | C32: Month | D32: Jingeri | E32: Hidden Vale | F32: Liscombe | G32: Stewartdale 1 | H32: Stewartdale 2 | I32: Stewartdale 3 | J32: Total | L32: SD Total
B33: 2022 | C33: 6 | D33: =D19 -> #REF! | E33: =E19 -> 144.97329 | F33: =F19 -> 15.658748 | G33: =G19 -> 0 | H33: =H19 -> 0 | I33: =I19 -> 0 | J33: =SUM(D33:I33) -> #REF! | L33: =SUM(G33:I33) -> 0
B34: 2023 | C34: 6 | D34: =D20-D19 -> #REF! | E34: =E20-E19 -> -144.97329 | F34: =F20-F19 -> -15.658748 | G34: =G20-G19 -> 0 | H34: =H20-H19 -> 0 | I34: =I20-I19 -> 0 | J34: =SUM(D34:I34) -> #REF! | L34: =SUM(G34:I34) -> 0
B35: 2024 | C35: 6 | D35: =D21-D20 -> #REF! | E35: =E21-E20 -> 0 | F35: =F21-F20 -> 0 | G35: =G21-G20 -> 0 | H35: =H21-H20 -> 0 | I35: =I21-I20 -> 0 | J35: =SUM(D35:I35) -> #REF! | L35: =SUM(G35:I35) -> 0
B36: 2025 | C36: 6 | D36: =D22-D21 -> #REF! | E36: =E22-E21 -> 0 | F36: =F22-F21 -> 0 | G36: =G22-G21 -> 0 | H36: =H22-H21 -> 0 | I36: =I22-I21 -> 0 | J36: =SUM(D36:I36) -> #REF! | L36: =SUM(G36:I36) -> 0
B37: 2026 | C37: 6 | D37: =D23-D22 -> #REF! | E37: =E23-E22 -> 0 | F37: =F23-F22 -> 0 | G37: =G23-G22 -> 0 | H37: =H23-H22 -> 0 | I37: =I23-I22 -> 0 | J37: =SUM(D37:I37) -> #REF! | L37: =SUM(G37:I37) -> 0
B38: 2027 | C38: 6 | D38: =D24-D23 -> #REF! | E38: =E24-E23 -> 0 | F38: =F24-F23 -> 0 | G38: =G24-G23 -> 0 | H38: =H24-H23 -> 0 | I38: =I24-I23 -> 0 | J38: =SUM(D38:I38) -> #REF! | L38: =SUM(G38:I38) -> 0
B39: 2028 | C39: 6 | D39: =D25-D24 -> #REF! | E39: =E25-E24 -> 0 | F39: =F25-F24 -> 0 | G39: =G25-G24 -> 0 | H39: =H25-H24 -> 0 | I39: =I25-I24 -> 0 | J39: =SUM(D39:I39) -> #REF! | L39: =SUM(G39:I39) -> 0
B40: 2029 | C40: 6 | D40: =D26-D25 -> #REF! | E40: =E26-E25 -> 0 | F40: =F26-F25 -> 0 | G40: =G26-G25 -> 0 | H40: =H26-H25 -> 0 | I40: =I26-I25 -> 0 | J40: =SUM(D40:I40) -> #REF! | L40: =SUM(G40:I40) -> 0
B41: 2030 | C41: 6 | D41: =D27-D26 -> #REF! | E41: =E27-E26 -> 0 | F41: =F27-F26 -> 0 | G41: =G27-G26 -> 0 | H41: =H27-H26 -> 0 | I41: =I27-I26 -> 0 | J41: =SUM(D41:I41) -> #REF! | L41: =SUM(G41:I41) -> 0
B42: 2031 | C42: 6 | D42: =D28-D27 -> #REF! | E42: =E28-E27 -> 0 | F42: =F28-F27 -> 0 | G42: =G28-G27 -> 0 | H42: =H28-H27 -> 0 | I42: =I28-I27 -> 0 | J42: =SUM(D42:I42) -> #REF! | L42: =SUM(G42:I42) -> 0
B43: Total | D43: =SUM(D33:D42) -> #REF! | E43: =SUM(E33:E42) -> 0 | F43: =SUM(F33:F42) -> 0 | G43: =SUM(G33:G42) -> 0 | H43: =SUM(H33:H42) -> 0 | I43: =SUM(I33:I42) -> 0 | J43: =SUM(J33:J42) -> #REF! | L43: =SUM(G43:I43) -> 0
B46: Abatement Scheudle
B47: Year | C47: Month | D47: Jingeri | E47: Hidden Vale | F47: Liscombe | G47: Stewartdale 1 | H47: Stewartdale 2 | I47: Stewartdale 3 | J47: Total | L47: SD Total
B48: 2017 | C48: 6 | D48: =D33+D34 -> #REF! | E48: =E33+E34 -> 0 | F48: =F33+F34 -> 0 | G48: =G33+G34 -> 0 | H48: =H33+H34 -> 0 | I48: =I33+I34 -> 0 | J48: =SUM(D48:I48) -> #REF! | L48: =SUM(G48:I48) -> 0
...

Sheet CEA Attributes
A1: Method Ref | B1: CEA identification number | C1: BW_CEA_01 | D1: BW_CEA_02 | E1: BW_CEA_03 | F1: BW_CEA_04 | G1: BW_CEA_05 | H1: BW_CEA_06 | I1: BW_CEA_07
B2: Landholder / Property | C2: Dunkeld / Blackwood | D2: Dunkeld / Blackwood | E2: Dunkeld / Blackwood | F2: Dunkeld / Blackwood | G2: Dunkeld / Blackwood | H2: Dunkeld / Blackwood | I2: Dunkeld / Blackwood
B3: Date finished planting | C3: 45155 | D3: 45179 | E3: 45155 | F3: 45155 | G3: 44772 | H3: 44772 | I3: 44772
B4: Modelling Start Date | C4: 45155 | D4: 45179 | E4: 45155 | F4: 45155 | G4: 44772 | H4: 44772 | I4: 44772
B5: CEA area (ha) | C5: 8.64 | D5: 3.87 | E5: 4.12 | F5: 5.58 | G5: 9.27 | H5: 21.23 | I5: 19.11 | J5: =SUM(C5:I5) -> 71.82
B6: Exclusion area (ha) | C6: =181.3-(SUM(C5:I5)) -> 109.48
B7: Principal evidence of planting history | C7: Mgt Records | D7: Mgt Records | E7: Mgt Records | F7: Mgt Records | G7: Mgt Records | H7: Mgt Records | I7: Mgt Records
B8: Permanent planting type | C8: MSEP-Generic | D8: MSEP-Generic | E8: MSEP-Generic | F8: MSEP-Generic | G8: MSEP-Generic | H8: MSEP-Generic | I8: MSEP-Generic
A9: 1.4 | B9: Permanent planting established on or after 1 July 2007? | C9: Yes - see plant date | D9: Yes - see plant date | E9: Yes - see plant date | F9: Yes - see plant date | G9: Yes - see plant date | H9: Yes - see plant date | I9: Yes - see plant date
A10: 2.3 (3) | B10: Did not contain woody biomass that needed to be cleared prior to the planting going ahead (other than known weed species required by law to be cleared) | C10: No - refer mgt records | D10: No - refer mgt records | E10: No - refer mgt records | F10: No - refer mgt records | G10: No - refer mgt records | H10: No - refer mgt records | I10: No - refer mgt records
B11: Land clear at 1989? | C11: Yes | D11: Yes | E11: Yes | F11: Yes | G11: Yes | H11: Yes | I11: Yes
B12: Planting required by law? | C12: No | D12: No | E12: No | F12: No | G12: No | H12: No | I12: No
A13: 2.3 (4) | B13: Clear of forest cover for 5 years before planting | C13: Yes | D13: Yes | E13: Yes | F13: Yes | G13: Yes | H13: Yes | I13: Yes
A14: 2.3 (5) | B14: Project trees have the potential to attain forest cover? | C14: Yes | D14: Yes | E14: Yes | F14: Yes | G14: Yes | H14: Yes | I14: Yes
B15: Species planted | C15: Acacia acinacea, Acacia implexa, Acacia mearnsii, Acacia melanoxylon, Acacia paradoxa, Acacia pycnantha, Acacia verticillata, Allocasuarina verticillata, Banksia marginata, Bursaria spinosa, Callistemon rugulosus, Dodonaea sp., Eucalyptus camaldulensis, Eucalyptus ovata, Leptospermum continentale, Leptospermum lanigerum, Melaleuca ericifolia, Melaleuca squarrosa, and Ozothamnus ferrugineus. | D15: Acacia pycnantha, Acacia paradoxa, Leptospermum continentale, Ozothamnus ferrugineus, Callistemon rugulosus, Melaleuca squarrosa, Melaleuca ericifolia, Hakea spp., Melaleuca decussata, Leptospermum lanigerum, Acacia verticillata, Dodonaea sp., Acacia implexa, Acacia mearnsii, Acacia melanoxylon, Allocasuarina verticillata, Eucalyptus camaldulensis, Eucalyptus ovata, Eucalyptus viminalis | E15: Acacia acinacea, Acacia implexa, Acacia mearnsii, Acacia melanoxylon, Acacia paradoxa, Acacia pycnantha, Acacia verticillata, Allocasuarina verticillata, Banksia marginata, Bursaria spinosa, Callistemon rugulosus, Dodonaea sp., Eucalyptus camaldulensis, Eucalyptus ovata, Leptospermum continentale, Leptospermum lanigerum, Melaleuca ericifolia, Melaleuca squarrosa, and Ozothamnus ferrugineus. | F15: Acacia acinacea, Acacia implexa, Acacia mearnsii, Acacia melanoxylon, Acacia paradoxa, Acacia pycnantha, Acacia verticillata, Allocasuarina verticillata, Banksia marginata, Bursaria spinosa, Callistemon rugulosus, Dodonaea sp., Eucalyptus camaldulensis, Eucalyptus ovata, Leptospermum continentale, Leptospermum lanigerum, Melaleuca ericifolia, Melaleuca squarrosa, and Ozothamnus ferrugineus. | G15: Acacia exudens, Acacia implexa, Acacia mearnsii, Acacia melanoxylon, Acacia retinodes, Acacia paradoxa, Acacia pycnantha, Acacia verticillata, Allocasuarina verticillata, Bursaria spinosa, Callistemon citrinus, Callistemon rugulosus, Dodonaea viscosa cuneata, Eucalyptus camaldulensis, Eucalyptus ovata, Leptospermum continentale, Leptospermum lanigerum, Melaleuca ericifolia, Melaleuca squarrosa, and Ozothamnus ferrugineus. | H15: Acacia exudens, Acacia implexa, Acacia mearnsii, Acacia melanoxylon, Acacia retinodes, Acacia paradoxa, Acacia pycnantha, Acacia verticillata, Allocasuarina verticillata, Bursaria spinosa, Callistemon citrinus, Callistemon rugulosus, Dodonaea viscosa cuneata, Eucalyptus camaldulensis, Eucalyptus ovata, Leptospermum continentale, Leptospermum lanigerum, Melaleuca ericifolia, Melaleuca squarrosa, and Ozothamnus ferrugineus. | I15: Acacia exudens, Acacia implexa, Acacia mearnsii, Acacia melanoxylon, Acacia retinodes, Acacia paradoxa, Acacia pycnantha, Acacia verticillata, Allocasuarina verticillata, Bursaria spinosa, Callistemon citrinus, Callistemon rugulosus, Dodonaea viscosa cuneata, Eucalyptus camaldulensis, Eucalyptus ovata, Leptospermum continentale, Leptospermum lanigerum, Melaleuca ericifolia, Melaleuca squarrosa, and Ozothamnus ferrugineus.
B16: NVIS Major Vegetation Subgroups - (MVS) | C16: MVS 9; 36 and 48 | D16: MVS 9 and 48 | E16: MVS 36 and 48 | F16: MVS 9; 36; 48 and 59 | G16: MVS 9; 36; and 48 | H16: MVS 9; 36 and 48 | I16: MVS 9; and 48
B17: Soil type (Australia Soil Atlas) | C17: Rudosols | D17: Rudosols | E17: Rudosols | F17: Rudosols | G17: Rudosols | H17: Rudosols | I17: Rudosols
B18: Aspect | C18: Grazing - Varied | D18: Grazing - Varied | E18: Grazing - Varied | F18: Grazing - Varied | G18: Grazing - Varied | H18: Grazing - Varied | I18: Grazing - Varied
B19: Slope position | C19: Mid-lower | D19: Mid-lower | E19: Mid-lower | F19: Mid-lower | G19: Mid-lower | H19: Mid-lower | I19: Mid-lower
B20: Land management regime | C20: Biodiversity | D20: Biodiversity | E20: Biodiversity | F20: Biodiversity | G20: Biodiversity | H20: Biodiversity | I20: Biodiversity
B21: What are some key aspects which makes this a separate CEA to others? | C21: Planting dates | D21: Planting dates | E21: Planting dates | F21: Planting dates | G21: Planting dates | H21: Planting dates | I21: Planting dates
B22: Planting type | C22: Mixed spp. | D22: Mixed spp. | E22: Mixed spp. | F22: Mixed spp. | G22: Mixed spp. | H22: Mixed spp. | I22: Mixed spp.
B23: Planting geometry | C23: Block | D23: Block - Direct Seeding | E23: Block | F23: Block | G23: Block | H23: Block | I23: Block
B24: Planting spacing (rows, m) | C24: 4 | D24: 4.5 | E24: 4 | F24: 4 | G24: 4 | H24: 4 | I24: 4
B25: Tree spacing (m) | C25: 2.5 | D25: 4.5 | E25: 2.5 | F25: 2.5 | G25: 4 | H25: 4 | I25: 4
B26: Stocking density (assumed for modelling) | C26: <500 | D26: <500 | E26: <500 | F26: <500 | G26: <500 | H26: <500 | I26: <500
B27: Tree proportion (assumed for modelling) | C27: <75% | D27: <75% | E27: <75% | F27: <75% | G27: <75% | H27: <75% | I27: <75%
B28: Subject to competition from adjacent trees? | C28: Yes | D28: Yes | E28: Yes | F28: Yes | G28: Yes | H28: Yes | I28: Yes
B29: CEA boundary distance from stems of outermost plants | C29: 0m | D29: 0m | E29: 0m | F29: 0m | G29: 0m | H29: 0m | I29: 0m
B30: Planting Start Date | C30: 45108 | D30: 45108 | E30: 45108 | F30: 45108 | G30: 44743 | H30: 44743 | I30: 44743
B31: Planting Finish Date | C31: 45153 | D31: 45170 | E31: 45153 | F31: 45153 | G31: 44772 | H31: 44772 | I31: 44772
A32: 3.18 | B32: Average number of propagated seedling stock per ha | C32: 1043 | D32: 500 | E32: 1043 | F32: 1043 | G32: 641 | H32: 641 | I32: 641
A33: 3.18 | B33: Tree proportion of trees to shrubs at planting | C33: 0.71 | D33: 1 | E33: 0.71 | F33: 0.71 | G33: 0.86 | H33: 0.86 | I33: 0.86
A34: 3.3 (2) (c) | B34: Operations history | C34: Yes | D34: Yes | E34: Yes | F34: Yes | G34: Yes | H34: Yes | I34: Yes
A35: 3.45, 3.48 | B35: Has harvesting or thinning occurred? | C35: No | D35: No | E35: No | F35: No | G35: No | H35: No | I35: No
A36: 3.47 | B36: Has grazing affected forest cover? | C36: No | D36: No | E36: No | F36: No | G36: No | H36: No | I36: No
A37: 3.49 | B37: Use of lime or fertilizer | C37: No | D37: No | E37: No | F37: No | G37: No | H37: No | I37: No
B38: Disturbance events including fire | C38: No | D38: No | E38: No | F38: No | G38: No | H38: No | I38: No
B39: Survival | C39: 0.828 | D39: 1 | E39: 0.828 | F39: 0.828 | G39: 0.856 | H39: 0.856 | I39: 0.856
B40: Simple calculation of future crown cover assuming radius of 2m | C40: =(PI()*2^2*C32*C39)/10000 -> 1.0852368 | D40: =(PI()*2^2*D32*D39)/10000 -> 0.62831853 | E40: =(PI()*2^2*E32*E39)/10000 -> 1.0852368 | F40: =(PI()*2^2*F32*F39)/10000 -> 1.0852368 | G40: =(PI()*2^2*G32*G39)/10000 -> 0.68951173 | H40: =(PI()*2^2*H32*H39)/10000 -> 0.68951173 | I40: =(PI()*2^2*I32*I39)/10000 -> 0.68951173
...

Sheet Abatement
A4: CEA Name | B4: FullCAM calibration used | C4: CEA area (ha) | D4: Initial carbon mass trees - CDt (t C /ha) | E4: Initial carbon mass debris - CDd (t C /ha) | F4: Initial carbon mass - CD (t C) | G4: End carbon mass trees - Ct (t C /ha) | H4: End carbon mass debris - Cd (t C /ha) | I4: End carbon mass - C (t C)
A5: BW_CEA_01 | B5: Mixed species environmental planting - Generic | C5: ='CEA Attributes'!C5 -> 8.64 | D5: 0 | E5: 0 | F5: =(D5+E5)*C5 -> 0 | G5: =BW_CEA_01!E37 -> 5.8838588 | H5: =BW_CEA_01!F37 -> 0.2989268 | I5: =(H5+G5)*C5 -> 53.419268
A6: BW_CEA_02 | B6: Mixed species environmental planting - Generic | C6: ='CEA Attributes'!D5 -> 3.87 | D6: 0 | E6: 0 | F6: =(D6+E6)*C6 -> 0 | G6: =BW_CEA_02!E36 -> 5.5329787 | H6: =BW_CEA_02!F36 -> 0.27471105 | I6: =(H6+G6)*C6 -> 22.475759
A7: BW_CEA_03 | B7: Mixed species environmental planting - Generic | C7: ='CEA Attributes'!E5 -> 4.12 | D7: 0 | E7: 0 | F7: =(D7+E7)*C7 -> 0 | G7: =BW_CEA_03!E37 -> 6.0023523 | H7: =BW_CEA_03!F37 -> 0.30422243 | I7: =(H7+G7)*C7 -> 25.983088
A8: BW_CEA_04 | B8: Mixed species environmental planting - Generic | C8: ='CEA Attributes'!F5 -> 5.58 | D8: 0 | E8: 0 | F8: =(D8+E8)*C8 -> 0 | G8: =BW_CEA_04!E37 -> 4.6033907 | H8: =BW_CEA_04!F37 -> 0.23859219 | I8: =(H8+G8)*C8 -> 27.018264
A9: BW_CEA_05 | B9: Mixed species environmental planting - Generic | C9: ='CEA Attributes'!G5 -> 9.27 | D9: 0 | E9: 0 | F9: =(D9+E9)*C9 -> 0 | G9: =BW_CEA_05!E50 -> 10.134726 | H9: =BW_CEA_05!F50 -> 0.70890114 | I9: =(H9+G9)*C9 -> 100.52042
A10: BW_CEA_06 | B10: Mixed species environmental planting - Generic | C10: ='CEA Attributes'!H5 -> 21.23 | D10: 0 | E10: 0 | F10: =(D10+E10)*C10 -> 0 | G10: =BW_CEA_06!E50 -> 9.954901 | H10: =BW_CEA_06!F50 -> 0.6967679 | I10: =(H10+G10)*C10 -> 226.13493 | J10: Total Check
A11: BW_CEA_07 | B11: Mixed species environmental planting - Generic | C11: ='CEA Attributes'!I5 -> 19.11 | D11: 0 | E11: 0 | F11: =(D11+E11)*C11 -> 0 | G11: =BW_CEA_07!E50 -> 8.8168756 | H11: =BW_CEA_07!F50 -> 0.6201545 | I11: =(H11+G11)*C11 -> 180.34165 | J11: =SUM(I5:I11) -> 635.89337 | K11: tC
E14: Initial carbon stock CN (tCO2e) | F14: =SUM(F5:F11)*44/12 -> 0 | H14: End carbon stock CP (tCO2e) | I14: =SUM(I5:I11)*44/12 -> 2331.609
H15: Equation 11b
H17: Total ACCUs | I17: =I14-F14 -> 2331.609

Sheet Project Emissions
A2: Division 5.4; Section 5.8(c)
A4: CEA Name | B4: FullCAM calibration used | C4: CEA area (ha) | D4: CH4 Emissions - ECH4 (t CH4/ha) | E4: CH4 Emissions - EBCH4 (t CH4) | F4: N2O Emmissions - EN2O (t N2O/ha) | G4: N2O Emmissions - EBN2O (t N2O)
A5: BW_CEA_01 | B5: Mixed species environmental planting - Generic | C5: ='CEA Attributes'!C5 -> 8.64 | D5: =BW_CEA_01!G25 -> 0 | E5: =D5*C5 -> 0 | F5: =BW_CEA_01!H24 -> 0 | G5: =F5*C5 -> 0
A6: BW_CEA_02 | B6: Mixed species environmental planting - Generic | C6: ='CEA Attributes'!D5 -> 3.87 | D6: =BW_CEA_02!G25 -> 0 | E6: =D6*C6 -> 0 | F6: =BW_CEA_02!H23 -> 0 | G6: =F6*C6 -> 0
A7: BW_CEA_03 | B7: Mixed species environmental planting - Generic | C7: ='CEA Attributes'!E5 -> 4.12 | D7: =BW_CEA_03!G25 -> 0 | E7: =D7*C7 -> 0 | F7: =BW_CEA_03!H23 -> 0 | G7: =F7*C7 -> 0
A8: BW_CEA_04 | B8: Mixed species environmental planting - Generic | C8: ='CEA Attributes'!F5 -> 5.58 | D8: =BW_CEA_01!G25 -> 0 | E8: =D8*C8 -> 0 | F8: =BW_CEA_01!H24 -> 0 | G8: =F8*C8 -> 0
A9: BW_CEA_05 | B9: Mixed species environmental planting - Generic | C9: ='CEA Attributes'!G5 -> 9.27 | D9: =BW_CEA_02!G25 -> 0 | E9: =D9*C9 -> 0 | F9: =BW_CEA_02!H24 -> 0 | G9: =F9*C9 -> 0
A10: BW_CEA_06 | B10: Mixed species environmental planting - Generic | C10: ='CEA Attributes'!H5 -> 21.23 | D10: =BW_CEA_01!G37 -> 0 | E10: =D10*C10 -> 0 | F10: =BW_CEA_01!H38 -> 0 | G10: =F10*C10 -> 0
A11: BW_CEA_07 | B11: Mixed species environmental planting - Generic | C11: ='CEA Attributes'!I5 -> 19.11 | D11: =BW_CEA_02!G37 -> 0 | E11: =D11*C11 -> 0 | F11: =BW_CEA_02!H38 -> 0 | G11: =F11*C11 -> 0
D14: Gl Warm Pot CH4 | E14: 28 | F14: Gl Warm Pot NO2 | G14: 265
D16: Equation 13 | E16: =SUM(E7:E12)*E14 -> 0 | F16: Equation 14 | G16: =SUM(G7:G12)*G14/1000 -> 0
F18: Equation 15 | G18: =G16+E16 -> 0

Sheet Global Warm Pot

Sheet Fuel Emissions
A2: Division 5.4; Section 5.8(d)
B4: Diesel use - fore each hectare assume:
B5: Ripping, Mound and Direct Seeding (all events) | D5: One time per CEA
B6: Fuel consumption 2022 and 2023 (L) | D6: ='Fuel Reference previous report'!F10 -> 2855.16 | E6: Estimated time/consuption | F6: 72% Invoices related to Blackwood ERF REGO - see calculation Tab CEA Attributes H11
B8: Petrol use - Fore each property, assume:
B9: Site visit frequency (visits/yr) | D9: 4
B10: Travel distance/site visit (km) | D10: 40
B11: Fuel consumption of (km/l) | D11: 10
B12: Fuel consumption/site visit (litres) | D12: =D10/D11 -> 4
B13: Reporting period (years) | D13: 2
B15: Qf - Total diesel (kL) | D15: =(D6)/1000 -> 2.85516 | H15: Qf - Total diesel (kL) | J15: 0
B16: Qf - Total gasoline (kL) | D16: =(D12*D9*D13)/1000 -> 0.032 | H16: Qf - Total gasoline (kL) | J16: 0
B18: Fuel emission for each fuel type and greenhouse gas for the project - Equation 16
C20: Fuel emissions (t CO2e)
C21: CO2 | D21: CH4 | E21: N2O | F21: Total CO2e
B22: Ef,diesel | C22: =$D$15*$C$36*D36/1000 -> 7.7036214 | D22: =$D$15*$C$36*E36/1000 -> 0.011020918 | E22: =$D$15*$C$36*F36/1000 -> 0.055104588 | F22: =SUM(C22:E22) -> 7.7697469
B23: Ef,gasoline | C23: =$D$16*$C$35*D35/1000 -> 0.07376256 | D23: =$D$16*$C$35*E35/1000 -> 0.0005472 | E23: =$D$16*$C$35*F35/1000 -> 0.00196992 | F23: =SUM(C23:E23) -> 0.07627968
B25: Total project fuel emissions for the reporting period - Equation 17
B26: Ef - Total project fuel emssions for the 1st reporting period= | E26: =F22+F23 -> 7.8460266 | F26: tonnes of CO2e | H26: Ef - Total project fuel emssions for the 2nd reporting period= | M26: 0 | N26: tonnes of CO2e
A30: Fuel combustion—fuels for transport energy purposes
A31: Item | B31: Fuel combusted | C31: Energy content factor | D31: Emission factor
C32: (GJ/kL unless otherwise indicated) | D32: kg CO2‑e/GJ
D33: (relevant oxidation factors incorporated)
D34: CO2 | E34: CH4 | F34: N2O
A35: 35 | B35: Gasoline (other than for use as fuel in an aircraft) | C35: 34.2 | D35: 67.4 | E35: 0.5 | F35: 1.8
A36: 40 | B36: Diesel oil | C36: 38.6 | D36: 69.9 | E36: 0.1 | F36: 0.5
A39: Proportion of fuel emmissions by CEA
A40: CEA Name | B40: FullCAM calibration used | C40: CEA area (ha) | D40: Proportion of Fuel emissions
A41: =Abatement!A5 -> BW_CEA_01 | B41: =Abatement!B5 -> Mixed species environmental planting - Generic | C41: =Abatement!C5 -> 8.64 | D41: =C41/$C$48*$E$26 -> 0.9438829
A42: =Abatement!A6 -> BW_CEA_02 | B42: =Abatement!B6 -> Mixed species environmental planting - Generic | C42: =Abatement!C6 -> 3.87 | D42: =C42/$C$48*$E$26 -> 0.42278088
A43: =Abatement!A7 -> BW_CEA_03 | B43: =Abatement!B7 -> Mixed species environmental planting - Generic | C43: =Abatement!C7 -> 4.12 | D43: =C43/$C$48*$E$26 -> 0.45009231
A44: =Abatement!A8 -> BW_CEA_04 | B44: =Abatement!B8 -> Mixed species environmental planting - Generic | C44: =Abatement!C8 -> 5.58 | D44: =C44/$C$48*$E$26 -> 0.60959104
A45: =Abatement!A9 -> BW_CEA_05 | B45: =Abatement!B9 -> Mixed species environmental planting - Generic | C45: =Abatement!C9 -> 9.27 | D45: =C45/$C$48*$E$26 -> 1.0127077
A46: =Abatement!A10 -> BW_CEA_06 | B46: =Abatement!B10 -> Mixed species environmental planting - Generic | C46: =Abatement!C10 -> 21.23 | D46: =C46/$C$48*$E$26 -> 2.3192863
A47: =Abatement!A11 -> BW_CEA_07 | B47: =Abatement!B11 -> Mixed species environmental planting - Generic | C47: =Abatement!C11 -> 19.11 | D47: =C47/$C$48*$E$26 -> 2.0876854
A48: Total | C48: =SUM(C41:C47) -> 71.82 | D48: =SUM(D41:D47) -> 7.8460266

Sheet Fuel Reference previous report
A1: Equipment Emission Estimation (Diesel) - soil preparation + installation works (2022 and 2023 - Machinery Service Invoice ) | D1: Time (h) | E1: Eficienc. | F1: Diesel (L)
A2: Ripping Tractor: Brand: Steiger 225HP - Diesel Fuel Consumption average 20L/Hr | D2: 71 | E2: 20 | F2: =D2*E2 -> 1420
A4: Mounding Tractor: Brand CLAAS: 110 HP - Diesel Fuel Consumption Average 15L/Hr | D4: 71 | E4: 15 | F4: =D4*E4 -> 1065
A6: Direct Seeding: John Deere 32HP (Series 3 Utility Tractor) - Diesel Fuel Consumption Average: 4.5L/Hr | D6: 9 | E6: 4.5 | F6: =D6*E6 -> 40.5
A8: Spraying - DPC - John Deere 6125M - 120HP - Diesel Fuel Consumption Average 18L/Hr | D8: 80 | E8: 18 | F8: =D8*E8 -> 1440
D10: TOTAL (L) | F10: =SUM(F2:F8)*0.72 -> 2855.16 | G10: considering 72% related to Blackwood ERF REGO | K10: =I15 -> 0.71621891
A11: Ripping and Mounding Invoice
F14: Planted 22 | G14: Planted 23 | H14: Area ERF REGO | I14: % / Project
D15: Blackwood | F15: 56.66 | G15: 28.57 | H15: 71.98 | I15: =H15/F18 -> 0.71621891
D16: Devon Park | F16: 2.27 | G16: 13 | H16: 5.78 | I16: =H16/F18 -> 0.057512438
D17: TOTAL | F17: =SUM(F15:F16) -> 58.93 | G17: =SUM(G15:G16) -> 41.57
A18: Direct Seeding invoice IV0655 | D18: TOTAL Planted 22/23 | F18: =F17+G17 -> 100.5 | H18: ha
A27: Weeding spot-spray -Knockdown 80h estimated

Sheet Tree Seedlings
A1: BW Planted Areas | C1: Tot Area | D1: %
A2: CEA 1 | B2: 5.55 | C2: =SUM(B2:B6) -> 24.65 | D2: =C2/(C2+B12) -> 0.78378378
A3: CEA 2 | B3: 9.07
A4: CEA 3
A5: CEA 4 | B5: 4.19
A6: CEA 5 | B6: 5.84
A7: CEA 6 | B7: 9.54 | C7: =SUM(B7:B9) -> 56.54 | D7: =C7/(C7+B13) -> 0.81223962
A8: CEA 7 | B8: 22.86
A9: CEA 8 | B9: 24.14
A10: TOTAL | B10: =SUM(B2:B9) -> 81.19 | C10: Original Planted Areas DP+BW | F10: Tree Survival Count 2024 - Devon Park + Blackwood | H10: Total Planted | I10: Current 2024 counting | J10: Survival Rate (%)
B11: DP (ha) | C11: BW (ha) | D11: Tot (ha) | G11: Units | H11: Stems/ha | I11: Stems/ha
A12: Planted 2023 | B12: 6.8 | C12: =C7 -> 56.54 | D12: =B12+C12 -> 63.34 | F12: Invoice Trees 2022 | G12: 40600 | H12: =G12/D12 -> 640.98516 | I12: 549 | J12: =I12/H12 -> 0.85649409
A13: Planted 2022 | B13: 13.07 | C13: =C2 -> 24.65 | D13: =B13+C13 -> 37.72 | F13: Invoice Trees 2023 | G13: 39352 | H13: =G13/D13 -> 1043.2662 | I13: =745 -> 745 | J13: =I13/H13 -> 0.71410348
D14: =SUM(D12:D13) -> 101.06

Sheet BW_CEA_01
A1: FullCAM: Output from Plot Simulation
A2: FullCAM Version 6.20.03.0827 (2020 PR)
A3: FullCAM Plot : Blackwood_ EP_CEA 02_Report 1.plo
A4: Output window name: Output 2
A5: Monday, ‎19 September ‎2024, 12:11:23 AM
A6: Each line reports the simulation state at the END of the step on that line.
A8: Year | B8: Month | C8: Day | D8: Dec. Year | E8: C mass of trees | F8: C mass of forest debris | G8: CH4 emitted due to fire | H8: N2O emitted due to fire | I8: C mass of trees+debris
D9: tCH4/ha | E9: tC/ha | F9: tN2O/ha | G9: tC/ha | I9: tC/ha
A10: 2023 | B10: 8 | C10: 16 | D10: 2023.6247 | E10: 0 | F10: 0 | G10: 0 | H10: 0 | I10: =E10+F10 -> 0
A11: 2023 | B11: 8 | C11: 31 | D11: 2023.6658 | E11: 0.29370032 | F11: 0.0029271181 | G11: 0 | H11: 0 | I11: =E11+F11 -> 0.29662744
A12: 2023 | B12: 9 | C12: 30 | D12: 2023.7479 | E12: 0.29372559 | F12: 0.0060798677 | G12: 0 | H12: 0 | I12: =E12+F12 -> 0.29980546
A13: 2023 | B13: 10 | C13: 31 | D13: 2023.8329 | E13: 0.29414854 | F13: 0.0080898383 | G13: 0 | H13: 0 | I13: =E13+F13 -> 0.30223838
A14: 2023 | B14: 11 | C14: 30 | D14: 2023.9151 | E14: 0.29672995 | F14: 0.0098268826 | G14: 0 | H14: 0 | I14: =E14+F14 -> 0.30655683
A15: 2023 | B15: 12 | C15: 31 | D15: 2024 | E15: 0.30654308 | F15: 0.011619907 | G15: 0 | H15: 0 | I15: =E15+F15 -> 0.31816299
A16: 2024 | B16: 1 | C16: 31 | D16: 2024.0847 | E16: 0.33219066 | F16: 0.013715515 | G16: 0 | H16: 0 | I16: =E16+F16 -> 0.34590617
A17: 2024 | B17: 2 | C17: 29 | D17: 2024.1639 | E17: 0.38042865 | F17: 0.016436434 | G17: 0 | H17: 0 | I17: =E17+F17 -> 0.39686508
A18: 2024 | B18: 3 | C18: 31 | D18: 2024.2486 | E18: 0.46917406 | F18: 0.018382668 | G18: 0 | H18: 0 | I18: =E18+F18 -> 0.48755673
A19: 2024 | B19: 4 | C19: 30 | D19: 2024.3306 | E19: 0.60167897 | F19: 0.020854983 | G19: 0 | H19: 0 | I19: =E19+F19 -> 0.62253396
A20: 2024 | B20: 5 | C20: 31 | D20: 2024.4153 | E20: 0.79531927 | F20: 0.024553368 | G20: 0 | H20: 0 | I20: =E20+F20 -> 0.81987263
A21: 2024 | B21: 6 | C21: 30 | D21: 2024.4973 | E21: 1.0433168 | F21: 0.029719382 | G21: 0 | H21: 0 | I21: =E21+F21 -> 1.0730361
... A23: 2024 | B23: 8 | C23: 31 | D23: 2024.6667 | E23: 1.6602138 | F23: 0.045775758 | G23: 0 | H23: 0 | I23: =E23+F23 -> 1.7059896
A24: 2024 | B24: 9 | C24: 30 | D24: 2024.7486 | E24: 1.8658792 | F24: 0.0555721 | G24: 0 | H24: 0 | I24: =E24+F24 -> 1.9214513 | K24: Year | L24: Month | M24: Trees+Debris | N24: Area | O24: Abatement (t C) | P24: Aabtement (tCO2) | Q24: Fuel Emissions tCO2e | R24: Net Abatement (tCO2e)
A25: 2024 | B25: 10 | C25: 31 | D25: 2024.8333 | E25: 2.0948109 | F25: 0.066830433 | G25: 0 | H25: 0 | I25: =E25+F25 -> 2.1616413 | K25: =A21 -> 2024 | L25: =B33 -> 6 | M25: =I33 -> 4.6059713 | N25: =Abatement!$C$5 -> 8.64 | O25: =M25*N25 -> 39.795592 | P25: =O25*44/12 -> 145.91717 | Q25: ='Fuel Emissions'!$D$41 -> 0.9438829 | R25: =P25-Q25 -> 144.97329
A26: 2024 | B26: 11 | C26: 30 | D26: 2024.9153 | E26: 2.3319407 | F26: 0.07909991 | G26: 0 | H26: 0 | I26: =E26+F26 -> 2.4110406 | K26: 2025 | L26: 6 | M26: =I33 -> 4.6059713 | N26: =Abatement!$C$5 -> 8.64 | O26: =M26*N26 -> 39.795592 | P26: =O26*44/12 -> 145.91717 | Q26: ='Fuel Emissions'!$D$41 -> 0.9438829 | R26: =P26-Q26 -> 144.97329
A27: 2024 | B27: 12 | C27: 31 | D27: 2025 | E27: 2.5926924 | F27: 0.093317203 | G27: 0 | H27: 0 | I27: =E27+F27 -> 2.6860096 | K27: 2026 | L27: 6 | M27: =I45 -> 9.7782024 | N27: =Abatement!$C$5 -> 8.64 | O27: =M27*N27 -> 84.483668 | P27: =O27*44/12 -> 309.77345 | Q27: ='Fuel Emissions'!$D$41 -> 0.9438829 | R27: =P27-Q27 -> 308.82957
A28: 2025 | B28: 1 | C28: 31 | D28: 2025.0849 | E28: 2.8689657 | F28: 0.10977843 | G28: 0 | H28: 0 | I28: =E28+F28 -> 2.9787442 | K28: 2027 | L28: 6 | M28: =I57 -> 15.952055 | N28: =Abatement!$C$5 -> 8.64 | O28: =M28*N28 -> 137.82576 | P28: =O28*44/12 -> 505.36111 | Q28: ='Fuel Emissions'!$D$41 -> 0.9438829 | R28: =P28-Q28 -> 504.41722
A29: 2025 | B29: 2 | C29: 28 | D29: 2025.1616 | E29: 3.1314206 | F29: 0.1277733 | G29: 0 | H29: 0 | I29: =E29+F29 -> 3.2591939 | K29: 2028 | L29: 6 | M29: =I69 -> 22.508402 | N29: =Abatement!$C$5 -> 8.64 | O29: =M29*N29 -> 194.47259 | P29: =O29*44/12 -> 713.06616 | Q29: ='Fuel Emissions'!$D$41 -> 0.9438829 | R29: =P29-Q29 -> 712.12228
A30: 2025 | B30: 3 | C30: 31 | D30: 2025.2466 | E30: 3.4357913 | F30: 0.14389462 | G30: 0 | H30: 0 | I30: =E30+F30 -> 3.5796859 | K30: 2029 | L30: 6 | M30: =I81 -> 29.040321 | N30: =Abatement!$C$5 -> 8.64 | O30: =M30*N30 -> 250.90837 | P30: =O30*44/12 -> 919.99737 | Q30: ='Fuel Emissions'!$D$41 -> 0.9438829 | R30: =P30-Q30 -> 919.05349
A31: 2025 | B31: 4 | C31: 30 | D31: 2025.3288 | E31: 3.7436174 | F31: 0.16013254 | G31: 0 | H31: 0 | I31: =E31+F31 -> 3.90375 | K31: 2030 | L31: 6 | M31: =I93 -> 35.367373 | N31: =Abatement!$C$5 -> 8.64 | O31: =M31*N31 -> 305.5741 | P31: =O31*44/12 -> 1120.4384 | Q31: ='Fuel Emissions'!$D$41 -> 0.9438829 | R31: =P31-Q31 -> 1119.4945
A32: 2025 | B32: 5 | C32: 31 | D32: 2025.4137 | E32: 4.0748328 | F32: 0.17848165 | G32: 0 | H32: 0 | I32: =E32+F32 -> 4.2533145 | K32: 2031 | L32: 6 | M32: =I105 -> 41.391468 | N32: =Abatement!$C$5 -> 8.64 | O32: =M32*N32 -> 357.62229 | P32: =O32*44/12 -> 1311.2817 | Q32: ='Fuel Emissions'!$D$41 -> 0.9438829 | R32: =P32-Q32 -> 1310.3378
A33: 2025 | B33: 6 | C33: 30 | D33: 2025.4959 | E33: 4.407491 | F33: 0.19848025 | G33: 0 | H33: 0 | I33: =E33+F33 -> 4.6059713 | K33: 2032 | L33: 6 | M33: =I117 -> 47.084672 | N33: =Abatement!$C$5 -> 8.64 | O33: =M33*N33 -> 406.81157 | P33: =O33*44/12 -> 1491.6424 | Q33: ='Fuel Emissions'!$D$41 -> 0.9438829 | R33: =P33-Q33 -> 1490.6985
A34: 2025 | B34: 7 | C34: 31 | D34: 2025.5808 | E34: 4.7631559 | F34: 0.22063028 | G34: 0 | H34: 0 | I34: =E34+F34 -> 4.9837861 | K34: 2033 | L34: 6 | M34: =I129 -> 52.406334 | N34: =Abatement!$C$5 -> 8.64 | O34: =M34*N34 -> 452.79073 | P34: =O34*44/12 -> 1660.2327 | Q34: ='Fuel Emissions'!$D$41 -> 0.9438829 | R34: =P34-Q34 -> 1659.2888
A35: 2025 | B35: 8 | C35: 31 | D35: 2025.6658 | E35: 5.1303066 | F35: 0.2444958 | G35: 0 | H35: 0 | I35: =E35+F35 -> 5.3748024
A36: 2025 | B36: 9 | C36: 30 | D36: 2025.7479 | E36: 5.4959529 | F36: 0.27019522 | G36: 0 | H36: 0 | I36: =E36+F36 -> 5.7661482
A37: 2025 | B37: 10 | C37: 31 | D37: 2025.8329 | E37: 5.8838588 | F37: 0.2989268 | G37: 0 | H37: 0 | I37: =E37+F37 -> 6.1827856
A38: 2025 | B38: 11 | C38: 30 | D38: 2025.9151 | E38: 6.2684192 | F38: 0.32910317 | G38: 0 | H38: 0 | I38: =E38+F38 -> 6.5975224
A39: 2025 | B39: 12 | C39: 31 | D39: 2026 | E39: 6.6746775 | F39: 0.36278935 | G39: 0 | H39: 0 | I39: =E39+F39 -> 7.0374668
A40: 2026 | B40: 1 | C40: 31 | D40: 2026.0849 | E40: 7.0893697 | F40: 0.40048431 | G40: 0 | H40: 0 | I40: =E40+F40 -> 7.489854
A41: 2026 | B41: 2 | C41: 28 | D41: 2026.1616 | E41: 7.470695 | F41: 0.44062953 | G41: 0 | H41: 0 | I41: =E41+F41 -> 7.9113245
A42: 2026 | B42: 3 | C42: 31 | D42: 2026.2466 | E42: 7.8998447 | F42: 0.47477659 | G42: 0 | H42: 0 | I42: =E42+F42 -> 8.3746213
...

Sheet BW_CEA_02
A1: FullCAM: Output from Plot Simulation
A2: FullCAM Version 6.20.03.0827 (2020 PR)
A3: FullCAM Plot : Blackwood_ EP_CEA 03_Report 1.plo
A4: Output window name: Output 2
A5: Monday, ‎19 September ‎2024, 12:32:23 AM
A6: Each line reports the simulation state at the END of the step on that line.
A8: Year | B8: Month | C8: Day | D8: Dec. Year | E8: C mass of trees | F8: C mass of forest debris | G8: CH4 emitted due to fire | H8: N2O emitted due to fire | I8: C mass of trees+debris
D9: tC/ha | E9: tCH4/ha | F9: tN2O/ha | G9: tC/ha | I9: tC/ha
A10: 2023 | B10: 9 | C10: 9 | D10: 2023.6904 | E10: 0 | F10: 0 | G10: 0 | H10: 0 | I10: =E10+F10 -> 0
A11: 2023 | B11: 9 | C11: 30 | D11: 2023.7479 | E11: 0.29370092 | F11: 0.0037913221 | G11: 0 | H11: 0 | I11: =E11+F11 -> 0.29749225
A12: 2023 | B12: 10 | C12: 31 | D12: 2023.8329 | E12: 0.29375397 | F12: 0.0066636159 | G12: 0 | H12: 0 | I12: =E12+F12 -> 0.30041759
A13: 2023 | B13: 11 | C13: 30 | D13: 2023.9151 | E13: 0.29438665 | F13: 0.0085959342 | G13: 0 | H13: 0 | I13: =E13+F13 -> 0.30298259
A14: 2023 | B14: 12 | C14: 31 | D14: 2024 | E14: 0.29802203 | F14: 0.010406331 | G14: 0 | H14: 0 | I14: =E14+F14 -> 0.30842836
A15: 2024 | B15: 1 | C15: 31 | D15: 2024.0847 | E15: 0.31041989 | F15: 0.012406006 | G15: 0 | H15: 0 | I15: =E15+F15 -> 0.3228259
A16: 2024 | B16: 2 | C16: 29 | D16: 2024.1639 | E16: 0.33812514 | F16: 0.014888989 | G16: 0 | H16: 0 | I16: =E16+F16 -> 0.35301413
A17: 2024 | B17: 3 | C17: 31 | D17: 2024.2486 | E17: 0.39574846 | F17: 0.01641286 | G17: 0 | H17: 0 | I17: =E17+F17 -> 0.41216132
A18: 2024 | B18: 4 | C18: 30 | D18: 2024.3306 | E18: 0.48985109 | F18: 0.018291146 | G18: 0 | H18: 0 | I18: =E18+F18 -> 0.50814223
A19: 2024 | B19: 5 | C19: 31 | D19: 2024.4153 | E19: 0.63685506 | F19: 0.021126882 | G19: 0 | H19: 0 | I19: =E19+F19 -> 0.65798194
A20: 2024 | B20: 6 | C20: 30 | D20: 2024.4973 | E20: 0.83487893 | F20: 0.025177833 | G20: 0 | H20: 0 | I20: =E20+F20 -> 0.86005676
A21: 2024 | B21: 7 | C21: 31 | D21: 2024.582 | E21: 1.1024794 | F21: 0.030820697 | G21: 0 | H21: 0 | I21: =E21+F21 -> 1.1333001 | K21: Year | L21: Month | M21: Trees+Debris | N21: Area | O21: Abatement (t C) | P21: Aabtement (tCO2) | Q21: Fuel Emissions tCO2e | R21: Net Abatement (tCO2e)
A22: 2024 | B22: 8 | C22: 31 | D22: 2024.6667 | E22: 1.4369313 | F22: 0.038326233 | G22: 0 | H22: 0 | I22: =E22+F22 -> 1.4752576 | K22: =A18 -> 2024 | L22: 6 | M22: =I21 -> 1.1333001 | N22: =Abatement!$C$6 -> 3.87 | O22: =M22*N22 -> 4.3858714 | P22: =O22*44/12 -> 16.081528 | Q22: ='Fuel Emissions'!$D$42 -> 0.42278088 | R22: =P22-Q22 -> 15.658748
A23: 2024 | B23: 9 | C23: 30 | D23: 2024.7486 | E23: 1.6868718 | F23: 0.04753421 | G23: 0 | H23: 0 | I23: =E23+F23 -> 1.734406 | K23: 2025 | L23: 6 | M23: =I33 -> 4.6481723 | N23: =Abatement!$C$6 -> 3.87 | O23: =M23*N23 -> 17.988427 | P23: =O23*44/12 -> 65.957566 | R23: =P23-Q23 -> 65.957566
A24: 2024 | B24: 10 | C24: 31 | D24: 2024.8333 | E24: 1.9008817 | F24: 0.057925117 | G24: 0 | H24: 0 | I24: =E24+F24 -> 1.9588068 | K24: 2026 | L24: 6 | M24: =I45 -> 9.7970223 | N24: =Abatement!$C$6 -> 3.87 | O24: =M24*N24 -> 37.914476 | P24: =O24*44/12 -> 139.01975 | R24: =P24-Q24 -> 139.01975
A25: 2024 | B25: 11 | C25: 30 | D25: 2024.9153 | E25: 2.1236649 | F25: 0.06919599 | G25: 0 | H25: 0 | I25: =E25+F25 -> 2.1928609 | K25: 2027 | L25: 6 | M25: =I57 -> 15.922318 | N25: =Abatement!$C$6 -> 3.87 | O25: =M25*N25 -> 61.619371 | P25: =O25*44/12 -> 225.93769 | R25: =P25-Q25 -> 225.93769
A26: 2024 | B26: 12 | C26: 31 | D26: 2025 | E26: 2.3697482 | F26: 0.08225714 | G26: 0 | H26: 0 | I26: =E26+F26 -> 2.4520053 | K26: 2028 | L26: 6 | M26: =I66 -> 20.799087 | N26: =Abatement!$C$6 -> 3.87 | O26: =M26*N26 -> 80.492466 | P26: =O26*44/12 -> 295.13904 | R26: =P26-Q26 -> 295.13904
A27: 2025 | B27: 1 | C27: 31 | D27: 2025.0849 | E27: 2.6315636 | F27: 0.097438996 | G27: 0 | H27: 0 | I27: =E27+F27 -> 2.7290026 | K27: 2029 | L27: 6 | M27: =I81 -> 28.880983 | N27: =Abatement!$C$6 -> 3.87 | O27: =M27*N27 -> 111.76941 | P27: =O27*44/12 -> 409.82115 | R27: =P27-Q27 -> 409.82115
A28: 2025 | B28: 2 | C28: 28 | D28: 2025.1616 | E28: 2.8811772 | F28: 0.11408707 | G28: 0 | H28: 0 | I28: =E28+F28 -> 2.9952643 | K28: 2030 | L28: 6 | M28: =I94 -> 35.64503 | N28: =Abatement!$C$6 -> 3.87 | O28: =M28*N28 -> 137.94627 | P28: =O28*44/12 -> 505.80297 | R28: =P28-Q28 -> 505.80297
A29: 2025 | B29: 3 | C29: 31 | D29: 2025.2466 | E29: 3.171605 | F29: 0.12898959 | G29: 0 | H29: 0 | I29: =E29+F29 -> 3.3005946 | K29: 2031 | L29: 6 | M29: =I105 -> 41.096355 | N29: =Abatement!$C$6 -> 3.87 | O29: =M29*N29 -> 159.04289 | P29: =O29*44/12 -> 583.15727 | R29: =P29-Q29 -> 583.15727
A30: 2025 | B30: 4 | C30: 30 | D30: 2025.3288 | E30: 3.4662392 | F30: 0.14412843 | G30: 0 | H30: 0 | I30: =E30+F30 -> 3.6103677 | K30: 2032 | L30: 6 | M30: =I117 -> 46.724913 | N30: =Abatement!$C$6 -> 3.87 | O30: =M30*N30 -> 180.82541 | P30: =O30*44/12 -> 663.02652 | R30: =P30-Q30 -> 663.02652
A31: 2025 | B31: 5 | C31: 31 | D31: 2025.4137 | E31: 3.7841571 | F31: 0.16127604 | G31: 0 | H31: 0 | I31: =E31+F31 -> 3.9454332 | K31: 2033 | L31: 6 | M31: =I129 -> 51.985281 | N31: =Abatement!$C$6 -> 3.87 | O31: =M31*N31 -> 201.18304 | P31: =O31*44/12 -> 737.67113 | R31: =P31-Q31 -> 737.67113
A32: 2025 | B32: 6 | C32: 30 | D32: 2025.4959 | E32: 4.1042867 | F32: 0.17999741 | G32: 0 | H32: 0 | I32: =E32+F32 -> 4.2842841
A33: 2025 | B33: 7 | C33: 31 | D33: 2025.5808 | E33: 4.4473694 | F33: 0.20080295 | G33: 0 | H33: 0 | I33: =E33+F33 -> 4.6481723
A34: 2025 | B34: 8 | C34: 31 | D34: 2025.6658 | E34: 4.8023168 | F34: 0.22328277 | G34: 0 | H34: 0 | I34: =E34+F34 -> 5.0255995
A35: 2025 | B35: 9 | C35: 30 | D35: 2025.7479 | E35: 5.1565189 | F35: 0.24752598 | G35: 0 | H35: 0 | I35: =E35+F35 -> 5.4040448
A36: 2025 | B36: 10 | C36: 31 | D36: 2025.8329 | E36: 5.5329787 | F36: 0.27471105 | G36: 0 | H36: 0 | I36: =E36+F36 -> 5.8076897
A37: 2025 | B37: 11 | C37: 30 | D37: 2025.9151 | E37: 5.9068291 | F37: 0.30330404 | G37: 0 | H37: 0 | I37: =E37+F37 -> 6.2101331
A38: 2025 | B38: 12 | C38: 31 | D38: 2026 | E38: 6.3023965 | F38: 0.3352228 | G38: 0 | H38: 0 | I38: =E38+F38 -> 6.6376193
A39: 2026 | B39: 1 | C39: 31 | D39: 2026.0849 | E39: 6.7067755 | F39: 0.37102539 | G39: 0 | H39: 0 | I39: =E39+F39 -> 7.0778009
A40: 2026 | B40: 2 | C40: 28 | D40: 2026.1616 | E40: 7.079105 | F40: 0.40919795 | G40: 0 | H40: 0 | I40: =E40+F40 -> 7.4883029
A41: 2026 | B41: 3 | C41: 31 | D41: 2026.2466 | E41: 7.4986415 | F41: 0.44167072 | G41: 0 | H41: 0 | I41: =E41+F41 -> 7.9403122
...

Sheet BW_CEA_03
A1: FullCAM: Output from Plot Simulation
A2: FullCAM Version 6.20.03.0827 (2020 PR)
A3: FullCAM Plot : Blackwood_ EP_CEA 04_Report 1.plo
A4: Output window name: Output 2
A5: Monday, ‎19 September ‎2024, 12:39:33 AM
A6: Each line reports the simulation state at the END of the step on that line.
A8: Year | B8: Month | C8: Day | D8: Dec. Year | E8: C mass of trees | F8: C mass of forest debris | G8: CH4 emitted due to fire | H8: N2O emitted due to fire | I8: C mass of trees+debris
D9: tC/ha | E9: tCH4/ha | F9: tN2O/ha | G9: tC/ha | I9: tC/ha
A10: 2023 | B10: 8 | C10: 16 | D10: 2023.6247 | E10: 0 | F10: 0 | G10: 0 | H10: 0 | I10: =E10+F10 -> 0
A11: 2023 | B11: 8 | C11: 31 | D11: 2023.6658 | E11: 0.29370033 | F11: 0.0029253542 | G11: 0 | H11: 0 | I11: =E11+F11 -> 0.29662568
A12: 2023 | B12: 9 | C12: 30 | D12: 2023.7479 | E12: 0.29372613 | F12: 0.0060726812 | G12: 0 | H12: 0 | I12: =E12+F12 -> 0.29979881
A13: 2023 | B13: 10 | C13: 31 | D13: 2023.8329 | E13: 0.29415804 | F13: 0.0080735897 | G13: 0 | H13: 0 | I13: =E13+F13 -> 0.30223163
A14: 2023 | B14: 11 | C14: 30 | D14: 2023.9151 | E14: 0.29679417 | F14: 0.0098049877 | G14: 0 | H14: 0 | I14: =E14+F14 -> 0.30659916
A15: 2023 | B15: 12 | C15: 31 | D15: 2024 | E15: 0.30681532 | F15: 0.01160089 | G15: 0 | H15: 0 | I15: =E15+F15 -> 0.31841621
A16: 2024 | B16: 1 | C16: 31 | D16: 2024.0847 | E16: 0.33300654 | F16: 0.013702981 | G16: 0 | H16: 0 | I16: =E16+F16 -> 0.34670952
A17: 2024 | B17: 2 | C17: 29 | D17: 2024.1639 | E17: 0.38226702 | F17: 0.016389543 | G17: 0 | H17: 0 | I17: =E17+F17 -> 0.39865656
A18: 2024 | B18: 3 | C18: 31 | D18: 2024.2486 | E18: 0.47289355 | F18: 0.018386635 | G18: 0 | H18: 0 | I18: =E18+F18 -> 0.49128019
A19: 2024 | B19: 4 | C19: 30 | D19: 2024.3306 | E19: 0.60820715 | F19: 0.020886805 | G19: 0 | H19: 0 | I19: =E19+F19 -> 0.62909395
A20: 2024 | B20: 5 | C20: 31 | D20: 2024.4153 | E20: 0.80595199 | F20: 0.024645181 | G20: 0 | H20: 0 | I20: =E20+F20 -> 0.83059717
A21: 2024 | B21: 6 | C21: 30 | D21: 2024.4973 | E21: 1.0592062 | F21: 0.02990764 | G21: 0 | H21: 0 | I21: =E21+F21 -> 1.0891139 | K21: Year | L21: Month | M21: Trees+Debris | N21: Area | O21: Abatement (t C) | P21: Aabtement (tCO2) | Q21: Fuel Emissions tCO2e | R21: Net Abatement (tCO2e)
A22: 2024 | B22: 7 | C22: 31 | D22: 2024.582 | E22: 1.3882954 | F22: 0.037098701 | G22: 0 | H22: 0 | I22: =E22+F22 -> 1.4253941 | K22: =A18 -> 2024 | L22: 6 | M22: =I21 -> 1.0891139 | N22: =Abatement!$C$6 -> 3.87 | O22: =M22*N22 -> 4.2148707 | P22: =O22*44/12 -> 15.454526 | Q22: ='Fuel Emissions'!$D$42 -> 0.42278088 | R22: =P22-Q22 -> 15.031745
A23: 2024 | B23: 8 | C23: 31 | D23: 2024.6667 | E23: 1.6891795 | F23: 0.046254418 | G23: 0 | H23: 0 | I23: =E23+F23 -> 1.735434 | K23: 2025 | L23: 6 | M23: =I33 -> 4.6965003 | N23: =Abatement!$C$6 -> 3.87 | O23: =M23*N23 -> 18.175456 | P23: =O23*44/12 -> 66.643339 | R23: =P23-Q23 -> 66.643339
A24: 2024 | B24: 9 | C24: 30 | D24: 2024.7486 | E24: 1.8992043 | F24: 0.056227501 | G24: 0 | H24: 0 | I24: =E24+F24 -> 1.9554318 | K24: 2026 | L24: 6 | M24: =I45 -> 9.9777327 | N24: =Abatement!$C$6 -> 3.87 | O24: =M24*N24 -> 38.613825 | P24: =O24*44/12 -> 141.58403 | R24: =P24-Q24 -> 141.58403
A25: 2024 | B25: 10 | C25: 31 | D25: 2024.8333 | E25: 2.1329887 | F25: 0.067671559 | G25: 0 | H25: 0 | I25: =E25+F25 -> 2.2006602 | K25: 2027 | L25: 6 | M25: =I57 -> 16.281458 | N25: =Abatement!$C$6 -> 3.87 | O25: =M25*N25 -> 63.009244 | P25: =O25*44/12 -> 231.03389 | R25: =P25-Q25 -> 231.03389
A26: 2024 | B26: 11 | C26: 30 | D26: 2024.9153 | E26: 2.3751449 | F26: 0.080150819 | G26: 0 | H26: 0 | I26: =E26+F26 -> 2.4552957 | K26: 2028 | L26: 6 | M26: =I66 -> 21.329385 | N26: =Abatement!$C$6 -> 3.87 | O26: =M26*N26 -> 82.544722 | P26: =O26*44/12 -> 302.66398 | R26: =P26-Q26 -> 302.66398
A27: 2024 | B27: 12 | C27: 31 | D27: 2025 | E27: 2.6414237 | F27: 0.094637449 | G27: 0 | H27: 0 | I27: =E27+F27 -> 2.7360612 | K27: 2029 | L27: 6 | M27: =I81 -> 29.643678 | N27: =Abatement!$C$6 -> 3.87 | O27: =M27*N27 -> 114.72103 | P27: =O27*44/12 -> 420.64379 | R27: =P27-Q27 -> 420.64379
A28: 2025 | B28: 1 | C28: 31 | D28: 2025.0849 | E28: 2.9235531 | F28: 0.11140481 | G28: 0 | H28: 0 | I28: =E28+F28 -> 3.034958 | K28: 2030 | L28: 6 | M28: =I94 -> 36.622903 | N28: =Abatement!$C$6 -> 3.87 | O28: =M28*N28 -> 141.73063 | P28: =O28*44/12 -> 519.67899 | R28: =P28-Q28 -> 519.67899
A29: 2025 | B29: 2 | C29: 28 | D29: 2025.1616 | E29: 3.1915713 | F29: 0.12957297 | G29: 0 | H29: 0 | I29: =E29+F29 -> 3.3211442 | K29: 2031 | L29: 6 | M29: =I105 -> 42.251031 | N29: =Abatement!$C$6 -> 3.87 | O29: =M29*N29 -> 163.51149 | P29: =O29*44/12 -> 599.54213 | R29: =P29-Q29 -> 599.54213
A30: 2025 | B30: 3 | C30: 31 | D30: 2025.2466 | E30: 3.5023936 | F30: 0.14612009 | G30: 0 | H30: 0 | I30: =E30+F30 -> 3.6485137 | K30: 2032 | L30: 6 | M30: =I117 -> 48.061419 | N30: =Abatement!$C$6 -> 3.87 | O30: =M30*N30 -> 185.99769 | P30: =O30*44/12 -> 681.99153 | R30: =P30-Q30 -> 681.99153
A31: 2025 | B31: 4 | C31: 30 | D31: 2025.3288 | E31: 3.8167447 | F31: 0.16265051 | G31: 0 | H31: 0 | I31: =E31+F31 -> 3.9793952 | K31: 2033 | L31: 6 | M31: =I129 -> 53.49202 | N31: =Abatement!$C$6 -> 3.87 | O31: =M31*N31 -> 207.01412 | P31: =O31*44/12 -> 759.05176 | R31: =P31-Q31 -> 759.05176
A32: 2025 | B32: 5 | C32: 31 | D32: 2025.4137 | E32: 4.1549808 | F32: 0.18137118 | G32: 0 | H32: 0 | I32: =E32+F32 -> 4.336352
A33: 2025 | B33: 6 | C33: 30 | D33: 2025.4959 | E33: 4.4946902 | F33: 0.20181002 | G33: 0 | H33: 0 | I33: =E33+F33 -> 4.6965003
A34: 2025 | B34: 7 | C34: 31 | D34: 2025.5808 | E34: 4.8578941 | F34: 0.22440949 | G34: 0 | H34: 0 | I34: =E34+F34 -> 5.0823035
A35: 2025 | B35: 8 | C35: 31 | D35: 2025.6658 | E35: 5.2328273 | F35: 0.24876184 | G35: 0 | H35: 0 | I35: =E35+F35 -> 5.4815891
A36: 2025 | B36: 9 | C36: 30 | D36: 2025.7479 | E36: 5.6062241 | F36: 0.27497317 | G36: 0 | H36: 0 | I36: =E36+F36 -> 5.8811973
A37: 2025 | B37: 10 | C37: 31 | D37: 2025.8329 | E37: 6.0023523 | F37: 0.30422243 | G37: 0 | H37: 0 | I37: =E37+F37 -> 6.3065748
A38: 2025 | B38: 11 | C38: 30 | D38: 2025.9151 | E38: 6.3950642 | F38: 0.3349538 | G38: 0 | H38: 0 | I38: =E38+F38 -> 6.730018
A39: 2025 | B39: 12 | C39: 31 | D39: 2026 | E39: 6.8099339 | F39: 0.36931993 | G39: 0 | H39: 0 | I39: =E39+F39 -> 7.1792538
A40: 2026 | B40: 1 | C40: 31 | D40: 2026.0849 | E40: 7.2334162 | F40: 0.4077627 | G40: 0 | H40: 0 | I40: =E40+F40 -> 7.6411789
A41: 2026 | B41: 2 | C41: 28 | D41: 2026.1616 | E41: 7.6228244 | F41: 0.4483251 | G41: 0 | H41: 0 | I41: =E41+F41 -> 8.0711495
...

Sheet BW_CEA_04
A1: FullCAM: Output from Plot Simulation
A2: FullCAM Version 6.20.03.0827 (2020 PR)
A3: FullCAM Plot : Blackwood_ EP_CEA 05_Report 1.plo
A4: Output window name: Output 2
A5: Monday, ‎19 September ‎2024, 12:49:33 AM
A6: Each line reports the simulation state at the END of the step on that line.
A8: Year | B8: Month | C8: Day | D8: Dec. Year | E8: C mass of trees | F8: C mass of forest debris | G8: CH4 emitted due to fire | H8: N2O emitted due to fire | I8: C mass of trees+debris
D9: tC/ha | E9: tCH4/ha | F9: tN2O/ha | G9: tC/ha | I9: tC/ha
A10: 2023 | B10: 8 | C10: 16 | D10: 2023.6247 | E10: 0 | F10: 0 | G10: 0 | H10: 0 | I10: =E10+F10 -> 0
A11: 2023 | B11: 8 | C11: 31 | D11: 2023.6658 | E11: 0.29370025 | F11: 0.0029240847 | G11: 0 | H11: 0 | I11: =E11+F11 -> 0.29662433
A12: 2023 | B12: 9 | C12: 30 | D12: 2023.7479 | E12: 0.29371973 | F12: 0.0060657504 | G12: 0 | H12: 0 | I12: =E12+F12 -> 0.29978548
A13: 2023 | B13: 10 | C13: 31 | D13: 2023.8329 | E13: 0.2940458 | F13: 0.0080692119 | G13: 0 | H13: 0 | I13: =E13+F13 -> 0.30211501
A14: 2023 | B14: 11 | C14: 30 | D14: 2023.9151 | E14: 0.29603591 | F14: 0.0097990122 | G14: 0 | H14: 0 | I14: =E14+F14 -> 0.30583493
A15: 2023 | B15: 12 | C15: 31 | D15: 2024 | E15: 0.30360128 | F15: 0.011565235 | G15: 0 | H15: 0 | I15: =E15+F15 -> 0.31516651
A16: 2024 | B16: 1 | C16: 31 | D16: 2024.0847 | E16: 0.32337408 | F16: 0.013611709 | G16: 0 | H16: 0 | I16: =E16+F16 -> 0.33698579
A17: 2024 | B17: 2 | C17: 29 | D17: 2024.1639 | E17: 0.36056279 | F17: 0.016157986 | G17: 0 | H17: 0 | I17: =E17+F17 -> 0.37672078
A18: 2024 | B18: 3 | C18: 31 | D18: 2024.2486 | E18: 0.4289804 | F18: 0.017884649 | G18: 0 | H18: 0 | I18: =E18+F18 -> 0.44686505
A19: 2024 | B19: 4 | C19: 30 | D19: 2024.3306 | E19: 0.53113406 | F19: 0.019980583 | G19: 0 | H19: 0 | I19: =E19+F19 -> 0.55111465
A20: 2024 | B20: 5 | C20: 31 | D20: 2024.4153 | E20: 0.68041958 | F20: 0.02304639 | G20: 0 | H20: 0 | I20: =E20+F20 -> 0.70346597
A21: 2024 | B21: 6 | C21: 30 | D21: 2024.4973 | E21: 0.87161138 | F21: 0.027278754 | G21: 0 | H21: 0 | I21: =E21+F21 -> 0.89889013 | K21: Year | L21: Month | M21: Trees+Debris | N21: Area | O21: Abatement (t C) | P21: Aabtement (tCO2) | Q21: Fuel Emissions tCO2e | R21: Net Abatement (tCO2e)
A22: 2024 | B22: 7 | C22: 31 | D22: 2024.582 | E22: 1.120054 | F22: 0.032980241 | G22: 0 | H22: 0 | I22: =E22+F22 -> 1.1530342 | K22: =A18 -> 2024 | L22: 6 | M22: =I21 -> 0.89889013 | N22: =Abatement!$C$6 -> 3.87 | O22: =M22*N22 -> 3.4787048 | P22: =O22*44/12 -> 12.755251 | Q22: ='Fuel Emissions'!$D$42 -> 0.42278088 | R22: =P22-Q22 -> 12.33247
A23: 2024 | B23: 8 | C23: 31 | D23: 2024.6667 | E23: 1.3472035 | F23: 0.040171776 | G23: 0 | H23: 0 | I23: =E23+F23 -> 1.3873753 | K23: 2025 | L23: 6 | M23: =I33 -> 3.6255432 | N23: =Abatement!$C$6 -> 3.87 | O23: =M23*N23 -> 14.030852 | P23: =O23*44/12 -> 51.446458 | R23: =P23-Q23 -> 51.446458
A24: 2024 | B24: 9 | C24: 30 | D24: 2024.7486 | E24: 1.5057596 | F24: 0.048000546 | G24: 0 | H24: 0 | I24: =E24+F24 -> 1.5537602 | K24: 2026 | L24: 6 | M24: =I45 -> 7.6150402 | N24: =Abatement!$C$6 -> 3.87 | O24: =M24*N24 -> 29.470206 | P24: =O24*44/12 -> 108.05742 | R24: =P24-Q24 -> 108.05742
A25: 2024 | B25: 10 | C25: 31 | D25: 2024.8333 | E25: 1.6822528 | F25: 0.056975499 | G25: 0 | H25: 0 | I25: =E25+F25 -> 1.7392283 | K25: 2027 | L25: 6 | M25: =I57 -> 12.37571 | N25: =Abatement!$C$6 -> 3.87 | O25: =M25*N25 -> 47.893999 | P25: =O25*44/12 -> 175.61133 | R25: =P25-Q25 -> 175.61133
A26: 2024 | B26: 11 | C26: 30 | D26: 2024.9153 | E26: 1.8650663 | F26: 0.066729382 | G26: 0 | H26: 0 | I26: =E26+F26 -> 1.9317957 | K26: 2028 | L26: 6 | M26: =I66 -> 16.187246 | N26: =Abatement!$C$6 -> 3.87 | O26: =M26*N26 -> 62.644641 | P26: =O26*44/12 -> 229.69702 | R26: =P26-Q26 -> 229.69702
A27: 2024 | B27: 12 | C27: 31 | D27: 2025 | E27: 2.0660908 | F27: 0.077980591 | G27: 0 | H27: 0 | I27: =E27+F27 -> 2.1440714 | K27: 2029 | L27: 6 | M27: =I81 -> 22.46483 | N27: =Abatement!$C$6 -> 3.87 | O27: =M27*N27 -> 86.938891 | P27: =O27*44/12 -> 318.77593 | R27: =P27-Q27 -> 318.77593
A28: 2025 | B28: 1 | C28: 31 | D28: 2025.0849 | E28: 2.2790817 | F28: 0.091029194 | G28: 0 | H28: 0 | I28: =E28+F28 -> 2.3701108 | K28: 2030 | L28: 6 | M28: =I94 -> 27.733582 | N28: =Abatement!$C$6 -> 3.87 | O28: =M28*N28 -> 107.32896 | P28: =O28*44/12 -> 393.53952 | R28: =P28-Q28 -> 393.53952
A29: 2025 | B29: 2 | C29: 28 | D29: 2025.1616 | E29: 2.4814193 | F29: 0.10516135 | G29: 0 | H29: 0 | I29: =E29+F29 -> 2.5865806 | K29: 2031 | L29: 6 | M29: =I105 -> 31.981801 | N29: =Abatement!$C$6 -> 3.87 | O29: =M29*N29 -> 123.76957 | P29: =O29*44/12 -> 453.82176 | R29: =P29-Q29 -> 453.82176
A30: 2025 | B30: 3 | C30: 31 | D30: 2025.2466 | E30: 2.7160716 | F30: 0.11776288 | G30: 0 | H30: 0 | I30: =E30+F30 -> 2.8338344 | K30: 2032 | L30: 6 | M30: =I117 -> 36.367222 | N30: =Abatement!$C$6 -> 3.87 | O30: =M30*N30 -> 140.74115 | P30: =O30*44/12 -> 516.05088 | R30: =P30-Q30 -> 516.05088
